<<< PROJECT PART I
<<< -- process set (n=20) with 12 CPU-bound processes
<<< -- seed=128; lambda=0.010000; bound=4096
CPU-bound process A0: arrival time 45ms; 30 CPU bursts
CPU-bound process A1: arrival time 47ms; 12 CPU bursts
CPU-bound process A2: arrival time 92ms; 30 CPU bursts
CPU-bound process A3: arrival time 324ms; 26 CPU bursts
CPU-bound process A4: arrival time 157ms; 4 CPU bursts
CPU-bound process A5: arrival time 130ms; 5 CPU bursts
CPU-bound process A6: arrival time 29ms; 18 CPU bursts
CPU-bound process A7: arrival time 54ms; 19 CPU bursts
CPU-bound process A8: arrival time 62ms; 8 CPU bursts
CPU-bound process A9: arrival time 41ms; 32 CPU bursts
CPU-bound process B0: arrival time 45ms; 19 CPU bursts
CPU-bound process B1: arrival time 9ms; 17 CPU bursts
I/O-bound process B2: arrival time 46ms; 15 CPU bursts
I/O-bound process B3: arrival time 271ms; 22 CPU bursts
I/O-bound process B4: arrival time 2ms; 16 CPU bursts
I/O-bound process B5: arrival time 140ms; 30 CPU bursts
I/O-bound process B6: arrival time 102ms; 5 CPU bursts
I/O-bound process B7: arrival time 30ms; 26 CPU bursts
I/O-bound process B8: arrival time 225ms; 20 CPU bursts
I/O-bound process B9: arrival time 95ms; 11 CPU bursts
time 0ms: Simulator started for RR [Q empty]
time 2ms: Process B4 arrived; added to ready queue [Q B4]
time 4ms: Process B4 started using the CPU for 8ms burst [Q empty]
time 9ms: Process B1 arrived; added to ready queue [Q B1]
time 12ms: Process B4 completed a CPU burst; 15 bursts to go [Q B1]
time 12ms: Process B4 switching out of CPU; blocking on I/O until time 982ms [Q B1]
time 16ms: Process B1 started using the CPU for 28ms burst [Q empty]
time 29ms: Process A6 arrived; added to ready queue [Q A6]
time 30ms: Process B7 arrived; added to ready queue [Q A6 B7]
time 41ms: Process A9 arrived; added to ready queue [Q A6 B7 A9]
time 44ms: Process B1 completed a CPU burst; 16 bursts to go [Q A6 B7 A9]
time 44ms: Process B1 switching out of CPU; blocking on I/O until time 264ms [Q A6 B7 A9]
time 45ms: Process A0 arrived; added to ready queue [Q A6 B7 A9 A0]
time 45ms: Process B0 arrived; added to ready queue [Q A6 B7 A9 A0 B0]
time 46ms: Process B2 arrived; added to ready queue [Q A6 B7 A9 A0 B0 B2]
time 47ms: Process A1 arrived; added to ready queue [Q B7 A9 A0 B0 B2 A1]
time 48ms: Process A6 started using the CPU for 280ms burst [Q B7 A9 A0 B0 B2 A1]
time 54ms: Process A7 arrived; added to ready queue [Q B7 A9 A0 B0 B2 A1 A7]
time 62ms: Process A8 arrived; added to ready queue [Q B7 A9 A0 B0 B2 A1 A7 A8]
time 92ms: Process A2 arrived; added to ready queue [Q B7 A9 A0 B0 B2 A1 A7 A8 A2]
time 95ms: Process B9 arrived; added to ready queue [Q B7 A9 A0 B0 B2 A1 A7 A8 A2 B9]
time 102ms: Process B6 arrived; added to ready queue [Q B7 A9 A0 B0 B2 A1 A7 A8 A2 B9 B6]
time 112ms: Time slice expired; preempting process A6 with 216ms remaining [Q B7 A9 A0 B0 B2 A1 A7 A8 A2 B9 B6]
time 116ms: Process B7 started using the CPU for 71ms burst [Q A9 A0 B0 B2 A1 A7 A8 A2 B9 B6 A6]
time 130ms: Process A5 arrived; added to ready queue [Q A9 A0 B0 B2 A1 A7 A8 A2 B9 B6 A6 A5]
time 140ms: Process B5 arrived; added to ready queue [Q A9 A0 B0 B2 A1 A7 A8 A2 B9 B6 A6 A5 B5]
time 157ms: Process A4 arrived; added to ready queue [Q A9 A0 B0 B2 A1 A7 A8 A2 B9 B6 A6 A5 B5 A4]
time 180ms: Time slice expired; preempting process B7 with 7ms remaining [Q A9 A0 B0 B2 A1 A7 A8 A2 B9 B6 A6 A5 B5 A4]
time 184ms: Process A9 started using the CPU for 360ms burst [Q A0 B0 B2 A1 A7 A8 A2 B9 B6 A6 A5 B5 A4 B7]
time 225ms: Process B8 arrived; added to ready queue [Q A0 B0 B2 A1 A7 A8 A2 B9 B6 A6 A5 B5 A4 B7 B8]
time 248ms: Time slice expired; preempting process A9 with 296ms remaining [Q A0 B0 B2 A1 A7 A8 A2 B9 B6 A6 A5 B5 A4 B7 B8]
time 252ms: Process A0 started using the CPU for 196ms burst [Q B0 B2 A1 A7 A8 A2 B9 B6 A6 A5 B5 A4 B7 B8 A9]
time 264ms: Process B1 completed I/O; added to ready queue [Q B0 B2 A1 A7 A8 A2 B9 B6 A6 A5 B5 A4 B7 B8 A9 B1]
time 271ms: Process B3 arrived; added to ready queue [Q B0 B2 A1 A7 A8 A2 B9 B6 A6 A5 B5 A4 B7 B8 A9 B1 B3]
time 316ms: Time slice expired; preempting process A0 with 132ms remaining [Q B0 B2 A1 A7 A8 A2 B9 B6 A6 A5 B5 A4 B7 B8 A9 B1 B3]
time 320ms: Process B0 started using the CPU for 216ms burst [Q B2 A1 A7 A8 A2 B9 B6 A6 A5 B5 A4 B7 B8 A9 B1 B3 A0]
time 324ms: Process A3 arrived; added to ready queue [Q B2 A1 A7 A8 A2 B9 B6 A6 A5 B5 A4 B7 B8 A9 B1 B3 A0 A3]
time 384ms: Time slice expired; preempting process B0 with 152ms remaining [Q B2 A1 A7 A8 A2 B9 B6 A6 A5 B5 A4 B7 B8 A9 B1 B3 A0 A3]
time 388ms: Process B2 started using the CPU for 122ms burst [Q A1 A7 A8 A2 B9 B6 A6 A5 B5 A4 B7 B8 A9 B1 B3 A0 A3 B0]
time 452ms: Time slice expired; preempting process B2 with 58ms remaining [Q A1 A7 A8 A2 B9 B6 A6 A5 B5 A4 B7 B8 A9 B1 B3 A0 A3 B0]
time 456ms: Process A1 started using the CPU for 632ms burst [Q A7 A8 A2 B9 B6 A6 A5 B5 A4 B7 B8 A9 B1 B3 A0 A3 B0 B2]
time 520ms: Time slice expired; preempting process A1 with 568ms remaining [Q A7 A8 A2 B9 B6 A6 A5 B5 A4 B7 B8 A9 B1 B3 A0 A3 B0 B2]
time 524ms: Process A7 started using the CPU for 84ms burst [Q A8 A2 B9 B6 A6 A5 B5 A4 B7 B8 A9 B1 B3 A0 A3 B0 B2 A1]
time 588ms: Time slice expired; preempting process A7 with 20ms remaining [Q A8 A2 B9 B6 A6 A5 B5 A4 B7 B8 A9 B1 B3 A0 A3 B0 B2 A1]
time 592ms: Process A8 started using the CPU for 420ms burst [Q A2 B9 B6 A6 A5 B5 A4 B7 B8 A9 B1 B3 A0 A3 B0 B2 A1 A7]
time 656ms: Time slice expired; preempting process A8 with 356ms remaining [Q A2 B9 B6 A6 A5 B5 A4 B7 B8 A9 B1 B3 A0 A3 B0 B2 A1 A7]
time 660ms: Process A2 started using the CPU for 28ms burst [Q B9 B6 A6 A5 B5 A4 B7 B8 A9 B1 B3 A0 A3 B0 B2 A1 A7 A8]
time 688ms: Process A2 completed a CPU burst; 29 bursts to go [Q B9 B6 A6 A5 B5 A4 B7 B8 A9 B1 B3 A0 A3 B0 B2 A1 A7 A8]
time 688ms: Process A2 switching out of CPU; blocking on I/O until time 703ms [Q B9 B6 A6 A5 B5 A4 B7 B8 A9 B1 B3 A0 A3 B0 B2 A1 A7 A8]
time 692ms: Process B9 started using the CPU for 22ms burst [Q B6 A6 A5 B5 A4 B7 B8 A9 B1 B3 A0 A3 B0 B2 A1 A7 A8]
time 703ms: Process A2 completed I/O; added to ready queue [Q B6 A6 A5 B5 A4 B7 B8 A9 B1 B3 A0 A3 B0 B2 A1 A7 A8 A2]
time 714ms: Process B9 completed a CPU burst; 10 bursts to go [Q B6 A6 A5 B5 A4 B7 B8 A9 B1 B3 A0 A3 B0 B2 A1 A7 A8 A2]
time 714ms: Process B9 switching out of CPU; blocking on I/O until time 1324ms [Q B6 A6 A5 B5 A4 B7 B8 A9 B1 B3 A0 A3 B0 B2 A1 A7 A8 A2]
time 718ms: Process B6 started using the CPU for 113ms burst [Q A6 A5 B5 A4 B7 B8 A9 B1 B3 A0 A3 B0 B2 A1 A7 A8 A2]
time 782ms: Time slice expired; preempting process B6 with 49ms remaining [Q A6 A5 B5 A4 B7 B8 A9 B1 B3 A0 A3 B0 B2 A1 A7 A8 A2]
time 786ms: Process A6 started using the CPU for remaining 216ms of 280ms burst [Q A5 B5 A4 B7 B8 A9 B1 B3 A0 A3 B0 B2 A1 A7 A8 A2 B6]
time 850ms: Time slice expired; preempting process A6 with 152ms remaining [Q A5 B5 A4 B7 B8 A9 B1 B3 A0 A3 B0 B2 A1 A7 A8 A2 B6]
time 854ms: Process A5 started using the CPU for 196ms burst [Q B5 A4 B7 B8 A9 B1 B3 A0 A3 B0 B2 A1 A7 A8 A2 B6 A6]
time 918ms: Time slice expired; preempting process A5 with 132ms remaining [Q B5 A4 B7 B8 A9 B1 B3 A0 A3 B0 B2 A1 A7 A8 A2 B6 A6]
time 922ms: Process B5 started using the CPU for 20ms burst [Q A4 B7 B8 A9 B1 B3 A0 A3 B0 B2 A1 A7 A8 A2 B6 A6 A5]
time 942ms: Process B5 completed a CPU burst; 29 bursts to go [Q A4 B7 B8 A9 B1 B3 A0 A3 B0 B2 A1 A7 A8 A2 B6 A6 A5]
time 942ms: Process B5 switching out of CPU; blocking on I/O until time 1192ms [Q A4 B7 B8 A9 B1 B3 A0 A3 B0 B2 A1 A7 A8 A2 B6 A6 A5]
time 946ms: Process A4 started using the CPU for 300ms burst [Q B7 B8 A9 B1 B3 A0 A3 B0 B2 A1 A7 A8 A2 B6 A6 A5]
time 982ms: Process B4 completed I/O; added to ready queue [Q B7 B8 A9 B1 B3 A0 A3 B0 B2 A1 A7 A8 A2 B6 A6 A5 B4]
time 1010ms: Time slice expired; preempting process A4 with 236ms remaining [Q B7 B8 A9 B1 B3 A0 A3 B0 B2 A1 A7 A8 A2 B6 A6 A5 B4]
time 1014ms: Process B7 started using the CPU for remaining 7ms of 71ms burst [Q B8 A9 B1 B3 A0 A3 B0 B2 A1 A7 A8 A2 B6 A6 A5 B4 A4]
time 1021ms: Process B7 completed a CPU burst; 25 bursts to go [Q B8 A9 B1 B3 A0 A3 B0 B2 A1 A7 A8 A2 B6 A6 A5 B4 A4]
time 1021ms: Process B7 switching out of CPU; blocking on I/O until time 4071ms [Q B8 A9 B1 B3 A0 A3 B0 B2 A1 A7 A8 A2 B6 A6 A5 B4 A4]
time 1025ms: Process B8 started using the CPU for 308ms burst [Q A9 B1 B3 A0 A3 B0 B2 A1 A7 A8 A2 B6 A6 A5 B4 A4]
time 1089ms: Time slice expired; preempting process B8 with 244ms remaining [Q A9 B1 B3 A0 A3 B0 B2 A1 A7 A8 A2 B6 A6 A5 B4 A4]
time 1093ms: Process A9 started using the CPU for remaining 296ms of 360ms burst [Q B1 B3 A0 A3 B0 B2 A1 A7 A8 A2 B6 A6 A5 B4 A4 B8]
time 1157ms: Time slice expired; preempting process A9 with 232ms remaining [Q B1 B3 A0 A3 B0 B2 A1 A7 A8 A2 B6 A6 A5 B4 A4 B8]
time 1161ms: Process B1 started using the CPU for 3004ms burst [Q B3 A0 A3 B0 B2 A1 A7 A8 A2 B6 A6 A5 B4 A4 B8 A9]
time 1192ms: Process B5 completed I/O; added to ready queue [Q B3 A0 A3 B0 B2 A1 A7 A8 A2 B6 A6 A5 B4 A4 B8 A9 B5]
time 1225ms: Time slice expired; preempting process B1 with 2940ms remaining [Q B3 A0 A3 B0 B2 A1 A7 A8 A2 B6 A6 A5 B4 A4 B8 A9 B5]
time 1229ms: Process B3 started using the CPU for 51ms burst [Q A0 A3 B0 B2 A1 A7 A8 A2 B6 A6 A5 B4 A4 B8 A9 B5 B1]
time 1280ms: Process B3 completed a CPU burst; 21 bursts to go [Q A0 A3 B0 B2 A1 A7 A8 A2 B6 A6 A5 B4 A4 B8 A9 B5 B1]
time 1280ms: Process B3 switching out of CPU; blocking on I/O until time 3618ms [Q A0 A3 B0 B2 A1 A7 A8 A2 B6 A6 A5 B4 A4 B8 A9 B5 B1]
time 1284ms: Process A0 started using the CPU for remaining 132ms of 196ms burst [Q A3 B0 B2 A1 A7 A8 A2 B6 A6 A5 B4 A4 B8 A9 B5 B1]
time 1324ms: Process B9 completed I/O; added to ready queue [Q A3 B0 B2 A1 A7 A8 A2 B6 A6 A5 B4 A4 B8 A9 B5 B1 B9]
time 1348ms: Time slice expired; preempting process A0 with 68ms remaining [Q A3 B0 B2 A1 A7 A8 A2 B6 A6 A5 B4 A4 B8 A9 B5 B1 B9]
time 1352ms: Process A3 started using the CPU for 96ms burst [Q B0 B2 A1 A7 A8 A2 B6 A6 A5 B4 A4 B8 A9 B5 B1 B9 A0]
time 1416ms: Time slice expired; preempting process A3 with 32ms remaining [Q B0 B2 A1 A7 A8 A2 B6 A6 A5 B4 A4 B8 A9 B5 B1 B9 A0]
time 1420ms: Process B0 started using the CPU for remaining 152ms of 216ms burst [Q B2 A1 A7 A8 A2 B6 A6 A5 B4 A4 B8 A9 B5 B1 B9 A0 A3]
time 1484ms: Time slice expired; preempting process B0 with 88ms remaining [Q B2 A1 A7 A8 A2 B6 A6 A5 B4 A4 B8 A9 B5 B1 B9 A0 A3]
time 1488ms: Process B2 started using the CPU for remaining 58ms of 122ms burst [Q A1 A7 A8 A2 B6 A6 A5 B4 A4 B8 A9 B5 B1 B9 A0 A3 B0]
time 1546ms: Process B2 completed a CPU burst; 14 bursts to go [Q A1 A7 A8 A2 B6 A6 A5 B4 A4 B8 A9 B5 B1 B9 A0 A3 B0]
time 1546ms: Process B2 switching out of CPU; blocking on I/O until time 2068ms [Q A1 A7 A8 A2 B6 A6 A5 B4 A4 B8 A9 B5 B1 B9 A0 A3 B0]
time 1550ms: Process A1 started using the CPU for remaining 568ms of 632ms burst [Q A7 A8 A2 B6 A6 A5 B4 A4 B8 A9 B5 B1 B9 A0 A3 B0]
time 1614ms: Time slice expired; preempting process A1 with 504ms remaining [Q A7 A8 A2 B6 A6 A5 B4 A4 B8 A9 B5 B1 B9 A0 A3 B0]
time 1618ms: Process A7 started using the CPU for remaining 20ms of 84ms burst [Q A8 A2 B6 A6 A5 B4 A4 B8 A9 B5 B1 B9 A0 A3 B0 A1]
time 1638ms: Process A7 completed a CPU burst; 18 bursts to go [Q A8 A2 B6 A6 A5 B4 A4 B8 A9 B5 B1 B9 A0 A3 B0 A1]
time 1638ms: Process A7 switching out of CPU; blocking on I/O until time 1689ms [Q A8 A2 B6 A6 A5 B4 A4 B8 A9 B5 B1 B9 A0 A3 B0 A1]
time 1642ms: Process A8 started using the CPU for remaining 356ms of 420ms burst [Q A2 B6 A6 A5 B4 A4 B8 A9 B5 B1 B9 A0 A3 B0 A1]
time 1689ms: Process A7 completed I/O; added to ready queue [Q A2 B6 A6 A5 B4 A4 B8 A9 B5 B1 B9 A0 A3 B0 A1 A7]
time 1706ms: Time slice expired; preempting process A8 with 292ms remaining [Q A2 B6 A6 A5 B4 A4 B8 A9 B5 B1 B9 A0 A3 B0 A1 A7]
time 1710ms: Process A2 started using the CPU for 444ms burst [Q B6 A6 A5 B4 A4 B8 A9 B5 B1 B9 A0 A3 B0 A1 A7 A8]
time 1774ms: Time slice expired; preempting process A2 with 380ms remaining [Q B6 A6 A5 B4 A4 B8 A9 B5 B1 B9 A0 A3 B0 A1 A7 A8]
time 1778ms: Process B6 started using the CPU for remaining 49ms of 113ms burst [Q A6 A5 B4 A4 B8 A9 B5 B1 B9 A0 A3 B0 A1 A7 A8 A2]
time 1827ms: Process B6 completed a CPU burst; 4 bursts to go [Q A6 A5 B4 A4 B8 A9 B5 B1 B9 A0 A3 B0 A1 A7 A8 A2]
time 1827ms: Process B6 switching out of CPU; blocking on I/O until time 5053ms [Q A6 A5 B4 A4 B8 A9 B5 B1 B9 A0 A3 B0 A1 A7 A8 A2]
time 1831ms: Process A6 started using the CPU for remaining 152ms of 280ms burst [Q A5 B4 A4 B8 A9 B5 B1 B9 A0 A3 B0 A1 A7 A8 A2]
time 1895ms: Time slice expired; preempting process A6 with 88ms remaining [Q A5 B4 A4 B8 A9 B5 B1 B9 A0 A3 B0 A1 A7 A8 A2]
time 1899ms: Process A5 started using the CPU for remaining 132ms of 196ms burst [Q B4 A4 B8 A9 B5 B1 B9 A0 A3 B0 A1 A7 A8 A2 A6]
time 1963ms: Time slice expired; preempting process A5 with 68ms remaining [Q B4 A4 B8 A9 B5 B1 B9 A0 A3 B0 A1 A7 A8 A2 A6]
time 1967ms: Process B4 started using the CPU for 3ms burst [Q A4 B8 A9 B5 B1 B9 A0 A3 B0 A1 A7 A8 A2 A6 A5]
time 1970ms: Process B4 completed a CPU burst; 14 bursts to go [Q A4 B8 A9 B5 B1 B9 A0 A3 B0 A1 A7 A8 A2 A6 A5]
time 1970ms: Process B4 switching out of CPU; blocking on I/O until time 3068ms [Q A4 B8 A9 B5 B1 B9 A0 A3 B0 A1 A7 A8 A2 A6 A5]
time 1974ms: Process A4 started using the CPU for remaining 236ms of 300ms burst [Q B8 A9 B5 B1 B9 A0 A3 B0 A1 A7 A8 A2 A6 A5]
time 2038ms: Time slice expired; preempting process A4 with 172ms remaining [Q B8 A9 B5 B1 B9 A0 A3 B0 A1 A7 A8 A2 A6 A5]
time 2042ms: Process B8 started using the CPU for remaining 244ms of 308ms burst [Q A9 B5 B1 B9 A0 A3 B0 A1 A7 A8 A2 A6 A5 A4]
time 2068ms: Process B2 completed I/O; added to ready queue [Q A9 B5 B1 B9 A0 A3 B0 A1 A7 A8 A2 A6 A5 A4 B2]
time 2106ms: Time slice expired; preempting process B8 with 180ms remaining [Q A9 B5 B1 B9 A0 A3 B0 A1 A7 A8 A2 A6 A5 A4 B2]
time 2110ms: Process A9 started using the CPU for remaining 232ms of 360ms burst [Q B5 B1 B9 A0 A3 B0 A1 A7 A8 A2 A6 A5 A4 B2 B8]
time 2174ms: Time slice expired; preempting process A9 with 168ms remaining [Q B5 B1 B9 A0 A3 B0 A1 A7 A8 A2 A6 A5 A4 B2 B8]
time 2178ms: Process B5 started using the CPU for 85ms burst [Q B1 B9 A0 A3 B0 A1 A7 A8 A2 A6 A5 A4 B2 B8 A9]
time 2242ms: Time slice expired; preempting process B5 with 21ms remaining [Q B1 B9 A0 A3 B0 A1 A7 A8 A2 A6 A5 A4 B2 B8 A9]
time 2246ms: Process B1 started using the CPU for remaining 2940ms of 3004ms burst [Q B9 A0 A3 B0 A1 A7 A8 A2 A6 A5 A4 B2 B8 A9 B5]
time 2310ms: Time slice expired; preempting process B1 with 2876ms remaining [Q B9 A0 A3 B0 A1 A7 A8 A2 A6 A5 A4 B2 B8 A9 B5]
time 2314ms: Process B9 started using the CPU for 142ms burst [Q A0 A3 B0 A1 A7 A8 A2 A6 A5 A4 B2 B8 A9 B5 B1]
time 2378ms: Time slice expired; preempting process B9 with 78ms remaining [Q A0 A3 B0 A1 A7 A8 A2 A6 A5 A4 B2 B8 A9 B5 B1]
time 2382ms: Process A0 started using the CPU for remaining 68ms of 196ms burst [Q A3 B0 A1 A7 A8 A2 A6 A5 A4 B2 B8 A9 B5 B1 B9]
time 2446ms: Time slice expired; preempting process A0 with 4ms remaining [Q A3 B0 A1 A7 A8 A2 A6 A5 A4 B2 B8 A9 B5 B1 B9]
time 2450ms: Process A3 started using the CPU for remaining 32ms of 96ms burst [Q B0 A1 A7 A8 A2 A6 A5 A4 B2 B8 A9 B5 B1 B9 A0]
time 2482ms: Process A3 completed a CPU burst; 25 bursts to go [Q B0 A1 A7 A8 A2 A6 A5 A4 B2 B8 A9 B5 B1 B9 A0]
time 2482ms: Process A3 switching out of CPU; blocking on I/O until time 2854ms [Q B0 A1 A7 A8 A2 A6 A5 A4 B2 B8 A9 B5 B1 B9 A0]
time 2486ms: Process B0 started using the CPU for remaining 88ms of 216ms burst [Q A1 A7 A8 A2 A6 A5 A4 B2 B8 A9 B5 B1 B9 A0]
time 2550ms: Time slice expired; preempting process B0 with 24ms remaining [Q A1 A7 A8 A2 A6 A5 A4 B2 B8 A9 B5 B1 B9 A0]
time 2554ms: Process A1 started using the CPU for remaining 504ms of 632ms burst [Q A7 A8 A2 A6 A5 A4 B2 B8 A9 B5 B1 B9 A0 B0]
time 2618ms: Time slice expired; preempting process A1 with 440ms remaining [Q A7 A8 A2 A6 A5 A4 B2 B8 A9 B5 B1 B9 A0 B0]
time 2622ms: Process A7 started using the CPU for 768ms burst [Q A8 A2 A6 A5 A4 B2 B8 A9 B5 B1 B9 A0 B0 A1]
time 2686ms: Time slice expired; preempting process A7 with 704ms remaining [Q A8 A2 A6 A5 A4 B2 B8 A9 B5 B1 B9 A0 B0 A1]
time 2690ms: Process A8 started using the CPU for remaining 292ms of 420ms burst [Q A2 A6 A5 A4 B2 B8 A9 B5 B1 B9 A0 B0 A1 A7]
time 2754ms: Time slice expired; preempting process A8 with 228ms remaining [Q A2 A6 A5 A4 B2 B8 A9 B5 B1 B9 A0 B0 A1 A7]
time 2758ms: Process A2 started using the CPU for remaining 380ms of 444ms burst [Q A6 A5 A4 B2 B8 A9 B5 B1 B9 A0 B0 A1 A7 A8]
time 2822ms: Time slice expired; preempting process A2 with 316ms remaining [Q A6 A5 A4 B2 B8 A9 B5 B1 B9 A0 B0 A1 A7 A8]
time 2826ms: Process A6 started using the CPU for remaining 88ms of 280ms burst [Q A5 A4 B2 B8 A9 B5 B1 B9 A0 B0 A1 A7 A8 A2]
time 2854ms: Process A3 completed I/O; added to ready queue [Q A5 A4 B2 B8 A9 B5 B1 B9 A0 B0 A1 A7 A8 A2 A3]
time 2890ms: Time slice expired; preempting process A6 with 24ms remaining [Q A5 A4 B2 B8 A9 B5 B1 B9 A0 B0 A1 A7 A8 A2 A3]
time 2894ms: Process A5 started using the CPU for remaining 68ms of 196ms burst [Q A4 B2 B8 A9 B5 B1 B9 A0 B0 A1 A7 A8 A2 A3 A6]
time 2958ms: Time slice expired; preempting process A5 with 4ms remaining [Q A4 B2 B8 A9 B5 B1 B9 A0 B0 A1 A7 A8 A2 A3 A6]
time 2962ms: Process A4 started using the CPU for remaining 172ms of 300ms burst [Q B2 B8 A9 B5 B1 B9 A0 B0 A1 A7 A8 A2 A3 A6 A5]
time 3026ms: Time slice expired; preempting process A4 with 108ms remaining [Q B2 B8 A9 B5 B1 B9 A0 B0 A1 A7 A8 A2 A3 A6 A5]
time 3030ms: Process B2 started using the CPU for 183ms burst [Q B8 A9 B5 B1 B9 A0 B0 A1 A7 A8 A2 A3 A6 A5 A4]
time 3068ms: Process B4 completed I/O; added to ready queue [Q B8 A9 B5 B1 B9 A0 B0 A1 A7 A8 A2 A3 A6 A5 A4 B4]
time 3094ms: Time slice expired; preempting process B2 with 119ms remaining [Q B8 A9 B5 B1 B9 A0 B0 A1 A7 A8 A2 A3 A6 A5 A4 B4]
time 3098ms: Process B8 started using the CPU for remaining 180ms of 308ms burst [Q A9 B5 B1 B9 A0 B0 A1 A7 A8 A2 A3 A6 A5 A4 B4 B2]
time 3162ms: Time slice expired; preempting process B8 with 116ms remaining [Q A9 B5 B1 B9 A0 B0 A1 A7 A8 A2 A3 A6 A5 A4 B4 B2]
time 3166ms: Process A9 started using the CPU for remaining 168ms of 360ms burst [Q B5 B1 B9 A0 B0 A1 A7 A8 A2 A3 A6 A5 A4 B4 B2 B8]
time 3230ms: Time slice expired; preempting process A9 with 104ms remaining [Q B5 B1 B9 A0 B0 A1 A7 A8 A2 A3 A6 A5 A4 B4 B2 B8]
time 3234ms: Process B5 started using the CPU for remaining 21ms of 85ms burst [Q B1 B9 A0 B0 A1 A7 A8 A2 A3 A6 A5 A4 B4 B2 B8 A9]
time 3255ms: Process B5 completed a CPU burst; 28 bursts to go [Q B1 B9 A0 B0 A1 A7 A8 A2 A3 A6 A5 A4 B4 B2 B8 A9]
time 3255ms: Process B5 switching out of CPU; blocking on I/O until time 3497ms [Q B1 B9 A0 B0 A1 A7 A8 A2 A3 A6 A5 A4 B4 B2 B8 A9]
time 3259ms: Process B1 started using the CPU for remaining 2876ms of 3004ms burst [Q B9 A0 B0 A1 A7 A8 A2 A3 A6 A5 A4 B4 B2 B8 A9]
time 3323ms: Time slice expired; preempting process B1 with 2812ms remaining [Q B9 A0 B0 A1 A7 A8 A2 A3 A6 A5 A4 B4 B2 B8 A9]
time 3327ms: Process B9 started using the CPU for remaining 78ms of 142ms burst [Q A0 B0 A1 A7 A8 A2 A3 A6 A5 A4 B4 B2 B8 A9 B1]
time 3391ms: Time slice expired; preempting process B9 with 14ms remaining [Q A0 B0 A1 A7 A8 A2 A3 A6 A5 A4 B4 B2 B8 A9 B1]
time 3395ms: Process A0 started using the CPU for remaining 4ms of 196ms burst [Q B0 A1 A7 A8 A2 A3 A6 A5 A4 B4 B2 B8 A9 B1 B9]
time 3399ms: Process A0 completed a CPU burst; 29 bursts to go [Q B0 A1 A7 A8 A2 A3 A6 A5 A4 B4 B2 B8 A9 B1 B9]
time 3399ms: Process A0 switching out of CPU; blocking on I/O until time 3480ms [Q B0 A1 A7 A8 A2 A3 A6 A5 A4 B4 B2 B8 A9 B1 B9]
time 3403ms: Process B0 started using the CPU for remaining 24ms of 216ms burst [Q A1 A7 A8 A2 A3 A6 A5 A4 B4 B2 B8 A9 B1 B9]
time 3427ms: Process B0 completed a CPU burst; 18 bursts to go [Q A1 A7 A8 A2 A3 A6 A5 A4 B4 B2 B8 A9 B1 B9]
time 3427ms: Process B0 switching out of CPU; blocking on I/O until time 3578ms [Q A1 A7 A8 A2 A3 A6 A5 A4 B4 B2 B8 A9 B1 B9]
time 3431ms: Process A1 started using the CPU for remaining 440ms of 632ms burst [Q A7 A8 A2 A3 A6 A5 A4 B4 B2 B8 A9 B1 B9]
time 3480ms: Process A0 completed I/O; added to ready queue [Q A7 A8 A2 A3 A6 A5 A4 B4 B2 B8 A9 B1 B9 A0]
time 3495ms: Time slice expired; preempting process A1 with 376ms remaining [Q A7 A8 A2 A3 A6 A5 A4 B4 B2 B8 A9 B1 B9 A0]
time 3497ms: Process B5 completed I/O; added to ready queue [Q A7 A8 A2 A3 A6 A5 A4 B4 B2 B8 A9 B1 B9 A0 A1 B5]
time 3499ms: Process A7 started using the CPU for remaining 704ms of 768ms burst [Q A8 A2 A3 A6 A5 A4 B4 B2 B8 A9 B1 B9 A0 A1 B5]
time 3563ms: Time slice expired; preempting process A7 with 640ms remaining [Q A8 A2 A3 A6 A5 A4 B4 B2 B8 A9 B1 B9 A0 A1 B5]
time 3567ms: Process A8 started using the CPU for remaining 228ms of 420ms burst [Q A2 A3 A6 A5 A4 B4 B2 B8 A9 B1 B9 A0 A1 B5 A7]
time 3578ms: Process B0 completed I/O; added to ready queue [Q A2 A3 A6 A5 A4 B4 B2 B8 A9 B1 B9 A0 A1 B5 A7 B0]
time 3618ms: Process B3 completed I/O; added to ready queue [Q A2 A3 A6 A5 A4 B4 B2 B8 A9 B1 B9 A0 A1 B5 A7 B0 B3]
time 3631ms: Time slice expired; preempting process A8 with 164ms remaining [Q A2 A3 A6 A5 A4 B4 B2 B8 A9 B1 B9 A0 A1 B5 A7 B0 B3]
time 3635ms: Process A2 started using the CPU for remaining 316ms of 444ms burst [Q A3 A6 A5 A4 B4 B2 B8 A9 B1 B9 A0 A1 B5 A7 B0 B3 A8]
time 3699ms: Time slice expired; preempting process A2 with 252ms remaining [Q A3 A6 A5 A4 B4 B2 B8 A9 B1 B9 A0 A1 B5 A7 B0 B3 A8]
time 3703ms: Process A3 started using the CPU for 308ms burst [Q A6 A5 A4 B4 B2 B8 A9 B1 B9 A0 A1 B5 A7 B0 B3 A8 A2]
time 3767ms: Time slice expired; preempting process A3 with 244ms remaining [Q A6 A5 A4 B4 B2 B8 A9 B1 B9 A0 A1 B5 A7 B0 B3 A8 A2]
time 3771ms: Process A6 started using the CPU for remaining 24ms of 280ms burst [Q A5 A4 B4 B2 B8 A9 B1 B9 A0 A1 B5 A7 B0 B3 A8 A2 A3]
time 3795ms: Process A6 completed a CPU burst; 17 bursts to go [Q A5 A4 B4 B2 B8 A9 B1 B9 A0 A1 B5 A7 B0 B3 A8 A2 A3]
time 3795ms: Process A6 switching out of CPU; blocking on I/O until time 3869ms [Q A5 A4 B4 B2 B8 A9 B1 B9 A0 A1 B5 A7 B0 B3 A8 A2 A3]
time 3799ms: Process A5 started using the CPU for remaining 4ms of 196ms burst [Q A4 B4 B2 B8 A9 B1 B9 A0 A1 B5 A7 B0 B3 A8 A2 A3]
time 3803ms: Process A5 completed a CPU burst; 4 bursts to go [Q A4 B4 B2 B8 A9 B1 B9 A0 A1 B5 A7 B0 B3 A8 A2 A3]
time 3803ms: Process A5 switching out of CPU; blocking on I/O until time 3822ms [Q A4 B4 B2 B8 A9 B1 B9 A0 A1 B5 A7 B0 B3 A8 A2 A3]
time 3807ms: Process A4 started using the CPU for remaining 108ms of 300ms burst [Q B4 B2 B8 A9 B1 B9 A0 A1 B5 A7 B0 B3 A8 A2 A3]
time 3822ms: Process A5 completed I/O; added to ready queue [Q B4 B2 B8 A9 B1 B9 A0 A1 B5 A7 B0 B3 A8 A2 A3 A5]
time 3869ms: Process A6 completed I/O; added to ready queue [Q B4 B2 B8 A9 B1 B9 A0 A1 B5 A7 B0 B3 A8 A2 A3 A5 A6]
time 3871ms: Time slice expired; preempting process A4 with 44ms remaining [Q B4 B2 B8 A9 B1 B9 A0 A1 B5 A7 B0 B3 A8 A2 A3 A5 A6]
time 3875ms: Process B4 started using the CPU for 285ms burst [Q B2 B8 A9 B1 B9 A0 A1 B5 A7 B0 B3 A8 A2 A3 A5 A6 A4]
time 3939ms: Time slice expired; preempting process B4 with 221ms remaining [Q B2 B8 A9 B1 B9 A0 A1 B5 A7 B0 B3 A8 A2 A3 A5 A6 A4]
time 3943ms: Process B2 started using the CPU for remaining 119ms of 183ms burst [Q B8 A9 B1 B9 A0 A1 B5 A7 B0 B3 A8 A2 A3 A5 A6 A4 B4]
time 4007ms: Time slice expired; preempting process B2 with 55ms remaining [Q B8 A9 B1 B9 A0 A1 B5 A7 B0 B3 A8 A2 A3 A5 A6 A4 B4]
time 4011ms: Process B8 started using the CPU for remaining 116ms of 308ms burst [Q A9 B1 B9 A0 A1 B5 A7 B0 B3 A8 A2 A3 A5 A6 A4 B4 B2]
time 4071ms: Process B7 completed I/O; added to ready queue [Q A9 B1 B9 A0 A1 B5 A7 B0 B3 A8 A2 A3 A5 A6 A4 B4 B2 B7]
time 4075ms: Time slice expired; preempting process B8 with 52ms remaining [Q A9 B1 B9 A0 A1 B5 A7 B0 B3 A8 A2 A3 A5 A6 A4 B4 B2 B7]
time 4079ms: Process A9 started using the CPU for remaining 104ms of 360ms burst [Q B1 B9 A0 A1 B5 A7 B0 B3 A8 A2 A3 A5 A6 A4 B4 B2 B7 B8]
time 4143ms: Time slice expired; preempting process A9 with 40ms remaining [Q B1 B9 A0 A1 B5 A7 B0 B3 A8 A2 A3 A5 A6 A4 B4 B2 B7 B8]
time 4147ms: Process B1 started using the CPU for remaining 2812ms of 3004ms burst [Q B9 A0 A1 B5 A7 B0 B3 A8 A2 A3 A5 A6 A4 B4 B2 B7 B8 A9]
time 4211ms: Time slice expired; preempting process B1 with 2748ms remaining [Q B9 A0 A1 B5 A7 B0 B3 A8 A2 A3 A5 A6 A4 B4 B2 B7 B8 A9]
time 4215ms: Process B9 started using the CPU for remaining 14ms of 142ms burst [Q A0 A1 B5 A7 B0 B3 A8 A2 A3 A5 A6 A4 B4 B2 B7 B8 A9 B1]
time 4229ms: Process B9 completed a CPU burst; 9 bursts to go [Q A0 A1 B5 A7 B0 B3 A8 A2 A3 A5 A6 A4 B4 B2 B7 B8 A9 B1]
time 4229ms: Process B9 switching out of CPU; blocking on I/O until time 4303ms [Q A0 A1 B5 A7 B0 B3 A8 A2 A3 A5 A6 A4 B4 B2 B7 B8 A9 B1]
time 4233ms: Process A0 started using the CPU for 1096ms burst [Q A1 B5 A7 B0 B3 A8 A2 A3 A5 A6 A4 B4 B2 B7 B8 A9 B1]
time 4297ms: Time slice expired; preempting process A0 with 1032ms remaining [Q A1 B5 A7 B0 B3 A8 A2 A3 A5 A6 A4 B4 B2 B7 B8 A9 B1]
time 4301ms: Process A1 started using the CPU for remaining 376ms of 632ms burst [Q B5 A7 B0 B3 A8 A2 A3 A5 A6 A4 B4 B2 B7 B8 A9 B1 A0]
time 4303ms: Process B9 completed I/O; added to ready queue [Q B5 A7 B0 B3 A8 A2 A3 A5 A6 A4 B4 B2 B7 B8 A9 B1 A0 B9]
time 4365ms: Time slice expired; preempting process A1 with 312ms remaining [Q B5 A7 B0 B3 A8 A2 A3 A5 A6 A4 B4 B2 B7 B8 A9 B1 A0 B9]
time 4369ms: Process B5 started using the CPU for 20ms burst [Q A7 B0 B3 A8 A2 A3 A5 A6 A4 B4 B2 B7 B8 A9 B1 A0 B9 A1]
time 4389ms: Process B5 completed a CPU burst; 27 bursts to go [Q A7 B0 B3 A8 A2 A3 A5 A6 A4 B4 B2 B7 B8 A9 B1 A0 B9 A1]
time 4389ms: Process B5 switching out of CPU; blocking on I/O until time 4815ms [Q A7 B0 B3 A8 A2 A3 A5 A6 A4 B4 B2 B7 B8 A9 B1 A0 B9 A1]
time 4393ms: Process A7 started using the CPU for remaining 640ms of 768ms burst [Q B0 B3 A8 A2 A3 A5 A6 A4 B4 B2 B7 B8 A9 B1 A0 B9 A1]
time 4457ms: Time slice expired; preempting process A7 with 576ms remaining [Q B0 B3 A8 A2 A3 A5 A6 A4 B4 B2 B7 B8 A9 B1 A0 B9 A1]
time 4461ms: Process B0 started using the CPU for 1264ms burst [Q B3 A8 A2 A3 A5 A6 A4 B4 B2 B7 B8 A9 B1 A0 B9 A1 A7]
time 4525ms: Time slice expired; preempting process B0 with 1200ms remaining [Q B3 A8 A2 A3 A5 A6 A4 B4 B2 B7 B8 A9 B1 A0 B9 A1 A7]
time 4529ms: Process B3 started using the CPU for 129ms burst [Q A8 A2 A3 A5 A6 A4 B4 B2 B7 B8 A9 B1 A0 B9 A1 A7 B0]
time 4593ms: Time slice expired; preempting process B3 with 65ms remaining [Q A8 A2 A3 A5 A6 A4 B4 B2 B7 B8 A9 B1 A0 B9 A1 A7 B0]
time 4597ms: Process A8 started using the CPU for remaining 164ms of 420ms burst [Q A2 A3 A5 A6 A4 B4 B2 B7 B8 A9 B1 A0 B9 A1 A7 B0 B3]
time 4661ms: Time slice expired; preempting process A8 with 100ms remaining [Q A2 A3 A5 A6 A4 B4 B2 B7 B8 A9 B1 A0 B9 A1 A7 B0 B3]
time 4665ms: Process A2 started using the CPU for remaining 252ms of 444ms burst [Q A3 A5 A6 A4 B4 B2 B7 B8 A9 B1 A0 B9 A1 A7 B0 B3 A8]
time 4729ms: Time slice expired; preempting process A2 with 188ms remaining [Q A3 A5 A6 A4 B4 B2 B7 B8 A9 B1 A0 B9 A1 A7 B0 B3 A8]
time 4733ms: Process A3 started using the CPU for remaining 244ms of 308ms burst [Q A5 A6 A4 B4 B2 B7 B8 A9 B1 A0 B9 A1 A7 B0 B3 A8 A2]
time 4797ms: Time slice expired; preempting process A3 with 180ms remaining [Q A5 A6 A4 B4 B2 B7 B8 A9 B1 A0 B9 A1 A7 B0 B3 A8 A2]
time 4801ms: Process A5 started using the CPU for 140ms burst [Q A6 A4 B4 B2 B7 B8 A9 B1 A0 B9 A1 A7 B0 B3 A8 A2 A3]
time 4815ms: Process B5 completed I/O; added to ready queue [Q A6 A4 B4 B2 B7 B8 A9 B1 A0 B9 A1 A7 B0 B3 A8 A2 A3 B5]
time 4865ms: Time slice expired; preempting process A5 with 76ms remaining [Q A6 A4 B4 B2 B7 B8 A9 B1 A0 B9 A1 A7 B0 B3 A8 A2 A3 B5]
time 4869ms: Process A6 started using the CPU for 100ms burst [Q A4 B4 B2 B7 B8 A9 B1 A0 B9 A1 A7 B0 B3 A8 A2 A3 B5 A5]
time 4933ms: Time slice expired; preempting process A6 with 36ms remaining [Q A4 B4 B2 B7 B8 A9 B1 A0 B9 A1 A7 B0 B3 A8 A2 A3 B5 A5]
time 4937ms: Process A4 started using the CPU for remaining 44ms of 300ms burst [Q B4 B2 B7 B8 A9 B1 A0 B9 A1 A7 B0 B3 A8 A2 A3 B5 A5 A6]
time 4981ms: Process A4 completed a CPU burst; 3 bursts to go [Q B4 B2 B7 B8 A9 B1 A0 B9 A1 A7 B0 B3 A8 A2 A3 B5 A5 A6]
time 4981ms: Process A4 switching out of CPU; blocking on I/O until time 5072ms [Q B4 B2 B7 B8 A9 B1 A0 B9 A1 A7 B0 B3 A8 A2 A3 B5 A5 A6]
time 4985ms: Process B4 started using the CPU for remaining 221ms of 285ms burst [Q B2 B7 B8 A9 B1 A0 B9 A1 A7 B0 B3 A8 A2 A3 B5 A5 A6]
time 5049ms: Time slice expired; preempting process B4 with 157ms remaining [Q B2 B7 B8 A9 B1 A0 B9 A1 A7 B0 B3 A8 A2 A3 B5 A5 A6]
time 5053ms: Process B2 started using the CPU for remaining 55ms of 183ms burst [Q B7 B8 A9 B1 A0 B9 A1 A7 B0 B3 A8 A2 A3 B5 A5 A6 B4]
time 5053ms: Process B6 completed I/O; added to ready queue [Q B7 B8 A9 B1 A0 B9 A1 A7 B0 B3 A8 A2 A3 B5 A5 A6 B4 B6]
time 5072ms: Process A4 completed I/O; added to ready queue [Q B7 B8 A9 B1 A0 B9 A1 A7 B0 B3 A8 A2 A3 B5 A5 A6 B4 B6 A4]
time 5108ms: Process B2 completed a CPU burst; 13 bursts to go [Q B7 B8 A9 B1 A0 B9 A1 A7 B0 B3 A8 A2 A3 B5 A5 A6 B4 B6 A4]
time 5108ms: Process B2 switching out of CPU; blocking on I/O until time 5422ms [Q B7 B8 A9 B1 A0 B9 A1 A7 B0 B3 A8 A2 A3 B5 A5 A6 B4 B6 A4]
time 5112ms: Process B7 started using the CPU for 20ms burst [Q B8 A9 B1 A0 B9 A1 A7 B0 B3 A8 A2 A3 B5 A5 A6 B4 B6 A4]
time 5132ms: Process B7 completed a CPU burst; 24 bursts to go [Q B8 A9 B1 A0 B9 A1 A7 B0 B3 A8 A2 A3 B5 A5 A6 B4 B6 A4]
time 5132ms: Process B7 switching out of CPU; blocking on I/O until time 5174ms [Q B8 A9 B1 A0 B9 A1 A7 B0 B3 A8 A2 A3 B5 A5 A6 B4 B6 A4]
time 5136ms: Process B8 started using the CPU for remaining 52ms of 308ms burst [Q A9 B1 A0 B9 A1 A7 B0 B3 A8 A2 A3 B5 A5 A6 B4 B6 A4]
time 5174ms: Process B7 completed I/O; added to ready queue [Q A9 B1 A0 B9 A1 A7 B0 B3 A8 A2 A3 B5 A5 A6 B4 B6 A4 B7]
time 5188ms: Process B8 completed a CPU burst; 19 bursts to go [Q A9 B1 A0 B9 A1 A7 B0 B3 A8 A2 A3 B5 A5 A6 B4 B6 A4 B7]
time 5188ms: Process B8 switching out of CPU; blocking on I/O until time 7470ms [Q A9 B1 A0 B9 A1 A7 B0 B3 A8 A2 A3 B5 A5 A6 B4 B6 A4 B7]
time 5192ms: Process A9 started using the CPU for remaining 40ms of 360ms burst [Q B1 A0 B9 A1 A7 B0 B3 A8 A2 A3 B5 A5 A6 B4 B6 A4 B7]
time 5232ms: Process A9 completed a CPU burst; 31 bursts to go [Q B1 A0 B9 A1 A7 B0 B3 A8 A2 A3 B5 A5 A6 B4 B6 A4 B7]
time 5232ms: Process A9 switching out of CPU; blocking on I/O until time 5274ms [Q B1 A0 B9 A1 A7 B0 B3 A8 A2 A3 B5 A5 A6 B4 B6 A4 B7]
time 5236ms: Process B1 started using the CPU for remaining 2748ms of 3004ms burst [Q A0 B9 A1 A7 B0 B3 A8 A2 A3 B5 A5 A6 B4 B6 A4 B7]
time 5274ms: Process A9 completed I/O; added to ready queue [Q A0 B9 A1 A7 B0 B3 A8 A2 A3 B5 A5 A6 B4 B6 A4 B7 A9]
time 5300ms: Time slice expired; preempting process B1 with 2684ms remaining [Q A0 B9 A1 A7 B0 B3 A8 A2 A3 B5 A5 A6 B4 B6 A4 B7 A9]
time 5304ms: Process A0 started using the CPU for remaining 1032ms of 1096ms burst [Q B9 A1 A7 B0 B3 A8 A2 A3 B5 A5 A6 B4 B6 A4 B7 A9 B1]
time 5368ms: Time slice expired; preempting process A0 with 968ms remaining [Q B9 A1 A7 B0 B3 A8 A2 A3 B5 A5 A6 B4 B6 A4 B7 A9 B1]
time 5372ms: Process B9 started using the CPU for 64ms burst [Q A1 A7 B0 B3 A8 A2 A3 B5 A5 A6 B4 B6 A4 B7 A9 B1 A0]
time 5422ms: Process B2 completed I/O; added to ready queue [Q A1 A7 B0 B3 A8 A2 A3 B5 A5 A6 B4 B6 A4 B7 A9 B1 A0 B2]
time 5436ms: Process B9 completed a CPU burst; 8 bursts to go [Q A1 A7 B0 B3 A8 A2 A3 B5 A5 A6 B4 B6 A4 B7 A9 B1 A0 B2]
time 5436ms: Process B9 switching out of CPU; blocking on I/O until time 6278ms [Q A1 A7 B0 B3 A8 A2 A3 B5 A5 A6 B4 B6 A4 B7 A9 B1 A0 B2]
time 5440ms: Process A1 started using the CPU for remaining 312ms of 632ms burst [Q A7 B0 B3 A8 A2 A3 B5 A5 A6 B4 B6 A4 B7 A9 B1 A0 B2]
time 5504ms: Time slice expired; preempting process A1 with 248ms remaining [Q A7 B0 B3 A8 A2 A3 B5 A5 A6 B4 B6 A4 B7 A9 B1 A0 B2]
time 5508ms: Process A7 started using the CPU for remaining 576ms of 768ms burst [Q B0 B3 A8 A2 A3 B5 A5 A6 B4 B6 A4 B7 A9 B1 A0 B2 A1]
time 5572ms: Time slice expired; preempting process A7 with 512ms remaining [Q B0 B3 A8 A2 A3 B5 A5 A6 B4 B6 A4 B7 A9 B1 A0 B2 A1]
time 5576ms: Process B0 started using the CPU for remaining 1200ms of 1264ms burst [Q B3 A8 A2 A3 B5 A5 A6 B4 B6 A4 B7 A9 B1 A0 B2 A1 A7]
time 5640ms: Time slice expired; preempting process B0 with 1136ms remaining [Q B3 A8 A2 A3 B5 A5 A6 B4 B6 A4 B7 A9 B1 A0 B2 A1 A7]
time 5644ms: Process B3 started using the CPU for remaining 65ms of 129ms burst [Q A8 A2 A3 B5 A5 A6 B4 B6 A4 B7 A9 B1 A0 B2 A1 A7 B0]
time 5708ms: Time slice expired; preempting process B3 with 1ms remaining [Q A8 A2 A3 B5 A5 A6 B4 B6 A4 B7 A9 B1 A0 B2 A1 A7 B0]
time 5712ms: Process A8 started using the CPU for remaining 100ms of 420ms burst [Q A2 A3 B5 A5 A6 B4 B6 A4 B7 A9 B1 A0 B2 A1 A7 B0 B3]
time 5776ms: Time slice expired; preempting process A8 with 36ms remaining [Q A2 A3 B5 A5 A6 B4 B6 A4 B7 A9 B1 A0 B2 A1 A7 B0 B3]
time 5780ms: Process A2 started using the CPU for remaining 188ms of 444ms burst [Q A3 B5 A5 A6 B4 B6 A4 B7 A9 B1 A0 B2 A1 A7 B0 B3 A8]
time 5844ms: Time slice expired; preempting process A2 with 124ms remaining [Q A3 B5 A5 A6 B4 B6 A4 B7 A9 B1 A0 B2 A1 A7 B0 B3 A8]
time 5848ms: Process A3 started using the CPU for remaining 180ms of 308ms burst [Q B5 A5 A6 B4 B6 A4 B7 A9 B1 A0 B2 A1 A7 B0 B3 A8 A2]
time 5912ms: Time slice expired; preempting process A3 with 116ms remaining [Q B5 A5 A6 B4 B6 A4 B7 A9 B1 A0 B2 A1 A7 B0 B3 A8 A2]
time 5916ms: Process B5 started using the CPU for 14ms burst [Q A5 A6 B4 B6 A4 B7 A9 B1 A0 B2 A1 A7 B0 B3 A8 A2 A3]
time 5930ms: Process B5 completed a CPU burst; 26 bursts to go [Q A5 A6 B4 B6 A4 B7 A9 B1 A0 B2 A1 A7 B0 B3 A8 A2 A3]
time 5930ms: Process B5 switching out of CPU; blocking on I/O until time 7052ms [Q A5 A6 B4 B6 A4 B7 A9 B1 A0 B2 A1 A7 B0 B3 A8 A2 A3]
time 5934ms: Process A5 started using the CPU for remaining 76ms of 140ms burst [Q A6 B4 B6 A4 B7 A9 B1 A0 B2 A1 A7 B0 B3 A8 A2 A3]
time 5998ms: Time slice expired; preempting process A5 with 12ms remaining [Q A6 B4 B6 A4 B7 A9 B1 A0 B2 A1 A7 B0 B3 A8 A2 A3]
time 6002ms: Process A6 started using the CPU for remaining 36ms of 100ms burst [Q B4 B6 A4 B7 A9 B1 A0 B2 A1 A7 B0 B3 A8 A2 A3 A5]
time 6038ms: Process A6 completed a CPU burst; 16 bursts to go [Q B4 B6 A4 B7 A9 B1 A0 B2 A1 A7 B0 B3 A8 A2 A3 A5]
time 6038ms: Process A6 switching out of CPU; blocking on I/O until time 6055ms [Q B4 B6 A4 B7 A9 B1 A0 B2 A1 A7 B0 B3 A8 A2 A3 A5]
time 6042ms: Process B4 started using the CPU for remaining 157ms of 285ms burst [Q B6 A4 B7 A9 B1 A0 B2 A1 A7 B0 B3 A8 A2 A3 A5]
time 6055ms: Process A6 completed I/O; added to ready queue [Q B6 A4 B7 A9 B1 A0 B2 A1 A7 B0 B3 A8 A2 A3 A5 A6]
time 6106ms: Time slice expired; preempting process B4 with 93ms remaining [Q B6 A4 B7 A9 B1 A0 B2 A1 A7 B0 B3 A8 A2 A3 A5 A6]
time 6110ms: Process B6 started using the CPU for 142ms burst [Q A4 B7 A9 B1 A0 B2 A1 A7 B0 B3 A8 A2 A3 A5 A6 B4]
time 6174ms: Time slice expired; preempting process B6 with 78ms remaining [Q A4 B7 A9 B1 A0 B2 A1 A7 B0 B3 A8 A2 A3 A5 A6 B4]
time 6178ms: Process A4 started using the CPU for 20ms burst [Q B7 A9 B1 A0 B2 A1 A7 B0 B3 A8 A2 A3 A5 A6 B4 B6]
time 6198ms: Process A4 completed a CPU burst; 2 bursts to go [Q B7 A9 B1 A0 B2 A1 A7 B0 B3 A8 A2 A3 A5 A6 B4 B6]
time 6198ms: Process A4 switching out of CPU; blocking on I/O until time 6360ms [Q B7 A9 B1 A0 B2 A1 A7 B0 B3 A8 A2 A3 A5 A6 B4 B6]
time 6202ms: Process B7 started using the CPU for 3ms burst [Q A9 B1 A0 B2 A1 A7 B0 B3 A8 A2 A3 A5 A6 B4 B6]
time 6205ms: Process B7 completed a CPU burst; 23 bursts to go [Q A9 B1 A0 B2 A1 A7 B0 B3 A8 A2 A3 A5 A6 B4 B6]
time 6205ms: Process B7 switching out of CPU; blocking on I/O until time 9167ms [Q A9 B1 A0 B2 A1 A7 B0 B3 A8 A2 A3 A5 A6 B4 B6]
time 6209ms: Process A9 started using the CPU for 28ms burst [Q B1 A0 B2 A1 A7 B0 B3 A8 A2 A3 A5 A6 B4 B6]
time 6237ms: Process A9 completed a CPU burst; 30 bursts to go [Q B1 A0 B2 A1 A7 B0 B3 A8 A2 A3 A5 A6 B4 B6]
time 6237ms: Process A9 switching out of CPU; blocking on I/O until time 6267ms [Q B1 A0 B2 A1 A7 B0 B3 A8 A2 A3 A5 A6 B4 B6]
time 6241ms: Process B1 started using the CPU for remaining 2684ms of 3004ms burst [Q A0 B2 A1 A7 B0 B3 A8 A2 A3 A5 A6 B4 B6]
time 6267ms: Process A9 completed I/O; added to ready queue [Q A0 B2 A1 A7 B0 B3 A8 A2 A3 A5 A6 B4 B6 A9]
time 6278ms: Process B9 completed I/O; added to ready queue [Q A0 B2 A1 A7 B0 B3 A8 A2 A3 A5 A6 B4 B6 A9 B9]
time 6305ms: Time slice expired; preempting process B1 with 2620ms remaining [Q A0 B2 A1 A7 B0 B3 A8 A2 A3 A5 A6 B4 B6 A9 B9]
time 6309ms: Process A0 started using the CPU for remaining 968ms of 1096ms burst [Q B2 A1 A7 B0 B3 A8 A2 A3 A5 A6 B4 B6 A9 B9 B1]
time 6360ms: Process A4 completed I/O; added to ready queue [Q B2 A1 A7 B0 B3 A8 A2 A3 A5 A6 B4 B6 A9 B9 B1 A4]
time 6373ms: Time slice expired; preempting process A0 with 904ms remaining [Q B2 A1 A7 B0 B3 A8 A2 A3 A5 A6 B4 B6 A9 B9 B1 A4]
time 6377ms: Process B2 started using the CPU for 219ms burst [Q A1 A7 B0 B3 A8 A2 A3 A5 A6 B4 B6 A9 B9 B1 A4 A0]
time 6441ms: Time slice expired; preempting process B2 with 155ms remaining [Q A1 A7 B0 B3 A8 A2 A3 A5 A6 B4 B6 A9 B9 B1 A4 A0]
time 6445ms: Process A1 started using the CPU for remaining 248ms of 632ms burst [Q A7 B0 B3 A8 A2 A3 A5 A6 B4 B6 A9 B9 B1 A4 A0 B2]
time 6509ms: Time slice expired; preempting process A1 with 184ms remaining [Q A7 B0 B3 A8 A2 A3 A5 A6 B4 B6 A9 B9 B1 A4 A0 B2]
time 6513ms: Process A7 started using the CPU for remaining 512ms of 768ms burst [Q B0 B3 A8 A2 A3 A5 A6 B4 B6 A9 B9 B1 A4 A0 B2 A1]
time 6577ms: Time slice expired; preempting process A7 with 448ms remaining [Q B0 B3 A8 A2 A3 A5 A6 B4 B6 A9 B9 B1 A4 A0 B2 A1]
time 6581ms: Process B0 started using the CPU for remaining 1136ms of 1264ms burst [Q B3 A8 A2 A3 A5 A6 B4 B6 A9 B9 B1 A4 A0 B2 A1 A7]
time 6645ms: Time slice expired; preempting process B0 with 1072ms remaining [Q B3 A8 A2 A3 A5 A6 B4 B6 A9 B9 B1 A4 A0 B2 A1 A7]
time 6649ms: Process B3 started using the CPU for remaining 1ms of 129ms burst [Q A8 A2 A3 A5 A6 B4 B6 A9 B9 B1 A4 A0 B2 A1 A7 B0]
time 6650ms: Process B3 completed a CPU burst; 20 bursts to go [Q A8 A2 A3 A5 A6 B4 B6 A9 B9 B1 A4 A0 B2 A1 A7 B0]
time 6650ms: Process B3 switching out of CPU; blocking on I/O until time 8012ms [Q A8 A2 A3 A5 A6 B4 B6 A9 B9 B1 A4 A0 B2 A1 A7 B0]
time 6654ms: Process A8 started using the CPU for remaining 36ms of 420ms burst [Q A2 A3 A5 A6 B4 B6 A9 B9 B1 A4 A0 B2 A1 A7 B0]
time 6690ms: Process A8 completed a CPU burst; 7 bursts to go [Q A2 A3 A5 A6 B4 B6 A9 B9 B1 A4 A0 B2 A1 A7 B0]
time 6690ms: Process A8 switching out of CPU; blocking on I/O until time 6746ms [Q A2 A3 A5 A6 B4 B6 A9 B9 B1 A4 A0 B2 A1 A7 B0]
time 6694ms: Process A2 started using the CPU for remaining 124ms of 444ms burst [Q A3 A5 A6 B4 B6 A9 B9 B1 A4 A0 B2 A1 A7 B0]
time 6746ms: Process A8 completed I/O; added to ready queue [Q A3 A5 A6 B4 B6 A9 B9 B1 A4 A0 B2 A1 A7 B0 A8]
time 6758ms: Time slice expired; preempting process A2 with 60ms remaining [Q A3 A5 A6 B4 B6 A9 B9 B1 A4 A0 B2 A1 A7 B0 A8]
time 6762ms: Process A3 started using the CPU for remaining 116ms of 308ms burst [Q A5 A6 B4 B6 A9 B9 B1 A4 A0 B2 A1 A7 B0 A8 A2]
time 6826ms: Time slice expired; preempting process A3 with 52ms remaining [Q A5 A6 B4 B6 A9 B9 B1 A4 A0 B2 A1 A7 B0 A8 A2]
time 6830ms: Process A5 started using the CPU for remaining 12ms of 140ms burst [Q A6 B4 B6 A9 B9 B1 A4 A0 B2 A1 A7 B0 A8 A2 A3]
time 6842ms: Process A5 completed a CPU burst; 3 bursts to go [Q A6 B4 B6 A9 B9 B1 A4 A0 B2 A1 A7 B0 A8 A2 A3]
time 6842ms: Process A5 switching out of CPU; blocking on I/O until time 6956ms [Q A6 B4 B6 A9 B9 B1 A4 A0 B2 A1 A7 B0 A8 A2 A3]
time 6846ms: Process A6 started using the CPU for 344ms burst [Q B4 B6 A9 B9 B1 A4 A0 B2 A1 A7 B0 A8 A2 A3]
time 6910ms: Time slice expired; preempting process A6 with 280ms remaining [Q B4 B6 A9 B9 B1 A4 A0 B2 A1 A7 B0 A8 A2 A3]
time 6914ms: Process B4 started using the CPU for remaining 93ms of 285ms burst [Q B6 A9 B9 B1 A4 A0 B2 A1 A7 B0 A8 A2 A3 A6]
time 6956ms: Process A5 completed I/O; added to ready queue [Q B6 A9 B9 B1 A4 A0 B2 A1 A7 B0 A8 A2 A3 A6 A5]
time 6978ms: Time slice expired; preempting process B4 with 29ms remaining [Q B6 A9 B9 B1 A4 A0 B2 A1 A7 B0 A8 A2 A3 A6 A5]
time 6982ms: Process B6 started using the CPU for remaining 78ms of 142ms burst [Q A9 B9 B1 A4 A0 B2 A1 A7 B0 A8 A2 A3 A6 A5 B4]
time 7046ms: Time slice expired; preempting process B6 with 14ms remaining [Q A9 B9 B1 A4 A0 B2 A1 A7 B0 A8 A2 A3 A6 A5 B4]
time 7050ms: Process A9 started using the CPU for 308ms burst [Q B9 B1 A4 A0 B2 A1 A7 B0 A8 A2 A3 A6 A5 B4 B6]
time 7052ms: Process B5 completed I/O; added to ready queue [Q B9 B1 A4 A0 B2 A1 A7 B0 A8 A2 A3 A6 A5 B4 B6 B5]
time 7114ms: Time slice expired; preempting process A9 with 244ms remaining [Q B9 B1 A4 A0 B2 A1 A7 B0 A8 A2 A3 A6 A5 B4 B6 B5]
time 7118ms: Process B9 started using the CPU for 181ms burst [Q B1 A4 A0 B2 A1 A7 B0 A8 A2 A3 A6 A5 B4 B6 B5 A9]
time 7182ms: Time slice expired; preempting process B9 with 117ms remaining [Q B1 A4 A0 B2 A1 A7 B0 A8 A2 A3 A6 A5 B4 B6 B5 A9]
time 7186ms: Process B1 started using the CPU for remaining 2620ms of 3004ms burst [Q A4 A0 B2 A1 A7 B0 A8 A2 A3 A6 A5 B4 B6 B5 A9 B9]
time 7250ms: Time slice expired; preempting process B1 with 2556ms remaining [Q A4 A0 B2 A1 A7 B0 A8 A2 A3 A6 A5 B4 B6 B5 A9 B9]
time 7254ms: Process A4 started using the CPU for 1248ms burst [Q A0 B2 A1 A7 B0 A8 A2 A3 A6 A5 B4 B6 B5 A9 B9 B1]
time 7318ms: Time slice expired; preempting process A4 with 1184ms remaining [Q A0 B2 A1 A7 B0 A8 A2 A3 A6 A5 B4 B6 B5 A9 B9 B1]
time 7322ms: Process A0 started using the CPU for remaining 904ms of 1096ms burst [Q B2 A1 A7 B0 A8 A2 A3 A6 A5 B4 B6 B5 A9 B9 B1 A4]
time 7386ms: Time slice expired; preempting process A0 with 840ms remaining [Q B2 A1 A7 B0 A8 A2 A3 A6 A5 B4 B6 B5 A9 B9 B1 A4]
time 7390ms: Process B2 started using the CPU for remaining 155ms of 219ms burst [Q A1 A7 B0 A8 A2 A3 A6 A5 B4 B6 B5 A9 B9 B1 A4 A0]
time 7454ms: Time slice expired; preempting process B2 with 91ms remaining [Q A1 A7 B0 A8 A2 A3 A6 A5 B4 B6 B5 A9 B9 B1 A4 A0]
time 7458ms: Process A1 started using the CPU for remaining 184ms of 632ms burst [Q A7 B0 A8 A2 A3 A6 A5 B4 B6 B5 A9 B9 B1 A4 A0 B2]
time 7470ms: Process B8 completed I/O; added to ready queue [Q A7 B0 A8 A2 A3 A6 A5 B4 B6 B5 A9 B9 B1 A4 A0 B2 B8]
time 7522ms: Time slice expired; preempting process A1 with 120ms remaining [Q A7 B0 A8 A2 A3 A6 A5 B4 B6 B5 A9 B9 B1 A4 A0 B2 B8]
time 7526ms: Process A7 started using the CPU for remaining 448ms of 768ms burst [Q B0 A8 A2 A3 A6 A5 B4 B6 B5 A9 B9 B1 A4 A0 B2 B8 A1]
time 7590ms: Time slice expired; preempting process A7 with 384ms remaining [Q B0 A8 A2 A3 A6 A5 B4 B6 B5 A9 B9 B1 A4 A0 B2 B8 A1]
time 7594ms: Process B0 started using the CPU for remaining 1072ms of 1264ms burst [Q A8 A2 A3 A6 A5 B4 B6 B5 A9 B9 B1 A4 A0 B2 B8 A1 A7]
time 7658ms: Time slice expired; preempting process B0 with 1008ms remaining [Q A8 A2 A3 A6 A5 B4 B6 B5 A9 B9 B1 A4 A0 B2 B8 A1 A7]
time 7662ms: Process A8 started using the CPU for 176ms burst [Q A2 A3 A6 A5 B4 B6 B5 A9 B9 B1 A4 A0 B2 B8 A1 A7 B0]
time 7726ms: Time slice expired; preempting process A8 with 112ms remaining [Q A2 A3 A6 A5 B4 B6 B5 A9 B9 B1 A4 A0 B2 B8 A1 A7 B0]
time 7730ms: Process A2 started using the CPU for remaining 60ms of 444ms burst [Q A3 A6 A5 B4 B6 B5 A9 B9 B1 A4 A0 B2 B8 A1 A7 B0 A8]
time 7790ms: Process A2 completed a CPU burst; 28 bursts to go [Q A3 A6 A5 B4 B6 B5 A9 B9 B1 A4 A0 B2 B8 A1 A7 B0 A8]
time 7790ms: Process A2 switching out of CPU; blocking on I/O until time 8251ms [Q A3 A6 A5 B4 B6 B5 A9 B9 B1 A4 A0 B2 B8 A1 A7 B0 A8]
time 7794ms: Process A3 started using the CPU for remaining 52ms of 308ms burst [Q A6 A5 B4 B6 B5 A9 B9 B1 A4 A0 B2 B8 A1 A7 B0 A8]
time 7846ms: Process A3 completed a CPU burst; 24 bursts to go [Q A6 A5 B4 B6 B5 A9 B9 B1 A4 A0 B2 B8 A1 A7 B0 A8]
time 7846ms: Process A3 switching out of CPU; blocking on I/O until time 7936ms [Q A6 A5 B4 B6 B5 A9 B9 B1 A4 A0 B2 B8 A1 A7 B0 A8]
time 7850ms: Process A6 started using the CPU for remaining 280ms of 344ms burst [Q A5 B4 B6 B5 A9 B9 B1 A4 A0 B2 B8 A1 A7 B0 A8]
time 7914ms: Time slice expired; preempting process A6 with 216ms remaining [Q A5 B4 B6 B5 A9 B9 B1 A4 A0 B2 B8 A1 A7 B0 A8]
time 7918ms: Process A5 started using the CPU for 200ms burst [Q B4 B6 B5 A9 B9 B1 A4 A0 B2 B8 A1 A7 B0 A8 A6]
time 7936ms: Process A3 completed I/O; added to ready queue [Q B4 B6 B5 A9 B9 B1 A4 A0 B2 B8 A1 A7 B0 A8 A6 A3]
time 7982ms: Time slice expired; preempting process A5 with 136ms remaining [Q B4 B6 B5 A9 B9 B1 A4 A0 B2 B8 A1 A7 B0 A8 A6 A3]
time 7986ms: Process B4 started using the CPU for remaining 29ms of 285ms burst [Q B6 B5 A9 B9 B1 A4 A0 B2 B8 A1 A7 B0 A8 A6 A3 A5]
time 8012ms: Process B3 completed I/O; added to ready queue [Q B6 B5 A9 B9 B1 A4 A0 B2 B8 A1 A7 B0 A8 A6 A3 A5 B3]
time 8015ms: Process B4 completed a CPU burst; 13 bursts to go [Q B6 B5 A9 B9 B1 A4 A0 B2 B8 A1 A7 B0 A8 A6 A3 A5 B3]
time 8015ms: Process B4 switching out of CPU; blocking on I/O until time 8241ms [Q B6 B5 A9 B9 B1 A4 A0 B2 B8 A1 A7 B0 A8 A6 A3 A5 B3]
time 8019ms: Process B6 started using the CPU for remaining 14ms of 142ms burst [Q B5 A9 B9 B1 A4 A0 B2 B8 A1 A7 B0 A8 A6 A3 A5 B3]
time 8033ms: Process B6 completed a CPU burst; 3 bursts to go [Q B5 A9 B9 B1 A4 A0 B2 B8 A1 A7 B0 A8 A6 A3 A5 B3]
time 8033ms: Process B6 switching out of CPU; blocking on I/O until time 8907ms [Q B5 A9 B9 B1 A4 A0 B2 B8 A1 A7 B0 A8 A6 A3 A5 B3]
time 8037ms: Process B5 started using the CPU for 21ms burst [Q A9 B9 B1 A4 A0 B2 B8 A1 A7 B0 A8 A6 A3 A5 B3]
time 8058ms: Process B5 completed a CPU burst; 25 bursts to go [Q A9 B9 B1 A4 A0 B2 B8 A1 A7 B0 A8 A6 A3 A5 B3]
time 8058ms: Process B5 switching out of CPU; blocking on I/O until time 8076ms [Q A9 B9 B1 A4 A0 B2 B8 A1 A7 B0 A8 A6 A3 A5 B3]
time 8062ms: Process A9 started using the CPU for remaining 244ms of 308ms burst [Q B9 B1 A4 A0 B2 B8 A1 A7 B0 A8 A6 A3 A5 B3]
time 8076ms: Process B5 completed I/O; added to ready queue [Q B9 B1 A4 A0 B2 B8 A1 A7 B0 A8 A6 A3 A5 B3 B5]
time 8126ms: Time slice expired; preempting process A9 with 180ms remaining [Q B9 B1 A4 A0 B2 B8 A1 A7 B0 A8 A6 A3 A5 B3 B5]
time 8130ms: Process B9 started using the CPU for remaining 117ms of 181ms burst [Q B1 A4 A0 B2 B8 A1 A7 B0 A8 A6 A3 A5 B3 B5 A9]
time 8194ms: Time slice expired; preempting process B9 with 53ms remaining [Q B1 A4 A0 B2 B8 A1 A7 B0 A8 A6 A3 A5 B3 B5 A9]
time 8198ms: Process B1 started using the CPU for remaining 2556ms of 3004ms burst [Q A4 A0 B2 B8 A1 A7 B0 A8 A6 A3 A5 B3 B5 A9 B9]
time 8241ms: Process B4 completed I/O; added to ready queue [Q A4 A0 B2 B8 A1 A7 B0 A8 A6 A3 A5 B3 B5 A9 B9 B4]
time 8251ms: Process A2 completed I/O; added to ready queue [Q A4 A0 B2 B8 A1 A7 B0 A8 A6 A3 A5 B3 B5 A9 B9 B4 A2]
time 8262ms: Time slice expired; preempting process B1 with 2492ms remaining [Q A4 A0 B2 B8 A1 A7 B0 A8 A6 A3 A5 B3 B5 A9 B9 B4 A2]
time 8266ms: Process A4 started using the CPU for remaining 1184ms of 1248ms burst [Q A0 B2 B8 A1 A7 B0 A8 A6 A3 A5 B3 B5 A9 B9 B4 A2 B1]
time 8330ms: Time slice expired; preempting process A4 with 1120ms remaining [Q A0 B2 B8 A1 A7 B0 A8 A6 A3 A5 B3 B5 A9 B9 B4 A2 B1]
time 8334ms: Process A0 started using the CPU for remaining 840ms of 1096ms burst [Q B2 B8 A1 A7 B0 A8 A6 A3 A5 B3 B5 A9 B9 B4 A2 B1 A4]
time 8398ms: Time slice expired; preempting process A0 with 776ms remaining [Q B2 B8 A1 A7 B0 A8 A6 A3 A5 B3 B5 A9 B9 B4 A2 B1 A4]
time 8402ms: Process B2 started using the CPU for remaining 91ms of 219ms burst [Q B8 A1 A7 B0 A8 A6 A3 A5 B3 B5 A9 B9 B4 A2 B1 A4 A0]
time 8466ms: Time slice expired; preempting process B2 with 27ms remaining [Q B8 A1 A7 B0 A8 A6 A3 A5 B3 B5 A9 B9 B4 A2 B1 A4 A0]
time 8470ms: Process B8 started using the CPU for 18ms burst [Q A1 A7 B0 A8 A6 A3 A5 B3 B5 A9 B9 B4 A2 B1 A4 A0 B2]
time 8488ms: Process B8 completed a CPU burst; 18 bursts to go [Q A1 A7 B0 A8 A6 A3 A5 B3 B5 A9 B9 B4 A2 B1 A4 A0 B2]
time 8488ms: Process B8 switching out of CPU; blocking on I/O until time 8618ms [Q A1 A7 B0 A8 A6 A3 A5 B3 B5 A9 B9 B4 A2 B1 A4 A0 B2]
time 8492ms: Process A1 started using the CPU for remaining 120ms of 632ms burst [Q A7 B0 A8 A6 A3 A5 B3 B5 A9 B9 B4 A2 B1 A4 A0 B2]
time 8556ms: Time slice expired; preempting process A1 with 56ms remaining [Q A7 B0 A8 A6 A3 A5 B3 B5 A9 B9 B4 A2 B1 A4 A0 B2]
time 8560ms: Process A7 started using the CPU for remaining 384ms of 768ms burst [Q B0 A8 A6 A3 A5 B3 B5 A9 B9 B4 A2 B1 A4 A0 B2 A1]
time 8618ms: Process B8 completed I/O; added to ready queue [Q B0 A8 A6 A3 A5 B3 B5 A9 B9 B4 A2 B1 A4 A0 B2 A1 B8]
time 8624ms: Time slice expired; preempting process A7 with 320ms remaining [Q B0 A8 A6 A3 A5 B3 B5 A9 B9 B4 A2 B1 A4 A0 B2 A1 B8]
time 8628ms: Process B0 started using the CPU for remaining 1008ms of 1264ms burst [Q A8 A6 A3 A5 B3 B5 A9 B9 B4 A2 B1 A4 A0 B2 A1 B8 A7]
time 8692ms: Time slice expired; preempting process B0 with 944ms remaining [Q A8 A6 A3 A5 B3 B5 A9 B9 B4 A2 B1 A4 A0 B2 A1 B8 A7]
time 8696ms: Process A8 started using the CPU for remaining 112ms of 176ms burst [Q A6 A3 A5 B3 B5 A9 B9 B4 A2 B1 A4 A0 B2 A1 B8 A7 B0]
time 8760ms: Time slice expired; preempting process A8 with 48ms remaining [Q A6 A3 A5 B3 B5 A9 B9 B4 A2 B1 A4 A0 B2 A1 B8 A7 B0]
time 8764ms: Process A6 started using the CPU for remaining 216ms of 344ms burst [Q A3 A5 B3 B5 A9 B9 B4 A2 B1 A4 A0 B2 A1 B8 A7 B0 A8]
time 8828ms: Time slice expired; preempting process A6 with 152ms remaining [Q A3 A5 B3 B5 A9 B9 B4 A2 B1 A4 A0 B2 A1 B8 A7 B0 A8]
time 8832ms: Process A3 started using the CPU for 12ms burst [Q A5 B3 B5 A9 B9 B4 A2 B1 A4 A0 B2 A1 B8 A7 B0 A8 A6]
time 8844ms: Process A3 completed a CPU burst; 23 bursts to go [Q A5 B3 B5 A9 B9 B4 A2 B1 A4 A0 B2 A1 B8 A7 B0 A8 A6]
time 8844ms: Process A3 switching out of CPU; blocking on I/O until time 8909ms [Q A5 B3 B5 A9 B9 B4 A2 B1 A4 A0 B2 A1 B8 A7 B0 A8 A6]
time 8848ms: Process A5 started using the CPU for remaining 136ms of 200ms burst [Q B3 B5 A9 B9 B4 A2 B1 A4 A0 B2 A1 B8 A7 B0 A8 A6]
time 8907ms: Process B6 completed I/O; added to ready queue [Q B3 B5 A9 B9 B4 A2 B1 A4 A0 B2 A1 B8 A7 B0 A8 A6 B6]
time 8909ms: Process A3 completed I/O; added to ready queue [Q B3 B5 A9 B9 B4 A2 B1 A4 A0 B2 A1 B8 A7 B0 A8 A6 B6 A3]
time 8912ms: Time slice expired; preempting process A5 with 72ms remaining [Q B3 B5 A9 B9 B4 A2 B1 A4 A0 B2 A1 B8 A7 B0 A8 A6 B6 A3]
time 8916ms: Process B3 started using the CPU for 4ms burst [Q B5 A9 B9 B4 A2 B1 A4 A0 B2 A1 B8 A7 B0 A8 A6 B6 A3 A5]
time 8920ms: Process B3 completed a CPU burst; 19 bursts to go [Q B5 A9 B9 B4 A2 B1 A4 A0 B2 A1 B8 A7 B0 A8 A6 B6 A3 A5]
time 8920ms: Process B3 switching out of CPU; blocking on I/O until time 9074ms [Q B5 A9 B9 B4 A2 B1 A4 A0 B2 A1 B8 A7 B0 A8 A6 B6 A3 A5]
time 8924ms: Process B5 started using the CPU for 24ms burst [Q A9 B9 B4 A2 B1 A4 A0 B2 A1 B8 A7 B0 A8 A6 B6 A3 A5]
time 8948ms: Process B5 completed a CPU burst; 24 bursts to go [Q A9 B9 B4 A2 B1 A4 A0 B2 A1 B8 A7 B0 A8 A6 B6 A3 A5]
time 8948ms: Process B5 switching out of CPU; blocking on I/O until time 9102ms [Q A9 B9 B4 A2 B1 A4 A0 B2 A1 B8 A7 B0 A8 A6 B6 A3 A5]
time 8952ms: Process A9 started using the CPU for remaining 180ms of 308ms burst [Q B9 B4 A2 B1 A4 A0 B2 A1 B8 A7 B0 A8 A6 B6 A3 A5]
time 9016ms: Time slice expired; preempting process A9 with 116ms remaining [Q B9 B4 A2 B1 A4 A0 B2 A1 B8 A7 B0 A8 A6 B6 A3 A5]
time 9020ms: Process B9 started using the CPU for remaining 53ms of 181ms burst [Q B4 A2 B1 A4 A0 B2 A1 B8 A7 B0 A8 A6 B6 A3 A5 A9]
time 9073ms: Process B9 completed a CPU burst; 7 bursts to go [Q B4 A2 B1 A4 A0 B2 A1 B8 A7 B0 A8 A6 B6 A3 A5 A9]
time 9073ms: Process B9 switching out of CPU; blocking on I/O until time 9267ms [Q B4 A2 B1 A4 A0 B2 A1 B8 A7 B0 A8 A6 B6 A3 A5 A9]
time 9074ms: Process B3 completed I/O; added to ready queue [Q B4 A2 B1 A4 A0 B2 A1 B8 A7 B0 A8 A6 B6 A3 A5 A9 B3]
time 9077ms: Process B4 started using the CPU for 70ms burst [Q A2 B1 A4 A0 B2 A1 B8 A7 B0 A8 A6 B6 A3 A5 A9 B3]
time 9102ms: Process B5 completed I/O; added to ready queue [Q A2 B1 A4 A0 B2 A1 B8 A7 B0 A8 A6 B6 A3 A5 A9 B3 B5]
time 9141ms: Time slice expired; preempting process B4 with 6ms remaining [Q A2 B1 A4 A0 B2 A1 B8 A7 B0 A8 A6 B6 A3 A5 A9 B3 B5]
time 9145ms: Process A2 started using the CPU for 760ms burst [Q B1 A4 A0 B2 A1 B8 A7 B0 A8 A6 B6 A3 A5 A9 B3 B5 B4]
time 9167ms: Process B7 completed I/O; added to ready queue [Q B1 A4 A0 B2 A1 B8 A7 B0 A8 A6 B6 A3 A5 A9 B3 B5 B4 B7]
time 9209ms: Time slice expired; preempting process A2 with 696ms remaining [Q B1 A4 A0 B2 A1 B8 A7 B0 A8 A6 B6 A3 A5 A9 B3 B5 B4 B7]
time 9213ms: Process B1 started using the CPU for remaining 2492ms of 3004ms burst [Q A4 A0 B2 A1 B8 A7 B0 A8 A6 B6 A3 A5 A9 B3 B5 B4 B7 A2]
time 9267ms: Process B9 completed I/O; added to ready queue [Q A4 A0 B2 A1 B8 A7 B0 A8 A6 B6 A3 A5 A9 B3 B5 B4 B7 A2 B9]
time 9277ms: Time slice expired; preempting process B1 with 2428ms remaining [Q A4 A0 B2 A1 B8 A7 B0 A8 A6 B6 A3 A5 A9 B3 B5 B4 B7 A2 B9]
time 9281ms: Process A4 started using the CPU for remaining 1120ms of 1248ms burst [Q A0 B2 A1 B8 A7 B0 A8 A6 B6 A3 A5 A9 B3 B5 B4 B7 A2 B9 B1]
time 9345ms: Time slice expired; preempting process A4 with 1056ms remaining [Q A0 B2 A1 B8 A7 B0 A8 A6 B6 A3 A5 A9 B3 B5 B4 B7 A2 B9 B1]
time 9349ms: Process A0 started using the CPU for remaining 776ms of 1096ms burst [Q B2 A1 B8 A7 B0 A8 A6 B6 A3 A5 A9 B3 B5 B4 B7 A2 B9 B1 A4]
time 9413ms: Time slice expired; preempting process A0 with 712ms remaining [Q B2 A1 B8 A7 B0 A8 A6 B6 A3 A5 A9 B3 B5 B4 B7 A2 B9 B1 A4]
time 9417ms: Process B2 started using the CPU for remaining 27ms of 219ms burst [Q A1 B8 A7 B0 A8 A6 B6 A3 A5 A9 B3 B5 B4 B7 A2 B9 B1 A4 A0]
time 9444ms: Process B2 completed a CPU burst; 12 bursts to go [Q A1 B8 A7 B0 A8 A6 B6 A3 A5 A9 B3 B5 B4 B7 A2 B9 B1 A4 A0]
time 9444ms: Process B2 switching out of CPU; blocking on I/O until time 9718ms [Q A1 B8 A7 B0 A8 A6 B6 A3 A5 A9 B3 B5 B4 B7 A2 B9 B1 A4 A0]
time 9448ms: Process A1 started using the CPU for remaining 56ms of 632ms burst [Q B8 A7 B0 A8 A6 B6 A3 A5 A9 B3 B5 B4 B7 A2 B9 B1 A4 A0]
time 9504ms: Process A1 completed a CPU burst; 11 bursts to go [Q B8 A7 B0 A8 A6 B6 A3 A5 A9 B3 B5 B4 B7 A2 B9 B1 A4 A0]
time 9504ms: Process A1 switching out of CPU; blocking on I/O until time 9544ms [Q B8 A7 B0 A8 A6 B6 A3 A5 A9 B3 B5 B4 B7 A2 B9 B1 A4 A0]
time 9508ms: Process B8 started using the CPU for 75ms burst [Q A7 B0 A8 A6 B6 A3 A5 A9 B3 B5 B4 B7 A2 B9 B1 A4 A0]
time 9544ms: Process A1 completed I/O; added to ready queue [Q A7 B0 A8 A6 B6 A3 A5 A9 B3 B5 B4 B7 A2 B9 B1 A4 A0 A1]
time 9572ms: Time slice expired; preempting process B8 with 11ms remaining [Q A7 B0 A8 A6 B6 A3 A5 A9 B3 B5 B4 B7 A2 B9 B1 A4 A0 A1]
time 9576ms: Process A7 started using the CPU for remaining 320ms of 768ms burst [Q B0 A8 A6 B6 A3 A5 A9 B3 B5 B4 B7 A2 B9 B1 A4 A0 A1 B8]
time 9640ms: Time slice expired; preempting process A7 with 256ms remaining [Q B0 A8 A6 B6 A3 A5 A9 B3 B5 B4 B7 A2 B9 B1 A4 A0 A1 B8]
time 9644ms: Process B0 started using the CPU for remaining 944ms of 1264ms burst [Q A8 A6 B6 A3 A5 A9 B3 B5 B4 B7 A2 B9 B1 A4 A0 A1 B8 A7]
time 9708ms: Time slice expired; preempting process B0 with 880ms remaining [Q A8 A6 B6 A3 A5 A9 B3 B5 B4 B7 A2 B9 B1 A4 A0 A1 B8 A7]
time 9712ms: Process A8 started using the CPU for remaining 48ms of 176ms burst [Q A6 B6 A3 A5 A9 B3 B5 B4 B7 A2 B9 B1 A4 A0 A1 B8 A7 B0]
time 9718ms: Process B2 completed I/O; added to ready queue [Q A6 B6 A3 A5 A9 B3 B5 B4 B7 A2 B9 B1 A4 A0 A1 B8 A7 B0 B2]
time 9760ms: Process A8 completed a CPU burst; 6 bursts to go [Q A6 B6 A3 A5 A9 B3 B5 B4 B7 A2 B9 B1 A4 A0 A1 B8 A7 B0 B2]
time 9760ms: Process A8 switching out of CPU; blocking on I/O until time 9800ms [Q A6 B6 A3 A5 A9 B3 B5 B4 B7 A2 B9 B1 A4 A0 A1 B8 A7 B0 B2]
time 9764ms: Process A6 started using the CPU for remaining 152ms of 344ms burst [Q B6 A3 A5 A9 B3 B5 B4 B7 A2 B9 B1 A4 A0 A1 B8 A7 B0 B2]
time 9800ms: Process A8 completed I/O; added to ready queue [Q B6 A3 A5 A9 B3 B5 B4 B7 A2 B9 B1 A4 A0 A1 B8 A7 B0 B2 A8]
time 9828ms: Time slice expired; preempting process A6 with 88ms remaining [Q B6 A3 A5 A9 B3 B5 B4 B7 A2 B9 B1 A4 A0 A1 B8 A7 B0 B2 A8]
time 9832ms: Process B6 started using the CPU for 235ms burst [Q A3 A5 A9 B3 B5 B4 B7 A2 B9 B1 A4 A0 A1 B8 A7 B0 B2 A8 A6]
time 9896ms: Time slice expired; preempting process B6 with 171ms remaining [Q A3 A5 A9 B3 B5 B4 B7 A2 B9 B1 A4 A0 A1 B8 A7 B0 B2 A8 A6]
time 9900ms: Process A3 started using the CPU for 28ms burst [Q A5 A9 B3 B5 B4 B7 A2 B9 B1 A4 A0 A1 B8 A7 B0 B2 A8 A6 B6]
time 9928ms: Process A3 completed a CPU burst; 22 bursts to go [Q A5 A9 B3 B5 B4 B7 A2 B9 B1 A4 A0 A1 B8 A7 B0 B2 A8 A6 B6]
time 9928ms: Process A3 switching out of CPU; blocking on I/O until time 10168ms [Q A5 A9 B3 B5 B4 B7 A2 B9 B1 A4 A0 A1 B8 A7 B0 B2 A8 A6 B6]
time 9932ms: Process A5 started using the CPU for remaining 72ms of 200ms burst [Q A9 B3 B5 B4 B7 A2 B9 B1 A4 A0 A1 B8 A7 B0 B2 A8 A6 B6]
time 9996ms: Time slice expired; preempting process A5 with 8ms remaining [Q A9 B3 B5 B4 B7 A2 B9 B1 A4 A0 A1 B8 A7 B0 B2 A8 A6 B6]
time 10000ms: Process A9 started using the CPU for remaining 116ms of 308ms burst [Q B3 B5 B4 B7 A2 B9 B1 A4 A0 A1 B8 A7 B0 B2 A8 A6 B6 A5]
time 10064ms: Time slice expired; preempting process A9 with 52ms remaining [Q B3 B5 B4 B7 A2 B9 B1 A4 A0 A1 B8 A7 B0 B2 A8 A6 B6 A5]
time 10068ms: Process B3 started using the CPU for 82ms burst [Q B5 B4 B7 A2 B9 B1 A4 A0 A1 B8 A7 B0 B2 A8 A6 B6 A5 A9]
time 10132ms: Time slice expired; preempting process B3 with 18ms remaining [Q B5 B4 B7 A2 B9 B1 A4 A0 A1 B8 A7 B0 B2 A8 A6 B6 A5 A9]
time 10136ms: Process B5 started using the CPU for 120ms burst [Q B4 B7 A2 B9 B1 A4 A0 A1 B8 A7 B0 B2 A8 A6 B6 A5 A9 B3]
time 10168ms: Process A3 completed I/O; added to ready queue [Q B4 B7 A2 B9 B1 A4 A0 A1 B8 A7 B0 B2 A8 A6 B6 A5 A9 B3 A3]
time 10200ms: Time slice expired; preempting process B5 with 56ms remaining [Q B4 B7 A2 B9 B1 A4 A0 A1 B8 A7 B0 B2 A8 A6 B6 A5 A9 B3 A3]
time 10204ms: Process B4 started using the CPU for remaining 6ms of 70ms burst [Q B7 A2 B9 B1 A4 A0 A1 B8 A7 B0 B2 A8 A6 B6 A5 A9 B3 A3 B5]
time 10210ms: Process B4 completed a CPU burst; 12 bursts to go [Q B7 A2 B9 B1 A4 A0 A1 B8 A7 B0 B2 A8 A6 B6 A5 A9 B3 A3 B5]
time 10210ms: Process B4 switching out of CPU; blocking on I/O until time 10380ms [Q B7 A2 B9 B1 A4 A0 A1 B8 A7 B0 B2 A8 A6 B6 A5 A9 B3 A3 B5]
time 10214ms: Process B7 started using the CPU for 74ms burst [Q A2 B9 B1 A4 A0 A1 B8 A7 B0 B2 A8 A6 B6 A5 A9 B3 A3 B5]
time 10278ms: Time slice expired; preempting process B7 with 10ms remaining [Q A2 B9 B1 A4 A0 A1 B8 A7 B0 B2 A8 A6 B6 A5 A9 B3 A3 B5]
time 10282ms: Process A2 started using the CPU for remaining 696ms of 760ms burst [Q B9 B1 A4 A0 A1 B8 A7 B0 B2 A8 A6 B6 A5 A9 B3 A3 B5 B7]
time 10346ms: Time slice expired; preempting process A2 with 632ms remaining [Q B9 B1 A4 A0 A1 B8 A7 B0 B2 A8 A6 B6 A5 A9 B3 A3 B5 B7]
time 10350ms: Process B9 started using the CPU for 240ms burst [Q B1 A4 A0 A1 B8 A7 B0 B2 A8 A6 B6 A5 A9 B3 A3 B5 B7 A2]
time 10380ms: Process B4 completed I/O; added to ready queue [Q B1 A4 A0 A1 B8 A7 B0 B2 A8 A6 B6 A5 A9 B3 A3 B5 B7 A2 B4]
time 10414ms: Time slice expired; preempting process B9 with 176ms remaining [Q B1 A4 A0 A1 B8 A7 B0 B2 A8 A6 B6 A5 A9 B3 A3 B5 B7 A2 B4]
time 10418ms: Process B1 started using the CPU for remaining 2428ms of 3004ms burst [Q A4 A0 A1 B8 A7 B0 B2 A8 A6 B6 A5 A9 B3 A3 B5 B7 A2 B4 B9]
time 10482ms: Time slice expired; preempting process B1 with 2364ms remaining [Q A4 A0 A1 B8 A7 B0 B2 A8 A6 B6 A5 A9 B3 A3 B5 B7 A2 B4 B9]
time 10486ms: Process A4 started using the CPU for remaining 1056ms of 1248ms burst [Q A0 A1 B8 A7 B0 B2 A8 A6 B6 A5 A9 B3 A3 B5 B7 A2 B4 B9 B1]
time 10550ms: Time slice expired; preempting process A4 with 992ms remaining [Q A0 A1 B8 A7 B0 B2 A8 A6 B6 A5 A9 B3 A3 B5 B7 A2 B4 B9 B1]
time 10554ms: Process A0 started using the CPU for remaining 712ms of 1096ms burst [Q A1 B8 A7 B0 B2 A8 A6 B6 A5 A9 B3 A3 B5 B7 A2 B4 B9 B1 A4]
time 10618ms: Time slice expired; preempting process A0 with 648ms remaining [Q A1 B8 A7 B0 B2 A8 A6 B6 A5 A9 B3 A3 B5 B7 A2 B4 B9 B1 A4]
time 10622ms: Process A1 started using the CPU for 200ms burst [Q B8 A7 B0 B2 A8 A6 B6 A5 A9 B3 A3 B5 B7 A2 B4 B9 B1 A4 A0]
time 10686ms: Time slice expired; preempting process A1 with 136ms remaining [Q B8 A7 B0 B2 A8 A6 B6 A5 A9 B3 A3 B5 B7 A2 B4 B9 B1 A4 A0]
time 10690ms: Process B8 started using the CPU for remaining 11ms of 75ms burst [Q A7 B0 B2 A8 A6 B6 A5 A9 B3 A3 B5 B7 A2 B4 B9 B1 A4 A0 A1]
time 10701ms: Process B8 completed a CPU burst; 17 bursts to go [Q A7 B0 B2 A8 A6 B6 A5 A9 B3 A3 B5 B7 A2 B4 B9 B1 A4 A0 A1]
time 10701ms: Process B8 switching out of CPU; blocking on I/O until time 10967ms [Q A7 B0 B2 A8 A6 B6 A5 A9 B3 A3 B5 B7 A2 B4 B9 B1 A4 A0 A1]
time 10705ms: Process A7 started using the CPU for remaining 256ms of 768ms burst [Q B0 B2 A8 A6 B6 A5 A9 B3 A3 B5 B7 A2 B4 B9 B1 A4 A0 A1]
time 10769ms: Time slice expired; preempting process A7 with 192ms remaining [Q B0 B2 A8 A6 B6 A5 A9 B3 A3 B5 B7 A2 B4 B9 B1 A4 A0 A1]
time 10773ms: Process B0 started using the CPU for remaining 880ms of 1264ms burst [Q B2 A8 A6 B6 A5 A9 B3 A3 B5 B7 A2 B4 B9 B1 A4 A0 A1 A7]
time 10837ms: Time slice expired; preempting process B0 with 816ms remaining [Q B2 A8 A6 B6 A5 A9 B3 A3 B5 B7 A2 B4 B9 B1 A4 A0 A1 A7]
time 10841ms: Process B2 started using the CPU for 123ms burst [Q A8 A6 B6 A5 A9 B3 A3 B5 B7 A2 B4 B9 B1 A4 A0 A1 A7 B0]
time 10905ms: Time slice expired; preempting process B2 with 59ms remaining [Q A8 A6 B6 A5 A9 B3 A3 B5 B7 A2 B4 B9 B1 A4 A0 A1 A7 B0]
time 10909ms: Process A8 started using the CPU for 340ms burst [Q A6 B6 A5 A9 B3 A3 B5 B7 A2 B4 B9 B1 A4 A0 A1 A7 B0 B2]
time 10967ms: Process B8 completed I/O; added to ready queue [Q A6 B6 A5 A9 B3 A3 B5 B7 A2 B4 B9 B1 A4 A0 A1 A7 B0 B2 B8]
time 10973ms: Time slice expired; preempting process A8 with 276ms remaining [Q A6 B6 A5 A9 B3 A3 B5 B7 A2 B4 B9 B1 A4 A0 A1 A7 B0 B2 B8]
time 10977ms: Process A6 started using the CPU for remaining 88ms of 344ms burst [Q B6 A5 A9 B3 A3 B5 B7 A2 B4 B9 B1 A4 A0 A1 A7 B0 B2 B8 A8]
time 11041ms: Time slice expired; preempting process A6 with 24ms remaining [Q B6 A5 A9 B3 A3 B5 B7 A2 B4 B9 B1 A4 A0 A1 A7 B0 B2 B8 A8]
time 11045ms: Process B6 started using the CPU for remaining 171ms of 235ms burst [Q A5 A9 B3 A3 B5 B7 A2 B4 B9 B1 A4 A0 A1 A7 B0 B2 B8 A8 A6]
time 11109ms: Time slice expired; preempting process B6 with 107ms remaining [Q A5 A9 B3 A3 B5 B7 A2 B4 B9 B1 A4 A0 A1 A7 B0 B2 B8 A8 A6]
time 11113ms: Process A5 started using the CPU for remaining 8ms of 200ms burst [Q A9 B3 A3 B5 B7 A2 B4 B9 B1 A4 A0 A1 A7 B0 B2 B8 A8 A6 B6]
time 11121ms: Process A5 completed a CPU burst; 2 bursts to go [Q A9 B3 A3 B5 B7 A2 B4 B9 B1 A4 A0 A1 A7 B0 B2 B8 A8 A6 B6]
time 11121ms: Process A5 switching out of CPU; blocking on I/O until time 11189ms [Q A9 B3 A3 B5 B7 A2 B4 B9 B1 A4 A0 A1 A7 B0 B2 B8 A8 A6 B6]
time 11125ms: Process A9 started using the CPU for remaining 52ms of 308ms burst [Q B3 A3 B5 B7 A2 B4 B9 B1 A4 A0 A1 A7 B0 B2 B8 A8 A6 B6]
time 11177ms: Process A9 completed a CPU burst; 29 bursts to go [Q B3 A3 B5 B7 A2 B4 B9 B1 A4 A0 A1 A7 B0 B2 B8 A8 A6 B6]
time 11177ms: Process A9 switching out of CPU; blocking on I/O until time 11212ms [Q B3 A3 B5 B7 A2 B4 B9 B1 A4 A0 A1 A7 B0 B2 B8 A8 A6 B6]
time 11181ms: Process B3 started using the CPU for remaining 18ms of 82ms burst [Q A3 B5 B7 A2 B4 B9 B1 A4 A0 A1 A7 B0 B2 B8 A8 A6 B6]
time 11189ms: Process A5 completed I/O; added to ready queue [Q A3 B5 B7 A2 B4 B9 B1 A4 A0 A1 A7 B0 B2 B8 A8 A6 B6 A5]
time 11199ms: Process B3 completed a CPU burst; 18 bursts to go [Q A3 B5 B7 A2 B4 B9 B1 A4 A0 A1 A7 B0 B2 B8 A8 A6 B6 A5]
time 11199ms: Process B3 switching out of CPU; blocking on I/O until time 11473ms [Q A3 B5 B7 A2 B4 B9 B1 A4 A0 A1 A7 B0 B2 B8 A8 A6 B6 A5]
time 11203ms: Process A3 started using the CPU for 88ms burst [Q B5 B7 A2 B4 B9 B1 A4 A0 A1 A7 B0 B2 B8 A8 A6 B6 A5]
time 11212ms: Process A9 completed I/O; added to ready queue [Q B5 B7 A2 B4 B9 B1 A4 A0 A1 A7 B0 B2 B8 A8 A6 B6 A5 A9]
time 11267ms: Time slice expired; preempting process A3 with 24ms remaining [Q B5 B7 A2 B4 B9 B1 A4 A0 A1 A7 B0 B2 B8 A8 A6 B6 A5 A9]
time 11271ms: Process B5 started using the CPU for remaining 56ms of 120ms burst [Q B7 A2 B4 B9 B1 A4 A0 A1 A7 B0 B2 B8 A8 A6 B6 A5 A9 A3]
time 11327ms: Process B5 completed a CPU burst; 23 bursts to go [Q B7 A2 B4 B9 B1 A4 A0 A1 A7 B0 B2 B8 A8 A6 B6 A5 A9 A3]
time 11327ms: Process B5 switching out of CPU; blocking on I/O until time 11969ms [Q B7 A2 B4 B9 B1 A4 A0 A1 A7 B0 B2 B8 A8 A6 B6 A5 A9 A3]
time 11331ms: Process B7 started using the CPU for remaining 10ms of 74ms burst [Q A2 B4 B9 B1 A4 A0 A1 A7 B0 B2 B8 A8 A6 B6 A5 A9 A3]
time 11341ms: Process B7 completed a CPU burst; 22 bursts to go [Q A2 B4 B9 B1 A4 A0 A1 A7 B0 B2 B8 A8 A6 B6 A5 A9 A3]
time 11341ms: Process B7 switching out of CPU; blocking on I/O until time 15055ms [Q A2 B4 B9 B1 A4 A0 A1 A7 B0 B2 B8 A8 A6 B6 A5 A9 A3]
time 11345ms: Process A2 started using the CPU for remaining 632ms of 760ms burst [Q B4 B9 B1 A4 A0 A1 A7 B0 B2 B8 A8 A6 B6 A5 A9 A3]
time 11409ms: Time slice expired; preempting process A2 with 568ms remaining [Q B4 B9 B1 A4 A0 A1 A7 B0 B2 B8 A8 A6 B6 A5 A9 A3]
time 11413ms: Process B4 started using the CPU for 39ms burst [Q B9 B1 A4 A0 A1 A7 B0 B2 B8 A8 A6 B6 A5 A9 A3 A2]
time 11452ms: Process B4 completed a CPU burst; 11 bursts to go [Q B9 B1 A4 A0 A1 A7 B0 B2 B8 A8 A6 B6 A5 A9 A3 A2]
time 11452ms: Process B4 switching out of CPU; blocking on I/O until time 11542ms [Q B9 B1 A4 A0 A1 A7 B0 B2 B8 A8 A6 B6 A5 A9 A3 A2]
time 11456ms: Process B9 started using the CPU for remaining 176ms of 240ms burst [Q B1 A4 A0 A1 A7 B0 B2 B8 A8 A6 B6 A5 A9 A3 A2]
time 11473ms: Process B3 completed I/O; added to ready queue [Q B1 A4 A0 A1 A7 B0 B2 B8 A8 A6 B6 A5 A9 A3 A2 B3]
time 11520ms: Time slice expired; preempting process B9 with 112ms remaining [Q B1 A4 A0 A1 A7 B0 B2 B8 A8 A6 B6 A5 A9 A3 A2 B3]
time 11524ms: Process B1 started using the CPU for remaining 2364ms of 3004ms burst [Q A4 A0 A1 A7 B0 B2 B8 A8 A6 B6 A5 A9 A3 A2 B3 B9]
time 11542ms: Process B4 completed I/O; added to ready queue [Q A4 A0 A1 A7 B0 B2 B8 A8 A6 B6 A5 A9 A3 A2 B3 B9 B4]
time 11588ms: Time slice expired; preempting process B1 with 2300ms remaining [Q A4 A0 A1 A7 B0 B2 B8 A8 A6 B6 A5 A9 A3 A2 B3 B9 B4]
time 11592ms: Process A4 started using the CPU for remaining 992ms of 1248ms burst [Q A0 A1 A7 B0 B2 B8 A8 A6 B6 A5 A9 A3 A2 B3 B9 B4 B1]
time 11656ms: Time slice expired; preempting process A4 with 928ms remaining [Q A0 A1 A7 B0 B2 B8 A8 A6 B6 A5 A9 A3 A2 B3 B9 B4 B1]
time 11660ms: Process A0 started using the CPU for remaining 648ms of 1096ms burst [Q A1 A7 B0 B2 B8 A8 A6 B6 A5 A9 A3 A2 B3 B9 B4 B1 A4]
time 11724ms: Time slice expired; preempting process A0 with 584ms remaining [Q A1 A7 B0 B2 B8 A8 A6 B6 A5 A9 A3 A2 B3 B9 B4 B1 A4]
time 11728ms: Process A1 started using the CPU for remaining 136ms of 200ms burst [Q A7 B0 B2 B8 A8 A6 B6 A5 A9 A3 A2 B3 B9 B4 B1 A4 A0]
time 11792ms: Time slice expired; preempting process A1 with 72ms remaining [Q A7 B0 B2 B8 A8 A6 B6 A5 A9 A3 A2 B3 B9 B4 B1 A4 A0]
time 11796ms: Process A7 started using the CPU for remaining 192ms of 768ms burst [Q B0 B2 B8 A8 A6 B6 A5 A9 A3 A2 B3 B9 B4 B1 A4 A0 A1]
time 11860ms: Time slice expired; preempting process A7 with 128ms remaining [Q B0 B2 B8 A8 A6 B6 A5 A9 A3 A2 B3 B9 B4 B1 A4 A0 A1]
time 11864ms: Process B0 started using the CPU for remaining 816ms of 1264ms burst [Q B2 B8 A8 A6 B6 A5 A9 A3 A2 B3 B9 B4 B1 A4 A0 A1 A7]
time 11928ms: Time slice expired; preempting process B0 with 752ms remaining [Q B2 B8 A8 A6 B6 A5 A9 A3 A2 B3 B9 B4 B1 A4 A0 A1 A7]
time 11932ms: Process B2 started using the CPU for remaining 59ms of 123ms burst [Q B8 A8 A6 B6 A5 A9 A3 A2 B3 B9 B4 B1 A4 A0 A1 A7 B0]
time 11969ms: Process B5 completed I/O; added to ready queue [Q B8 A8 A6 B6 A5 A9 A3 A2 B3 B9 B4 B1 A4 A0 A1 A7 B0 B5]
time 11991ms: Process B2 completed a CPU burst; 11 bursts to go [Q B8 A8 A6 B6 A5 A9 A3 A2 B3 B9 B4 B1 A4 A0 A1 A7 B0 B5]
time 11991ms: Process B2 switching out of CPU; blocking on I/O until time 12065ms [Q B8 A8 A6 B6 A5 A9 A3 A2 B3 B9 B4 B1 A4 A0 A1 A7 B0 B5]
time 11995ms: Process B8 started using the CPU for 44ms burst [Q A8 A6 B6 A5 A9 A3 A2 B3 B9 B4 B1 A4 A0 A1 A7 B0 B5]
time 12039ms: Process B8 completed a CPU burst; 16 bursts to go [Q A8 A6 B6 A5 A9 A3 A2 B3 B9 B4 B1 A4 A0 A1 A7 B0 B5]
time 12039ms: Process B8 switching out of CPU; blocking on I/O until time 14809ms [Q A8 A6 B6 A5 A9 A3 A2 B3 B9 B4 B1 A4 A0 A1 A7 B0 B5]
time 12043ms: Process A8 started using the CPU for remaining 276ms of 340ms burst [Q A6 B6 A5 A9 A3 A2 B3 B9 B4 B1 A4 A0 A1 A7 B0 B5]
time 12065ms: Process B2 completed I/O; added to ready queue [Q A6 B6 A5 A9 A3 A2 B3 B9 B4 B1 A4 A0 A1 A7 B0 B5 B2]
time 12107ms: Time slice expired; preempting process A8 with 212ms remaining [Q A6 B6 A5 A9 A3 A2 B3 B9 B4 B1 A4 A0 A1 A7 B0 B5 B2]
time 12111ms: Process A6 started using the CPU for remaining 24ms of 344ms burst [Q B6 A5 A9 A3 A2 B3 B9 B4 B1 A4 A0 A1 A7 B0 B5 B2 A8]
time 12135ms: Process A6 completed a CPU burst; 15 bursts to go [Q B6 A5 A9 A3 A2 B3 B9 B4 B1 A4 A0 A1 A7 B0 B5 B2 A8]
time 12135ms: Process A6 switching out of CPU; blocking on I/O until time 12178ms [Q B6 A5 A9 A3 A2 B3 B9 B4 B1 A4 A0 A1 A7 B0 B5 B2 A8]
time 12139ms: Process B6 started using the CPU for remaining 107ms of 235ms burst [Q A5 A9 A3 A2 B3 B9 B4 B1 A4 A0 A1 A7 B0 B5 B2 A8]
time 12178ms: Process A6 completed I/O; added to ready queue [Q A5 A9 A3 A2 B3 B9 B4 B1 A4 A0 A1 A7 B0 B5 B2 A8 A6]
time 12203ms: Time slice expired; preempting process B6 with 43ms remaining [Q A5 A9 A3 A2 B3 B9 B4 B1 A4 A0 A1 A7 B0 B5 B2 A8 A6]
time 12207ms: Process A5 started using the CPU for 60ms burst [Q A9 A3 A2 B3 B9 B4 B1 A4 A0 A1 A7 B0 B5 B2 A8 A6 B6]
time 12267ms: Process A5 completed a CPU burst; 1 burst to go [Q A9 A3 A2 B3 B9 B4 B1 A4 A0 A1 A7 B0 B5 B2 A8 A6 B6]
time 12267ms: Process A5 switching out of CPU; blocking on I/O until time 12375ms [Q A9 A3 A2 B3 B9 B4 B1 A4 A0 A1 A7 B0 B5 B2 A8 A6 B6]
time 12271ms: Process A9 started using the CPU for 16ms burst [Q A3 A2 B3 B9 B4 B1 A4 A0 A1 A7 B0 B5 B2 A8 A6 B6]
time 12287ms: Process A9 completed a CPU burst; 28 bursts to go [Q A3 A2 B3 B9 B4 B1 A4 A0 A1 A7 B0 B5 B2 A8 A6 B6]
time 12287ms: Process A9 switching out of CPU; blocking on I/O until time 12303ms [Q A3 A2 B3 B9 B4 B1 A4 A0 A1 A7 B0 B5 B2 A8 A6 B6]
time 12291ms: Process A3 started using the CPU for remaining 24ms of 88ms burst [Q A2 B3 B9 B4 B1 A4 A0 A1 A7 B0 B5 B2 A8 A6 B6]
time 12303ms: Process A9 completed I/O; added to ready queue [Q A2 B3 B9 B4 B1 A4 A0 A1 A7 B0 B5 B2 A8 A6 B6 A9]
time 12315ms: Process A3 completed a CPU burst; 21 bursts to go [Q A2 B3 B9 B4 B1 A4 A0 A1 A7 B0 B5 B2 A8 A6 B6 A9]
time 12315ms: Process A3 switching out of CPU; blocking on I/O until time 12380ms [Q A2 B3 B9 B4 B1 A4 A0 A1 A7 B0 B5 B2 A8 A6 B6 A9]
time 12319ms: Process A2 started using the CPU for remaining 568ms of 760ms burst [Q B3 B9 B4 B1 A4 A0 A1 A7 B0 B5 B2 A8 A6 B6 A9]
time 12375ms: Process A5 completed I/O; added to ready queue [Q B3 B9 B4 B1 A4 A0 A1 A7 B0 B5 B2 A8 A6 B6 A9 A5]
time 12380ms: Process A3 completed I/O; added to ready queue [Q B3 B9 B4 B1 A4 A0 A1 A7 B0 B5 B2 A8 A6 B6 A9 A5 A3]
time 12383ms: Time slice expired; preempting process A2 with 504ms remaining [Q B3 B9 B4 B1 A4 A0 A1 A7 B0 B5 B2 A8 A6 B6 A9 A5 A3]
time 12387ms: Process B3 started using the CPU for 125ms burst [Q B9 B4 B1 A4 A0 A1 A7 B0 B5 B2 A8 A6 B6 A9 A5 A3 A2]
time 12451ms: Time slice expired; preempting process B3 with 61ms remaining [Q B9 B4 B1 A4 A0 A1 A7 B0 B5 B2 A8 A6 B6 A9 A5 A3 A2]
time 12455ms: Process B9 started using the CPU for remaining 112ms of 240ms burst [Q B4 B1 A4 A0 A1 A7 B0 B5 B2 A8 A6 B6 A9 A5 A3 A2 B3]
time 12519ms: Time slice expired; preempting process B9 with 48ms remaining [Q B4 B1 A4 A0 A1 A7 B0 B5 B2 A8 A6 B6 A9 A5 A3 A2 B3]
time 12523ms: Process B4 started using the CPU for 205ms burst [Q B1 A4 A0 A1 A7 B0 B5 B2 A8 A6 B6 A9 A5 A3 A2 B3 B9]
time 12587ms: Time slice expired; preempting process B4 with 141ms remaining [Q B1 A4 A0 A1 A7 B0 B5 B2 A8 A6 B6 A9 A5 A3 A2 B3 B9]
time 12591ms: Process B1 started using the CPU for remaining 2300ms of 3004ms burst [Q A4 A0 A1 A7 B0 B5 B2 A8 A6 B6 A9 A5 A3 A2 B3 B9 B4]
time 12655ms: Time slice expired; preempting process B1 with 2236ms remaining [Q A4 A0 A1 A7 B0 B5 B2 A8 A6 B6 A9 A5 A3 A2 B3 B9 B4]
time 12659ms: Process A4 started using the CPU for remaining 928ms of 1248ms burst [Q A0 A1 A7 B0 B5 B2 A8 A6 B6 A9 A5 A3 A2 B3 B9 B4 B1]
time 12723ms: Time slice expired; preempting process A4 with 864ms remaining [Q A0 A1 A7 B0 B5 B2 A8 A6 B6 A9 A5 A3 A2 B3 B9 B4 B1]
time 12727ms: Process A0 started using the CPU for remaining 584ms of 1096ms burst [Q A1 A7 B0 B5 B2 A8 A6 B6 A9 A5 A3 A2 B3 B9 B4 B1 A4]
time 12791ms: Time slice expired; preempting process A0 with 520ms remaining [Q A1 A7 B0 B5 B2 A8 A6 B6 A9 A5 A3 A2 B3 B9 B4 B1 A4]
time 12795ms: Process A1 started using the CPU for remaining 72ms of 200ms burst [Q A7 B0 B5 B2 A8 A6 B6 A9 A5 A3 A2 B3 B9 B4 B1 A4 A0]
time 12859ms: Time slice expired; preempting process A1 with 8ms remaining [Q A7 B0 B5 B2 A8 A6 B6 A9 A5 A3 A2 B3 B9 B4 B1 A4 A0]
time 12863ms: Process A7 started using the CPU for remaining 128ms of 768ms burst [Q B0 B5 B2 A8 A6 B6 A9 A5 A3 A2 B3 B9 B4 B1 A4 A0 A1]
time 12927ms: Time slice expired; preempting process A7 with 64ms remaining [Q B0 B5 B2 A8 A6 B6 A9 A5 A3 A2 B3 B9 B4 B1 A4 A0 A1]
time 12931ms: Process B0 started using the CPU for remaining 752ms of 1264ms burst [Q B5 B2 A8 A6 B6 A9 A5 A3 A2 B3 B9 B4 B1 A4 A0 A1 A7]
time 12995ms: Time slice expired; preempting process B0 with 688ms remaining [Q B5 B2 A8 A6 B6 A9 A5 A3 A2 B3 B9 B4 B1 A4 A0 A1 A7]
time 12999ms: Process B5 started using the CPU for 72ms burst [Q B2 A8 A6 B6 A9 A5 A3 A2 B3 B9 B4 B1 A4 A0 A1 A7 B0]
time 13063ms: Time slice expired; preempting process B5 with 8ms remaining [Q B2 A8 A6 B6 A9 A5 A3 A2 B3 B9 B4 B1 A4 A0 A1 A7 B0]
time 13067ms: Process B2 started using the CPU for 7ms burst [Q A8 A6 B6 A9 A5 A3 A2 B3 B9 B4 B1 A4 A0 A1 A7 B0 B5]
time 13074ms: Process B2 completed a CPU burst; 10 bursts to go [Q A8 A6 B6 A9 A5 A3 A2 B3 B9 B4 B1 A4 A0 A1 A7 B0 B5]
time 13074ms: Process B2 switching out of CPU; blocking on I/O until time 13124ms [Q A8 A6 B6 A9 A5 A3 A2 B3 B9 B4 B1 A4 A0 A1 A7 B0 B5]
time 13078ms: Process A8 started using the CPU for remaining 212ms of 340ms burst [Q A6 B6 A9 A5 A3 A2 B3 B9 B4 B1 A4 A0 A1 A7 B0 B5]
time 13124ms: Process B2 completed I/O; added to ready queue [Q A6 B6 A9 A5 A3 A2 B3 B9 B4 B1 A4 A0 A1 A7 B0 B5 B2]
time 13142ms: Time slice expired; preempting process A8 with 148ms remaining [Q A6 B6 A9 A5 A3 A2 B3 B9 B4 B1 A4 A0 A1 A7 B0 B5 B2]
time 13146ms: Process A6 started using the CPU for 756ms burst [Q B6 A9 A5 A3 A2 B3 B9 B4 B1 A4 A0 A1 A7 B0 B5 B2 A8]
time 13210ms: Time slice expired; preempting process A6 with 692ms remaining [Q B6 A9 A5 A3 A2 B3 B9 B4 B1 A4 A0 A1 A7 B0 B5 B2 A8]
time 13214ms: Process B6 started using the CPU for remaining 43ms of 235ms burst [Q A9 A5 A3 A2 B3 B9 B4 B1 A4 A0 A1 A7 B0 B5 B2 A8 A6]
time 13257ms: Process B6 completed a CPU burst; 2 bursts to go [Q A9 A5 A3 A2 B3 B9 B4 B1 A4 A0 A1 A7 B0 B5 B2 A8 A6]
time 13257ms: Process B6 switching out of CPU; blocking on I/O until time 14219ms [Q A9 A5 A3 A2 B3 B9 B4 B1 A4 A0 A1 A7 B0 B5 B2 A8 A6]
time 13261ms: Process A9 started using the CPU for 644ms burst [Q A5 A3 A2 B3 B9 B4 B1 A4 A0 A1 A7 B0 B5 B2 A8 A6]
time 13325ms: Time slice expired; preempting process A9 with 580ms remaining [Q A5 A3 A2 B3 B9 B4 B1 A4 A0 A1 A7 B0 B5 B2 A8 A6]
time 13329ms: Process A5 started using the CPU for 912ms burst [Q A3 A2 B3 B9 B4 B1 A4 A0 A1 A7 B0 B5 B2 A8 A6 A9]
time 13393ms: Time slice expired; preempting process A5 with 848ms remaining [Q A3 A2 B3 B9 B4 B1 A4 A0 A1 A7 B0 B5 B2 A8 A6 A9]
time 13397ms: Process A3 started using the CPU for 116ms burst [Q A2 B3 B9 B4 B1 A4 A0 A1 A7 B0 B5 B2 A8 A6 A9 A5]
time 13461ms: Time slice expired; preempting process A3 with 52ms remaining [Q A2 B3 B9 B4 B1 A4 A0 A1 A7 B0 B5 B2 A8 A6 A9 A5]
time 13465ms: Process A2 started using the CPU for remaining 504ms of 760ms burst [Q B3 B9 B4 B1 A4 A0 A1 A7 B0 B5 B2 A8 A6 A9 A5 A3]
time 13529ms: Time slice expired; preempting process A2 with 440ms remaining [Q B3 B9 B4 B1 A4 A0 A1 A7 B0 B5 B2 A8 A6 A9 A5 A3]
time 13533ms: Process B3 started using the CPU for remaining 61ms of 125ms burst [Q B9 B4 B1 A4 A0 A1 A7 B0 B5 B2 A8 A6 A9 A5 A3 A2]
time 13594ms: Process B3 completed a CPU burst; 17 bursts to go [Q B9 B4 B1 A4 A0 A1 A7 B0 B5 B2 A8 A6 A9 A5 A3 A2]
time 13594ms: Process B3 switching out of CPU; blocking on I/O until time 14396ms [Q B9 B4 B1 A4 A0 A1 A7 B0 B5 B2 A8 A6 A9 A5 A3 A2]
time 13598ms: Process B9 started using the CPU for remaining 48ms of 240ms burst [Q B4 B1 A4 A0 A1 A7 B0 B5 B2 A8 A6 A9 A5 A3 A2]
time 13646ms: Process B9 completed a CPU burst; 6 bursts to go [Q B4 B1 A4 A0 A1 A7 B0 B5 B2 A8 A6 A9 A5 A3 A2]
time 13646ms: Process B9 switching out of CPU; blocking on I/O until time 14032ms [Q B4 B1 A4 A0 A1 A7 B0 B5 B2 A8 A6 A9 A5 A3 A2]
time 13650ms: Process B4 started using the CPU for remaining 141ms of 205ms burst [Q B1 A4 A0 A1 A7 B0 B5 B2 A8 A6 A9 A5 A3 A2]
time 13714ms: Time slice expired; preempting process B4 with 77ms remaining [Q B1 A4 A0 A1 A7 B0 B5 B2 A8 A6 A9 A5 A3 A2]
time 13718ms: Process B1 started using the CPU for remaining 2236ms of 3004ms burst [Q A4 A0 A1 A7 B0 B5 B2 A8 A6 A9 A5 A3 A2 B4]
time 13782ms: Time slice expired; preempting process B1 with 2172ms remaining [Q A4 A0 A1 A7 B0 B5 B2 A8 A6 A9 A5 A3 A2 B4]
time 13786ms: Process A4 started using the CPU for remaining 864ms of 1248ms burst [Q A0 A1 A7 B0 B5 B2 A8 A6 A9 A5 A3 A2 B4 B1]
time 13850ms: Time slice expired; preempting process A4 with 800ms remaining [Q A0 A1 A7 B0 B5 B2 A8 A6 A9 A5 A3 A2 B4 B1]
time 13854ms: Process A0 started using the CPU for remaining 520ms of 1096ms burst [Q A1 A7 B0 B5 B2 A8 A6 A9 A5 A3 A2 B4 B1 A4]
time 13918ms: Time slice expired; preempting process A0 with 456ms remaining [Q A1 A7 B0 B5 B2 A8 A6 A9 A5 A3 A2 B4 B1 A4]
time 13922ms: Process A1 started using the CPU for remaining 8ms of 200ms burst [Q A7 B0 B5 B2 A8 A6 A9 A5 A3 A2 B4 B1 A4 A0]
time 13930ms: Process A1 completed a CPU burst; 10 bursts to go [Q A7 B0 B5 B2 A8 A6 A9 A5 A3 A2 B4 B1 A4 A0]
time 13930ms: Process A1 switching out of CPU; blocking on I/O until time 13964ms [Q A7 B0 B5 B2 A8 A6 A9 A5 A3 A2 B4 B1 A4 A0]
time 13934ms: Process A7 started using the CPU for remaining 64ms of 768ms burst [Q B0 B5 B2 A8 A6 A9 A5 A3 A2 B4 B1 A4 A0]
time 13964ms: Process A1 completed I/O; added to ready queue [Q B0 B5 B2 A8 A6 A9 A5 A3 A2 B4 B1 A4 A0 A1]
time 13998ms: Process A7 completed a CPU burst; 17 bursts to go [Q B0 B5 B2 A8 A6 A9 A5 A3 A2 B4 B1 A4 A0 A1]
time 13998ms: Process A7 switching out of CPU; blocking on I/O until time 14121ms [Q B0 B5 B2 A8 A6 A9 A5 A3 A2 B4 B1 A4 A0 A1]
time 14002ms: Process B0 started using the CPU for remaining 688ms of 1264ms burst [Q B5 B2 A8 A6 A9 A5 A3 A2 B4 B1 A4 A0 A1]
time 14032ms: Process B9 completed I/O; added to ready queue [Q B5 B2 A8 A6 A9 A5 A3 A2 B4 B1 A4 A0 A1 B9]
time 14066ms: Time slice expired; preempting process B0 with 624ms remaining [Q B5 B2 A8 A6 A9 A5 A3 A2 B4 B1 A4 A0 A1 B9]
time 14070ms: Process B5 started using the CPU for remaining 8ms of 72ms burst [Q B2 A8 A6 A9 A5 A3 A2 B4 B1 A4 A0 A1 B9 B0]
time 14078ms: Process B5 completed a CPU burst; 22 bursts to go [Q B2 A8 A6 A9 A5 A3 A2 B4 B1 A4 A0 A1 B9 B0]
time 14078ms: Process B5 switching out of CPU; blocking on I/O until time 14392ms [Q B2 A8 A6 A9 A5 A3 A2 B4 B1 A4 A0 A1 B9 B0]
time 14082ms: Process B2 started using the CPU for 12ms burst [Q A8 A6 A9 A5 A3 A2 B4 B1 A4 A0 A1 B9 B0]
time 14094ms: Process B2 completed a CPU burst; 9 bursts to go [Q A8 A6 A9 A5 A3 A2 B4 B1 A4 A0 A1 B9 B0]
time 14094ms: Process B2 switching out of CPU; blocking on I/O until time 14448ms [Q A8 A6 A9 A5 A3 A2 B4 B1 A4 A0 A1 B9 B0]
time 14098ms: Process A8 started using the CPU for remaining 148ms of 340ms burst [Q A6 A9 A5 A3 A2 B4 B1 A4 A0 A1 B9 B0]
time 14121ms: Process A7 completed I/O; added to ready queue [Q A6 A9 A5 A3 A2 B4 B1 A4 A0 A1 B9 B0 A7]
time 14162ms: Time slice expired; preempting process A8 with 84ms remaining [Q A6 A9 A5 A3 A2 B4 B1 A4 A0 A1 B9 B0 A7]
time 14166ms: Process A6 started using the CPU for remaining 692ms of 756ms burst [Q A9 A5 A3 A2 B4 B1 A4 A0 A1 B9 B0 A7 A8]
time 14219ms: Process B6 completed I/O; added to ready queue [Q A9 A5 A3 A2 B4 B1 A4 A0 A1 B9 B0 A7 A8 B6]
time 14230ms: Time slice expired; preempting process A6 with 628ms remaining [Q A9 A5 A3 A2 B4 B1 A4 A0 A1 B9 B0 A7 A8 B6]
time 14234ms: Process A9 started using the CPU for remaining 580ms of 644ms burst [Q A5 A3 A2 B4 B1 A4 A0 A1 B9 B0 A7 A8 B6 A6]
time 14298ms: Time slice expired; preempting process A9 with 516ms remaining [Q A5 A3 A2 B4 B1 A4 A0 A1 B9 B0 A7 A8 B6 A6]
time 14302ms: Process A5 started using the CPU for remaining 848ms of 912ms burst [Q A3 A2 B4 B1 A4 A0 A1 B9 B0 A7 A8 B6 A6 A9]
time 14366ms: Time slice expired; preempting process A5 with 784ms remaining [Q A3 A2 B4 B1 A4 A0 A1 B9 B0 A7 A8 B6 A6 A9]
time 14370ms: Process A3 started using the CPU for remaining 52ms of 116ms burst [Q A2 B4 B1 A4 A0 A1 B9 B0 A7 A8 B6 A6 A9 A5]
time 14392ms: Process B5 completed I/O; added to ready queue [Q A2 B4 B1 A4 A0 A1 B9 B0 A7 A8 B6 A6 A9 A5 B5]
time 14396ms: Process B3 completed I/O; added to ready queue [Q A2 B4 B1 A4 A0 A1 B9 B0 A7 A8 B6 A6 A9 A5 B5 B3]
time 14422ms: Process A3 completed a CPU burst; 20 bursts to go [Q A2 B4 B1 A4 A0 A1 B9 B0 A7 A8 B6 A6 A9 A5 B5 B3]
time 14422ms: Process A3 switching out of CPU; blocking on I/O until time 14478ms [Q A2 B4 B1 A4 A0 A1 B9 B0 A7 A8 B6 A6 A9 A5 B5 B3]
time 14426ms: Process A2 started using the CPU for remaining 440ms of 760ms burst [Q B4 B1 A4 A0 A1 B9 B0 A7 A8 B6 A6 A9 A5 B5 B3]
time 14448ms: Process B2 completed I/O; added to ready queue [Q B4 B1 A4 A0 A1 B9 B0 A7 A8 B6 A6 A9 A5 B5 B3 B2]
time 14478ms: Process A3 completed I/O; added to ready queue [Q B4 B1 A4 A0 A1 B9 B0 A7 A8 B6 A6 A9 A5 B5 B3 B2 A3]
time 14490ms: Time slice expired; preempting process A2 with 376ms remaining [Q B4 B1 A4 A0 A1 B9 B0 A7 A8 B6 A6 A9 A5 B5 B3 B2 A3]
time 14494ms: Process B4 started using the CPU for remaining 77ms of 205ms burst [Q B1 A4 A0 A1 B9 B0 A7 A8 B6 A6 A9 A5 B5 B3 B2 A3 A2]
time 14558ms: Time slice expired; preempting process B4 with 13ms remaining [Q B1 A4 A0 A1 B9 B0 A7 A8 B6 A6 A9 A5 B5 B3 B2 A3 A2]
time 14562ms: Process B1 started using the CPU for remaining 2172ms of 3004ms burst [Q A4 A0 A1 B9 B0 A7 A8 B6 A6 A9 A5 B5 B3 B2 A3 A2 B4]
time 14626ms: Time slice expired; preempting process B1 with 2108ms remaining [Q A4 A0 A1 B9 B0 A7 A8 B6 A6 A9 A5 B5 B3 B2 A3 A2 B4]
time 14630ms: Process A4 started using the CPU for remaining 800ms of 1248ms burst [Q A0 A1 B9 B0 A7 A8 B6 A6 A9 A5 B5 B3 B2 A3 A2 B4 B1]
time 14694ms: Time slice expired; preempting process A4 with 736ms remaining [Q A0 A1 B9 B0 A7 A8 B6 A6 A9 A5 B5 B3 B2 A3 A2 B4 B1]
time 14698ms: Process A0 started using the CPU for remaining 456ms of 1096ms burst [Q A1 B9 B0 A7 A8 B6 A6 A9 A5 B5 B3 B2 A3 A2 B4 B1 A4]
time 14762ms: Time slice expired; preempting process A0 with 392ms remaining [Q A1 B9 B0 A7 A8 B6 A6 A9 A5 B5 B3 B2 A3 A2 B4 B1 A4]
time 14766ms: Process A1 started using the CPU for 608ms burst [Q B9 B0 A7 A8 B6 A6 A9 A5 B5 B3 B2 A3 A2 B4 B1 A4 A0]
time 14809ms: Process B8 completed I/O; added to ready queue [Q B9 B0 A7 A8 B6 A6 A9 A5 B5 B3 B2 A3 A2 B4 B1 A4 A0 B8]
time 14830ms: Time slice expired; preempting process A1 with 544ms remaining [Q B9 B0 A7 A8 B6 A6 A9 A5 B5 B3 B2 A3 A2 B4 B1 A4 A0 B8]
time 14834ms: Process B9 started using the CPU for 23ms burst [Q B0 A7 A8 B6 A6 A9 A5 B5 B3 B2 A3 A2 B4 B1 A4 A0 B8 A1]
time 14857ms: Process B9 completed a CPU burst; 5 bursts to go [Q B0 A7 A8 B6 A6 A9 A5 B5 B3 B2 A3 A2 B4 B1 A4 A0 B8 A1]
time 14857ms: Process B9 switching out of CPU; blocking on I/O until time 14987ms [Q B0 A7 A8 B6 A6 A9 A5 B5 B3 B2 A3 A2 B4 B1 A4 A0 B8 A1]
time 14861ms: Process B0 started using the CPU for remaining 624ms of 1264ms burst [Q A7 A8 B6 A6 A9 A5 B5 B3 B2 A3 A2 B4 B1 A4 A0 B8 A1]
time 14925ms: Time slice expired; preempting process B0 with 560ms remaining [Q A7 A8 B6 A6 A9 A5 B5 B3 B2 A3 A2 B4 B1 A4 A0 B8 A1]
time 14929ms: Process A7 started using the CPU for 1388ms burst [Q A8 B6 A6 A9 A5 B5 B3 B2 A3 A2 B4 B1 A4 A0 B8 A1 B0]
time 14987ms: Process B9 completed I/O; added to ready queue [Q A8 B6 A6 A9 A5 B5 B3 B2 A3 A2 B4 B1 A4 A0 B8 A1 B0 B9]
time 14993ms: Time slice expired; preempting process A7 with 1324ms remaining [Q A8 B6 A6 A9 A5 B5 B3 B2 A3 A2 B4 B1 A4 A0 B8 A1 B0 B9]
time 14997ms: Process A8 started using the CPU for remaining 84ms of 340ms burst [Q B6 A6 A9 A5 B5 B3 B2 A3 A2 B4 B1 A4 A0 B8 A1 B0 B9 A7]
time 15055ms: Process B7 completed I/O; added to ready queue [Q B6 A6 A9 A5 B5 B3 B2 A3 A2 B4 B1 A4 A0 B8 A1 B0 B9 A7 B7]
time 15061ms: Time slice expired; preempting process A8 with 20ms remaining [Q B6 A6 A9 A5 B5 B3 B2 A3 A2 B4 B1 A4 A0 B8 A1 B0 B9 A7 B7]
time 15065ms: Process B6 started using the CPU for 10ms burst [Q A6 A9 A5 B5 B3 B2 A3 A2 B4 B1 A4 A0 B8 A1 B0 B9 A7 B7 A8]
time 15075ms: Process B6 completed a CPU burst; 1 burst to go [Q A6 A9 A5 B5 B3 B2 A3 A2 B4 B1 A4 A0 B8 A1 B0 B9 A7 B7 A8]
time 15075ms: Process B6 switching out of CPU; blocking on I/O until time 15541ms [Q A6 A9 A5 B5 B3 B2 A3 A2 B4 B1 A4 A0 B8 A1 B0 B9 A7 B7 A8]
time 15079ms: Process A6 started using the CPU for remaining 628ms of 756ms burst [Q A9 A5 B5 B3 B2 A3 A2 B4 B1 A4 A0 B8 A1 B0 B9 A7 B7 A8]
time 15143ms: Time slice expired; preempting process A6 with 564ms remaining [Q A9 A5 B5 B3 B2 A3 A2 B4 B1 A4 A0 B8 A1 B0 B9 A7 B7 A8]
time 15147ms: Process A9 started using the CPU for remaining 516ms of 644ms burst [Q A5 B5 B3 B2 A3 A2 B4 B1 A4 A0 B8 A1 B0 B9 A7 B7 A8 A6]
time 15211ms: Time slice expired; preempting process A9 with 452ms remaining [Q A5 B5 B3 B2 A3 A2 B4 B1 A4 A0 B8 A1 B0 B9 A7 B7 A8 A6]
time 15215ms: Process A5 started using the CPU for remaining 784ms of 912ms burst [Q B5 B3 B2 A3 A2 B4 B1 A4 A0 B8 A1 B0 B9 A7 B7 A8 A6 A9]
time 15279ms: Time slice expired; preempting process A5 with 720ms remaining [Q B5 B3 B2 A3 A2 B4 B1 A4 A0 B8 A1 B0 B9 A7 B7 A8 A6 A9]
time 15283ms: Process B5 started using the CPU for 194ms burst [Q B3 B2 A3 A2 B4 B1 A4 A0 B8 A1 B0 B9 A7 B7 A8 A6 A9 A5]
time 15347ms: Time slice expired; preempting process B5 with 130ms remaining [Q B3 B2 A3 A2 B4 B1 A4 A0 B8 A1 B0 B9 A7 B7 A8 A6 A9 A5]
time 15351ms: Process B3 started using the CPU for 31ms burst [Q B2 A3 A2 B4 B1 A4 A0 B8 A1 B0 B9 A7 B7 A8 A6 A9 A5 B5]
time 15382ms: Process B3 completed a CPU burst; 16 bursts to go [Q B2 A3 A2 B4 B1 A4 A0 B8 A1 B0 B9 A7 B7 A8 A6 A9 A5 B5]
time 15382ms: Process B3 switching out of CPU; blocking on I/O until time 18536ms [Q B2 A3 A2 B4 B1 A4 A0 B8 A1 B0 B9 A7 B7 A8 A6 A9 A5 B5]
time 15386ms: Process B2 started using the CPU for 142ms burst [Q A3 A2 B4 B1 A4 A0 B8 A1 B0 B9 A7 B7 A8 A6 A9 A5 B5]
time 15450ms: Time slice expired; preempting process B2 with 78ms remaining [Q A3 A2 B4 B1 A4 A0 B8 A1 B0 B9 A7 B7 A8 A6 A9 A5 B5]
time 15454ms: Process A3 started using the CPU for 580ms burst [Q A2 B4 B1 A4 A0 B8 A1 B0 B9 A7 B7 A8 A6 A9 A5 B5 B2]
time 15518ms: Time slice expired; preempting process A3 with 516ms remaining [Q A2 B4 B1 A4 A0 B8 A1 B0 B9 A7 B7 A8 A6 A9 A5 B5 B2]
time 15522ms: Process A2 started using the CPU for remaining 376ms of 760ms burst [Q B4 B1 A4 A0 B8 A1 B0 B9 A7 B7 A8 A6 A9 A5 B5 B2 A3]
time 15541ms: Process B6 completed I/O; added to ready queue [Q B4 B1 A4 A0 B8 A1 B0 B9 A7 B7 A8 A6 A9 A5 B5 B2 A3 B6]
time 15586ms: Time slice expired; preempting process A2 with 312ms remaining [Q B4 B1 A4 A0 B8 A1 B0 B9 A7 B7 A8 A6 A9 A5 B5 B2 A3 B6]
time 15590ms: Process B4 started using the CPU for remaining 13ms of 205ms burst [Q B1 A4 A0 B8 A1 B0 B9 A7 B7 A8 A6 A9 A5 B5 B2 A3 B6 A2]
time 15603ms: Process B4 completed a CPU burst; 10 bursts to go [Q B1 A4 A0 B8 A1 B0 B9 A7 B7 A8 A6 A9 A5 B5 B2 A3 B6 A2]
time 15603ms: Process B4 switching out of CPU; blocking on I/O until time 16189ms [Q B1 A4 A0 B8 A1 B0 B9 A7 B7 A8 A6 A9 A5 B5 B2 A3 B6 A2]
time 15607ms: Process B1 started using the CPU for remaining 2108ms of 3004ms burst [Q A4 A0 B8 A1 B0 B9 A7 B7 A8 A6 A9 A5 B5 B2 A3 B6 A2]
time 15671ms: Time slice expired; preempting process B1 with 2044ms remaining [Q A4 A0 B8 A1 B0 B9 A7 B7 A8 A6 A9 A5 B5 B2 A3 B6 A2]
time 15675ms: Process A4 started using the CPU for remaining 736ms of 1248ms burst [Q A0 B8 A1 B0 B9 A7 B7 A8 A6 A9 A5 B5 B2 A3 B6 A2 B1]
time 15739ms: Time slice expired; preempting process A4 with 672ms remaining [Q A0 B8 A1 B0 B9 A7 B7 A8 A6 A9 A5 B5 B2 A3 B6 A2 B1]
time 15743ms: Process A0 started using the CPU for remaining 392ms of 1096ms burst [Q B8 A1 B0 B9 A7 B7 A8 A6 A9 A5 B5 B2 A3 B6 A2 B1 A4]
time 15807ms: Time slice expired; preempting process A0 with 328ms remaining [Q B8 A1 B0 B9 A7 B7 A8 A6 A9 A5 B5 B2 A3 B6 A2 B1 A4]
time 15811ms: Process B8 started using the CPU for 56ms burst [Q A1 B0 B9 A7 B7 A8 A6 A9 A5 B5 B2 A3 B6 A2 B1 A4 A0]
time 15867ms: Process B8 completed a CPU burst; 15 bursts to go [Q A1 B0 B9 A7 B7 A8 A6 A9 A5 B5 B2 A3 B6 A2 B1 A4 A0]
time 15867ms: Process B8 switching out of CPU; blocking on I/O until time 17093ms [Q A1 B0 B9 A7 B7 A8 A6 A9 A5 B5 B2 A3 B6 A2 B1 A4 A0]
time 15871ms: Process A1 started using the CPU for remaining 544ms of 608ms burst [Q B0 B9 A7 B7 A8 A6 A9 A5 B5 B2 A3 B6 A2 B1 A4 A0]
time 15935ms: Time slice expired; preempting process A1 with 480ms remaining [Q B0 B9 A7 B7 A8 A6 A9 A5 B5 B2 A3 B6 A2 B1 A4 A0]
time 15939ms: Process B0 started using the CPU for remaining 560ms of 1264ms burst [Q B9 A7 B7 A8 A6 A9 A5 B5 B2 A3 B6 A2 B1 A4 A0 A1]
time 16003ms: Time slice expired; preempting process B0 with 496ms remaining [Q B9 A7 B7 A8 A6 A9 A5 B5 B2 A3 B6 A2 B1 A4 A0 A1]
time 16007ms: Process B9 started using the CPU for 148ms burst [Q A7 B7 A8 A6 A9 A5 B5 B2 A3 B6 A2 B1 A4 A0 A1 B0]
time 16071ms: Time slice expired; preempting process B9 with 84ms remaining [Q A7 B7 A8 A6 A9 A5 B5 B2 A3 B6 A2 B1 A4 A0 A1 B0]
time 16075ms: Process A7 started using the CPU for remaining 1324ms of 1388ms burst [Q B7 A8 A6 A9 A5 B5 B2 A3 B6 A2 B1 A4 A0 A1 B0 B9]
time 16139ms: Time slice expired; preempting process A7 with 1260ms remaining [Q B7 A8 A6 A9 A5 B5 B2 A3 B6 A2 B1 A4 A0 A1 B0 B9]
time 16143ms: Process B7 started using the CPU for 133ms burst [Q A8 A6 A9 A5 B5 B2 A3 B6 A2 B1 A4 A0 A1 B0 B9 A7]
time 16189ms: Process B4 completed I/O; added to ready queue [Q A8 A6 A9 A5 B5 B2 A3 B6 A2 B1 A4 A0 A1 B0 B9 A7 B4]
time 16207ms: Time slice expired; preempting process B7 with 69ms remaining [Q A8 A6 A9 A5 B5 B2 A3 B6 A2 B1 A4 A0 A1 B0 B9 A7 B4]
time 16211ms: Process A8 started using the CPU for remaining 20ms of 340ms burst [Q A6 A9 A5 B5 B2 A3 B6 A2 B1 A4 A0 A1 B0 B9 A7 B4 B7]
time 16231ms: Process A8 completed a CPU burst; 5 bursts to go [Q A6 A9 A5 B5 B2 A3 B6 A2 B1 A4 A0 A1 B0 B9 A7 B4 B7]
time 16231ms: Process A8 switching out of CPU; blocking on I/O until time 16298ms [Q A6 A9 A5 B5 B2 A3 B6 A2 B1 A4 A0 A1 B0 B9 A7 B4 B7]
time 16235ms: Process A6 started using the CPU for remaining 564ms of 756ms burst [Q A9 A5 B5 B2 A3 B6 A2 B1 A4 A0 A1 B0 B9 A7 B4 B7]
time 16298ms: Process A8 completed I/O; added to ready queue [Q A9 A5 B5 B2 A3 B6 A2 B1 A4 A0 A1 B0 B9 A7 B4 B7 A8]
time 16299ms: Time slice expired; preempting process A6 with 500ms remaining [Q A9 A5 B5 B2 A3 B6 A2 B1 A4 A0 A1 B0 B9 A7 B4 B7 A8]
time 16303ms: Process A9 started using the CPU for remaining 452ms of 644ms burst [Q A5 B5 B2 A3 B6 A2 B1 A4 A0 A1 B0 B9 A7 B4 B7 A8 A6]
time 16367ms: Time slice expired; preempting process A9 with 388ms remaining [Q A5 B5 B2 A3 B6 A2 B1 A4 A0 A1 B0 B9 A7 B4 B7 A8 A6]
time 16371ms: Process A5 started using the CPU for remaining 720ms of 912ms burst [Q B5 B2 A3 B6 A2 B1 A4 A0 A1 B0 B9 A7 B4 B7 A8 A6 A9]
time 16435ms: Time slice expired; preempting process A5 with 656ms remaining [Q B5 B2 A3 B6 A2 B1 A4 A0 A1 B0 B9 A7 B4 B7 A8 A6 A9]
time 16439ms: Process B5 started using the CPU for remaining 130ms of 194ms burst [Q B2 A3 B6 A2 B1 A4 A0 A1 B0 B9 A7 B4 B7 A8 A6 A9 A5]
time 16503ms: Time slice expired; preempting process B5 with 66ms remaining [Q B2 A3 B6 A2 B1 A4 A0 A1 B0 B9 A7 B4 B7 A8 A6 A9 A5]
time 16507ms: Process B2 started using the CPU for remaining 78ms of 142ms burst [Q A3 B6 A2 B1 A4 A0 A1 B0 B9 A7 B4 B7 A8 A6 A9 A5 B5]
time 16571ms: Time slice expired; preempting process B2 with 14ms remaining [Q A3 B6 A2 B1 A4 A0 A1 B0 B9 A7 B4 B7 A8 A6 A9 A5 B5]
time 16575ms: Process A3 started using the CPU for remaining 516ms of 580ms burst [Q B6 A2 B1 A4 A0 A1 B0 B9 A7 B4 B7 A8 A6 A9 A5 B5 B2]
time 16639ms: Time slice expired; preempting process A3 with 452ms remaining [Q B6 A2 B1 A4 A0 A1 B0 B9 A7 B4 B7 A8 A6 A9 A5 B5 B2]
time 16643ms: Process B6 started using the CPU for 46ms burst [Q A2 B1 A4 A0 A1 B0 B9 A7 B4 B7 A8 A6 A9 A5 B5 B2 A3]
time 16689ms: Process B6 terminated [Q A2 B1 A4 A0 A1 B0 B9 A7 B4 B7 A8 A6 A9 A5 B5 B2 A3]
time 16693ms: Process A2 started using the CPU for remaining 312ms of 760ms burst [Q B1 A4 A0 A1 B0 B9 A7 B4 B7 A8 A6 A9 A5 B5 B2 A3]
time 16757ms: Time slice expired; preempting process A2 with 248ms remaining [Q B1 A4 A0 A1 B0 B9 A7 B4 B7 A8 A6 A9 A5 B5 B2 A3]
time 16761ms: Process B1 started using the CPU for remaining 2044ms of 3004ms burst [Q A4 A0 A1 B0 B9 A7 B4 B7 A8 A6 A9 A5 B5 B2 A3 A2]
time 16825ms: Time slice expired; preempting process B1 with 1980ms remaining [Q A4 A0 A1 B0 B9 A7 B4 B7 A8 A6 A9 A5 B5 B2 A3 A2]
time 16829ms: Process A4 started using the CPU for remaining 672ms of 1248ms burst [Q A0 A1 B0 B9 A7 B4 B7 A8 A6 A9 A5 B5 B2 A3 A2 B1]
time 16893ms: Time slice expired; preempting process A4 with 608ms remaining [Q A0 A1 B0 B9 A7 B4 B7 A8 A6 A9 A5 B5 B2 A3 A2 B1]
time 16897ms: Process A0 started using the CPU for remaining 328ms of 1096ms burst [Q A1 B0 B9 A7 B4 B7 A8 A6 A9 A5 B5 B2 A3 A2 B1 A4]
time 16961ms: Time slice expired; preempting process A0 with 264ms remaining [Q A1 B0 B9 A7 B4 B7 A8 A6 A9 A5 B5 B2 A3 A2 B1 A4]
time 16965ms: Process A1 started using the CPU for remaining 480ms of 608ms burst [Q B0 B9 A7 B4 B7 A8 A6 A9 A5 B5 B2 A3 A2 B1 A4 A0]
time 17029ms: Time slice expired; preempting process A1 with 416ms remaining [Q B0 B9 A7 B4 B7 A8 A6 A9 A5 B5 B2 A3 A2 B1 A4 A0]
time 17033ms: Process B0 started using the CPU for remaining 496ms of 1264ms burst [Q B9 A7 B4 B7 A8 A6 A9 A5 B5 B2 A3 A2 B1 A4 A0 A1]
time 17093ms: Process B8 completed I/O; added to ready queue [Q B9 A7 B4 B7 A8 A6 A9 A5 B5 B2 A3 A2 B1 A4 A0 A1 B8]
time 17097ms: Time slice expired; preempting process B0 with 432ms remaining [Q B9 A7 B4 B7 A8 A6 A9 A5 B5 B2 A3 A2 B1 A4 A0 A1 B8]
time 17101ms: Process B9 started using the CPU for remaining 84ms of 148ms burst [Q A7 B4 B7 A8 A6 A9 A5 B5 B2 A3 A2 B1 A4 A0 A1 B8 B0]
time 17165ms: Time slice expired; preempting process B9 with 20ms remaining [Q A7 B4 B7 A8 A6 A9 A5 B5 B2 A3 A2 B1 A4 A0 A1 B8 B0]
time 17169ms: Process A7 started using the CPU for remaining 1260ms of 1388ms burst [Q B4 B7 A8 A6 A9 A5 B5 B2 A3 A2 B1 A4 A0 A1 B8 B0 B9]
time 17233ms: Time slice expired; preempting process A7 with 1196ms remaining [Q B4 B7 A8 A6 A9 A5 B5 B2 A3 A2 B1 A4 A0 A1 B8 B0 B9]
time 17237ms: Process B4 started using the CPU for 47ms burst [Q B7 A8 A6 A9 A5 B5 B2 A3 A2 B1 A4 A0 A1 B8 B0 B9 A7]
time 17284ms: Process B4 completed a CPU burst; 9 bursts to go [Q B7 A8 A6 A9 A5 B5 B2 A3 A2 B1 A4 A0 A1 B8 B0 B9 A7]
time 17284ms: Process B4 switching out of CPU; blocking on I/O until time 17742ms [Q B7 A8 A6 A9 A5 B5 B2 A3 A2 B1 A4 A0 A1 B8 B0 B9 A7]
time 17288ms: Process B7 started using the CPU for remaining 69ms of 133ms burst [Q A8 A6 A9 A5 B5 B2 A3 A2 B1 A4 A0 A1 B8 B0 B9 A7]
time 17352ms: Time slice expired; preempting process B7 with 5ms remaining [Q A8 A6 A9 A5 B5 B2 A3 A2 B1 A4 A0 A1 B8 B0 B9 A7]
time 17356ms: Process A8 started using the CPU for 820ms burst [Q A6 A9 A5 B5 B2 A3 A2 B1 A4 A0 A1 B8 B0 B9 A7 B7]
time 17420ms: Time slice expired; preempting process A8 with 756ms remaining [Q A6 A9 A5 B5 B2 A3 A2 B1 A4 A0 A1 B8 B0 B9 A7 B7]
time 17424ms: Process A6 started using the CPU for remaining 500ms of 756ms burst [Q A9 A5 B5 B2 A3 A2 B1 A4 A0 A1 B8 B0 B9 A7 B7 A8]
time 17488ms: Time slice expired; preempting process A6 with 436ms remaining [Q A9 A5 B5 B2 A3 A2 B1 A4 A0 A1 B8 B0 B9 A7 B7 A8]
time 17492ms: Process A9 started using the CPU for remaining 388ms of 644ms burst [Q A5 B5 B2 A3 A2 B1 A4 A0 A1 B8 B0 B9 A7 B7 A8 A6]
time 17556ms: Time slice expired; preempting process A9 with 324ms remaining [Q A5 B5 B2 A3 A2 B1 A4 A0 A1 B8 B0 B9 A7 B7 A8 A6]
time 17560ms: Process A5 started using the CPU for remaining 656ms of 912ms burst [Q B5 B2 A3 A2 B1 A4 A0 A1 B8 B0 B9 A7 B7 A8 A6 A9]
time 17624ms: Time slice expired; preempting process A5 with 592ms remaining [Q B5 B2 A3 A2 B1 A4 A0 A1 B8 B0 B9 A7 B7 A8 A6 A9]
time 17628ms: Process B5 started using the CPU for remaining 66ms of 194ms burst [Q B2 A3 A2 B1 A4 A0 A1 B8 B0 B9 A7 B7 A8 A6 A9 A5]
time 17692ms: Time slice expired; preempting process B5 with 2ms remaining [Q B2 A3 A2 B1 A4 A0 A1 B8 B0 B9 A7 B7 A8 A6 A9 A5]
time 17696ms: Process B2 started using the CPU for remaining 14ms of 142ms burst [Q A3 A2 B1 A4 A0 A1 B8 B0 B9 A7 B7 A8 A6 A9 A5 B5]
time 17710ms: Process B2 completed a CPU burst; 8 bursts to go [Q A3 A2 B1 A4 A0 A1 B8 B0 B9 A7 B7 A8 A6 A9 A5 B5]
time 17710ms: Process B2 switching out of CPU; blocking on I/O until time 17744ms [Q A3 A2 B1 A4 A0 A1 B8 B0 B9 A7 B7 A8 A6 A9 A5 B5]
time 17714ms: Process A3 started using the CPU for remaining 452ms of 580ms burst [Q A2 B1 A4 A0 A1 B8 B0 B9 A7 B7 A8 A6 A9 A5 B5]
time 17742ms: Process B4 completed I/O; added to ready queue [Q A2 B1 A4 A0 A1 B8 B0 B9 A7 B7 A8 A6 A9 A5 B5 B4]
time 17744ms: Process B2 completed I/O; added to ready queue [Q A2 B1 A4 A0 A1 B8 B0 B9 A7 B7 A8 A6 A9 A5 B5 B4 B2]
time 17778ms: Time slice expired; preempting process A3 with 388ms remaining [Q A2 B1 A4 A0 A1 B8 B0 B9 A7 B7 A8 A6 A9 A5 B5 B4 B2]
time 17782ms: Process A2 started using the CPU for remaining 248ms of 760ms burst [Q B1 A4 A0 A1 B8 B0 B9 A7 B7 A8 A6 A9 A5 B5 B4 B2 A3]
time 17846ms: Time slice expired; preempting process A2 with 184ms remaining [Q B1 A4 A0 A1 B8 B0 B9 A7 B7 A8 A6 A9 A5 B5 B4 B2 A3]
time 17850ms: Process B1 started using the CPU for remaining 1980ms of 3004ms burst [Q A4 A0 A1 B8 B0 B9 A7 B7 A8 A6 A9 A5 B5 B4 B2 A3 A2]
time 17914ms: Time slice expired; preempting process B1 with 1916ms remaining [Q A4 A0 A1 B8 B0 B9 A7 B7 A8 A6 A9 A5 B5 B4 B2 A3 A2]
time 17918ms: Process A4 started using the CPU for remaining 608ms of 1248ms burst [Q A0 A1 B8 B0 B9 A7 B7 A8 A6 A9 A5 B5 B4 B2 A3 A2 B1]
time 17982ms: Time slice expired; preempting process A4 with 544ms remaining [Q A0 A1 B8 B0 B9 A7 B7 A8 A6 A9 A5 B5 B4 B2 A3 A2 B1]
time 17986ms: Process A0 started using the CPU for remaining 264ms of 1096ms burst [Q A1 B8 B0 B9 A7 B7 A8 A6 A9 A5 B5 B4 B2 A3 A2 B1 A4]
