<<< PROJECT PART I
<<< -- process set (n=8) with 6 CPU-bound processes
<<< -- seed=512; lambda=0.001000; bound=1024
CPU-bound process A0: arrival time 692ms; 6 CPU bursts
CPU-bound process A1: arrival time 407ms; 10 CPU bursts
CPU-bound process A2: arrival time 886ms; 1 CPU burst
CPU-bound process A3: arrival time 368ms; 6 CPU bursts
CPU-bound process A4: arrival time 269ms; 19 CPU bursts
CPU-bound process A5: arrival time 44ms; 11 CPU bursts
I/O-bound process A6: arrival time 589ms; 7 CPU bursts
I/O-bound process A7: arrival time 825ms; 22 CPU bursts
time 0ms: Simulator started for RR [Q empty]
time 44ms: Process A5 arrived; added to ready queue [Q A5]
time 47ms: Process A5 started using the CPU for 2428ms burst [Q empty]
time 175ms: Time slice expired; no preemption because ready queue is empty [Q empty]
time 269ms: Process A4 arrived; added to ready queue [Q A4]
time 303ms: Time slice expired; preempting process A5 with 2172ms remaining [Q A4]
time 309ms: Process A4 started using the CPU for 216ms burst [Q A5]
time 368ms: Process A3 arrived; added to ready queue [Q A5 A3]
time 407ms: Process A1 arrived; added to ready queue [Q A5 A3 A1]
time 437ms: Time slice expired; preempting process A4 with 88ms remaining [Q A5 A3 A1]
time 443ms: Process A5 started using the CPU for remaining 2172ms of 2428ms burst [Q A3 A1 A4]
time 571ms: Time slice expired; preempting process A5 with 2044ms remaining [Q A3 A1 A4]
time 577ms: Process A3 started using the CPU for 768ms burst [Q A1 A4 A5]
time 589ms: Process A6 arrived; added to ready queue [Q A1 A4 A5 A6]
time 692ms: Process A0 arrived; added to ready queue [Q A1 A4 A5 A6 A0]
time 705ms: Time slice expired; preempting process A3 with 640ms remaining [Q A1 A4 A5 A6 A0]
time 711ms: Process A1 started using the CPU for 2720ms burst [Q A4 A5 A6 A0 A3]
time 825ms: Process A7 arrived; added to ready queue [Q A4 A5 A6 A0 A3 A7]
time 839ms: Time slice expired; preempting process A1 with 2592ms remaining [Q A4 A5 A6 A0 A3 A7]
time 845ms: Process A4 started using the CPU for remaining 88ms of 216ms burst [Q A5 A6 A0 A3 A7 A1]
time 886ms: Process A2 arrived; added to ready queue [Q A5 A6 A0 A3 A7 A1 A2]
time 933ms: Process A4 completed a CPU burst; 18 bursts to go [Q A5 A6 A0 A3 A7 A1 A2]
time 933ms: Process A4 switching out of CPU; blocking on I/O until time 996ms [Q A5 A6 A0 A3 A7 A1 A2]
time 939ms: Process A5 started using the CPU for remaining 2044ms of 2428ms burst [Q A6 A0 A3 A7 A1 A2]
time 996ms: Process A4 completed I/O; added to ready queue [Q A6 A0 A3 A7 A1 A2 A4]
time 1067ms: Time slice expired; preempting process A5 with 1916ms remaining [Q A6 A0 A3 A7 A1 A2 A4]
time 1073ms: Process A6 started using the CPU for 36ms burst [Q A0 A3 A7 A1 A2 A4 A5]
time 1109ms: Process A6 completed a CPU burst; 6 bursts to go [Q A0 A3 A7 A1 A2 A4 A5]
time 1109ms: Process A6 switching out of CPU; blocking on I/O until time 2896ms [Q A0 A3 A7 A1 A2 A4 A5]
time 1115ms: Process A0 started using the CPU for 2552ms burst [Q A3 A7 A1 A2 A4 A5]
time 1243ms: Time slice expired; preempting process A0 with 2424ms remaining [Q A3 A7 A1 A2 A4 A5]
time 1249ms: Process A3 started using the CPU for remaining 640ms of 768ms burst [Q A7 A1 A2 A4 A5 A0]
time 1377ms: Time slice expired; preempting process A3 with 512ms remaining [Q A7 A1 A2 A4 A5 A0]
time 1383ms: Process A7 started using the CPU for 956ms burst [Q A1 A2 A4 A5 A0 A3]
time 1511ms: Time slice expired; preempting process A7 with 828ms remaining [Q A1 A2 A4 A5 A0 A3]
time 1517ms: Process A1 started using the CPU for remaining 2592ms of 2720ms burst [Q A2 A4 A5 A0 A3 A7]
time 1645ms: Time slice expired; preempting process A1 with 2464ms remaining [Q A2 A4 A5 A0 A3 A7]
time 1651ms: Process A2 started using the CPU for 1008ms burst [Q A4 A5 A0 A3 A7 A1]
time 1779ms: Time slice expired; preempting process A2 with 880ms remaining [Q A4 A5 A0 A3 A7 A1]
time 1785ms: Process A4 started using the CPU for 544ms burst [Q A5 A0 A3 A7 A1 A2]
time 1913ms: Time slice expired; preempting process A4 with 416ms remaining [Q A5 A0 A3 A7 A1 A2]
time 1919ms: Process A5 started using the CPU for remaining 1916ms of 2428ms burst [Q A0 A3 A7 A1 A2 A4]
time 2047ms: Time slice expired; preempting process A5 with 1788ms remaining [Q A0 A3 A7 A1 A2 A4]
time 2053ms: Process A0 started using the CPU for remaining 2424ms of 2552ms burst [Q A3 A7 A1 A2 A4 A5]
time 2181ms: Time slice expired; preempting process A0 with 2296ms remaining [Q A3 A7 A1 A2 A4 A5]
time 2187ms: Process A3 started using the CPU for remaining 512ms of 768ms burst [Q A7 A1 A2 A4 A5 A0]
time 2315ms: Time slice expired; preempting process A3 with 384ms remaining [Q A7 A1 A2 A4 A5 A0]
time 2321ms: Process A7 started using the CPU for remaining 828ms of 956ms burst [Q A1 A2 A4 A5 A0 A3]
time 2449ms: Time slice expired; preempting process A7 with 700ms remaining [Q A1 A2 A4 A5 A0 A3]
time 2455ms: Process A1 started using the CPU for remaining 2464ms of 2720ms burst [Q A2 A4 A5 A0 A3 A7]
time 2583ms: Time slice expired; preempting process A1 with 2336ms remaining [Q A2 A4 A5 A0 A3 A7]
time 2589ms: Process A2 started using the CPU for remaining 880ms of 1008ms burst [Q A4 A5 A0 A3 A7 A1]
time 2717ms: Time slice expired; preempting process A2 with 752ms remaining [Q A4 A5 A0 A3 A7 A1]
time 2723ms: Process A4 started using the CPU for remaining 416ms of 544ms burst [Q A5 A0 A3 A7 A1 A2]
time 2851ms: Time slice expired; preempting process A4 with 288ms remaining [Q A5 A0 A3 A7 A1 A2]
time 2857ms: Process A5 started using the CPU for remaining 1788ms of 2428ms burst [Q A0 A3 A7 A1 A2 A4]
time 2896ms: Process A6 completed I/O; added to ready queue [Q A0 A3 A7 A1 A2 A4 A6]
time 2985ms: Time slice expired; preempting process A5 with 1660ms remaining [Q A0 A3 A7 A1 A2 A4 A6]
time 2991ms: Process A0 started using the CPU for remaining 2296ms of 2552ms burst [Q A3 A7 A1 A2 A4 A6 A5]
time 3119ms: Time slice expired; preempting process A0 with 2168ms remaining [Q A3 A7 A1 A2 A4 A6 A5]
time 3125ms: Process A3 started using the CPU for remaining 384ms of 768ms burst [Q A7 A1 A2 A4 A6 A5 A0]
time 3253ms: Time slice expired; preempting process A3 with 256ms remaining [Q A7 A1 A2 A4 A6 A5 A0]
time 3259ms: Process A7 started using the CPU for remaining 700ms of 956ms burst [Q A1 A2 A4 A6 A5 A0 A3]
time 3387ms: Time slice expired; preempting process A7 with 572ms remaining [Q A1 A2 A4 A6 A5 A0 A3]
time 3393ms: Process A1 started using the CPU for remaining 2336ms of 2720ms burst [Q A2 A4 A6 A5 A0 A3 A7]
time 3521ms: Time slice expired; preempting process A1 with 2208ms remaining [Q A2 A4 A6 A5 A0 A3 A7]
time 3527ms: Process A2 started using the CPU for remaining 752ms of 1008ms burst [Q A4 A6 A5 A0 A3 A7 A1]
time 3655ms: Time slice expired; preempting process A2 with 624ms remaining [Q A4 A6 A5 A0 A3 A7 A1]
time 3661ms: Process A4 started using the CPU for remaining 288ms of 544ms burst [Q A6 A5 A0 A3 A7 A1 A2]
time 3789ms: Time slice expired; preempting process A4 with 160ms remaining [Q A6 A5 A0 A3 A7 A1 A2]
time 3795ms: Process A6 started using the CPU for 362ms burst [Q A5 A0 A3 A7 A1 A2 A4]
time 3923ms: Time slice expired; preempting process A6 with 234ms remaining [Q A5 A0 A3 A7 A1 A2 A4]
time 3929ms: Process A5 started using the CPU for remaining 1660ms of 2428ms burst [Q A0 A3 A7 A1 A2 A4 A6]
time 4057ms: Time slice expired; preempting process A5 with 1532ms remaining [Q A0 A3 A7 A1 A2 A4 A6]
time 4063ms: Process A0 started using the CPU for remaining 2168ms of 2552ms burst [Q A3 A7 A1 A2 A4 A6 A5]
time 4191ms: Time slice expired; preempting process A0 with 2040ms remaining [Q A3 A7 A1 A2 A4 A6 A5]
time 4197ms: Process A3 started using the CPU for remaining 256ms of 768ms burst [Q A7 A1 A2 A4 A6 A5 A0]
time 4325ms: Time slice expired; preempting process A3 with 128ms remaining [Q A7 A1 A2 A4 A6 A5 A0]
time 4331ms: Process A7 started using the CPU for remaining 572ms of 956ms burst [Q A1 A2 A4 A6 A5 A0 A3]
time 4459ms: Time slice expired; preempting process A7 with 444ms remaining [Q A1 A2 A4 A6 A5 A0 A3]
time 4465ms: Process A1 started using the CPU for remaining 2208ms of 2720ms burst [Q A2 A4 A6 A5 A0 A3 A7]
time 4593ms: Time slice expired; preempting process A1 with 2080ms remaining [Q A2 A4 A6 A5 A0 A3 A7]
time 4599ms: Process A2 started using the CPU for remaining 624ms of 1008ms burst [Q A4 A6 A5 A0 A3 A7 A1]
time 4727ms: Time slice expired; preempting process A2 with 496ms remaining [Q A4 A6 A5 A0 A3 A7 A1]
time 4733ms: Process A4 started using the CPU for remaining 160ms of 544ms burst [Q A6 A5 A0 A3 A7 A1 A2]
time 4861ms: Time slice expired; preempting process A4 with 32ms remaining [Q A6 A5 A0 A3 A7 A1 A2]
time 4867ms: Process A6 started using the CPU for remaining 234ms of 362ms burst [Q A5 A0 A3 A7 A1 A2 A4]
time 4995ms: Time slice expired; preempting process A6 with 106ms remaining [Q A5 A0 A3 A7 A1 A2 A4]
time 5001ms: Process A5 started using the CPU for remaining 1532ms of 2428ms burst [Q A0 A3 A7 A1 A2 A4 A6]
time 5129ms: Time slice expired; preempting process A5 with 1404ms remaining [Q A0 A3 A7 A1 A2 A4 A6]
time 5135ms: Process A0 started using the CPU for remaining 2040ms of 2552ms burst [Q A3 A7 A1 A2 A4 A6 A5]
time 5263ms: Time slice expired; preempting process A0 with 1912ms remaining [Q A3 A7 A1 A2 A4 A6 A5]
time 5269ms: Process A3 started using the CPU for remaining 128ms of 768ms burst [Q A7 A1 A2 A4 A6 A5 A0]
time 5397ms: Process A3 completed a CPU burst; 5 bursts to go [Q A7 A1 A2 A4 A6 A5 A0]
time 5397ms: Process A3 switching out of CPU; blocking on I/O until time 6342ms [Q A7 A1 A2 A4 A6 A5 A0]
time 5403ms: Process A7 started using the CPU for remaining 444ms of 956ms burst [Q A1 A2 A4 A6 A5 A0]
time 5531ms: Time slice expired; preempting process A7 with 316ms remaining [Q A1 A2 A4 A6 A5 A0]
time 5537ms: Process A1 started using the CPU for remaining 2080ms of 2720ms burst [Q A2 A4 A6 A5 A0 A7]
time 5665ms: Time slice expired; preempting process A1 with 1952ms remaining [Q A2 A4 A6 A5 A0 A7]
time 5671ms: Process A2 started using the CPU for remaining 496ms of 1008ms burst [Q A4 A6 A5 A0 A7 A1]
time 5799ms: Time slice expired; preempting process A2 with 368ms remaining [Q A4 A6 A5 A0 A7 A1]
time 5805ms: Process A4 started using the CPU for remaining 32ms of 544ms burst [Q A6 A5 A0 A7 A1 A2]
time 5837ms: Process A4 completed a CPU burst; 17 bursts to go [Q A6 A5 A0 A7 A1 A2]
time 5837ms: Process A4 switching out of CPU; blocking on I/O until time 6751ms [Q A6 A5 A0 A7 A1 A2]
time 5843ms: Process A6 started using the CPU for remaining 106ms of 362ms burst [Q A5 A0 A7 A1 A2]
time 5949ms: Process A6 completed a CPU burst; 5 bursts to go [Q A5 A0 A7 A1 A2]
time 5949ms: Process A6 switching out of CPU; blocking on I/O until time 6600ms [Q A5 A0 A7 A1 A2]
time 5955ms: Process A5 started using the CPU for remaining 1404ms of 2428ms burst [Q A0 A7 A1 A2]
time 6083ms: Time slice expired; preempting process A5 with 1276ms remaining [Q A0 A7 A1 A2]
time 6089ms: Process A0 started using the CPU for remaining 1912ms of 2552ms burst [Q A7 A1 A2 A5]
time 6217ms: Time slice expired; preempting process A0 with 1784ms remaining [Q A7 A1 A2 A5]
time 6223ms: Process A7 started using the CPU for remaining 316ms of 956ms burst [Q A1 A2 A5 A0]
time 6342ms: Process A3 completed I/O; added to ready queue [Q A1 A2 A5 A0 A3]
time 6351ms: Time slice expired; preempting process A7 with 188ms remaining [Q A1 A2 A5 A0 A3]
time 6357ms: Process A1 started using the CPU for remaining 1952ms of 2720ms burst [Q A2 A5 A0 A3 A7]
time 6485ms: Time slice expired; preempting process A1 with 1824ms remaining [Q A2 A5 A0 A3 A7]
time 6491ms: Process A2 started using the CPU for remaining 368ms of 1008ms burst [Q A5 A0 A3 A7 A1]
time 6600ms: Process A6 completed I/O; added to ready queue [Q A5 A0 A3 A7 A1 A6]
time 6619ms: Time slice expired; preempting process A2 with 240ms remaining [Q A5 A0 A3 A7 A1 A6]
time 6625ms: Process A5 started using the CPU for remaining 1276ms of 2428ms burst [Q A0 A3 A7 A1 A6 A2]
time 6751ms: Process A4 completed I/O; added to ready queue [Q A0 A3 A7 A1 A6 A2 A4]
time 6753ms: Time slice expired; preempting process A5 with 1148ms remaining [Q A0 A3 A7 A1 A6 A2 A4]
time 6759ms: Process A0 started using the CPU for remaining 1784ms of 2552ms burst [Q A3 A7 A1 A6 A2 A4 A5]
time 6887ms: Time slice expired; preempting process A0 with 1656ms remaining [Q A3 A7 A1 A6 A2 A4 A5]
time 6893ms: Process A3 started using the CPU for 3764ms burst [Q A7 A1 A6 A2 A4 A5 A0]
time 7021ms: Time slice expired; preempting process A3 with 3636ms remaining [Q A7 A1 A6 A2 A4 A5 A0]
time 7027ms: Process A7 started using the CPU for remaining 188ms of 956ms burst [Q A1 A6 A2 A4 A5 A0 A3]
time 7155ms: Time slice expired; preempting process A7 with 60ms remaining [Q A1 A6 A2 A4 A5 A0 A3]
time 7161ms: Process A1 started using the CPU for remaining 1824ms of 2720ms burst [Q A6 A2 A4 A5 A0 A3 A7]
time 7289ms: Time slice expired; preempting process A1 with 1696ms remaining [Q A6 A2 A4 A5 A0 A3 A7]
time 7295ms: Process A6 started using the CPU for 759ms burst [Q A2 A4 A5 A0 A3 A7 A1]
time 7423ms: Time slice expired; preempting process A6 with 631ms remaining [Q A2 A4 A5 A0 A3 A7 A1]
time 7429ms: Process A2 started using the CPU for remaining 240ms of 1008ms burst [Q A4 A5 A0 A3 A7 A1 A6]
time 7557ms: Time slice expired; preempting process A2 with 112ms remaining [Q A4 A5 A0 A3 A7 A1 A6]
time 7563ms: Process A4 started using the CPU for 1572ms burst [Q A5 A0 A3 A7 A1 A6 A2]
time 7691ms: Time slice expired; preempting process A4 with 1444ms remaining [Q A5 A0 A3 A7 A1 A6 A2]
time 7697ms: Process A5 started using the CPU for remaining 1148ms of 2428ms burst [Q A0 A3 A7 A1 A6 A2 A4]
time 7825ms: Time slice expired; preempting process A5 with 1020ms remaining [Q A0 A3 A7 A1 A6 A2 A4]
time 7831ms: Process A0 started using the CPU for remaining 1656ms of 2552ms burst [Q A3 A7 A1 A6 A2 A4 A5]
time 7959ms: Time slice expired; preempting process A0 with 1528ms remaining [Q A3 A7 A1 A6 A2 A4 A5]
time 7965ms: Process A3 started using the CPU for remaining 3636ms of 3764ms burst [Q A7 A1 A6 A2 A4 A5 A0]
time 8093ms: Time slice expired; preempting process A3 with 3508ms remaining [Q A7 A1 A6 A2 A4 A5 A0]
time 8099ms: Process A7 started using the CPU for remaining 60ms of 956ms burst [Q A1 A6 A2 A4 A5 A0 A3]
time 8159ms: Process A7 completed a CPU burst; 21 bursts to go [Q A1 A6 A2 A4 A5 A0 A3]
time 8159ms: Process A7 switching out of CPU; blocking on I/O until time 9394ms [Q A1 A6 A2 A4 A5 A0 A3]
time 8165ms: Process A1 started using the CPU for remaining 1696ms of 2720ms burst [Q A6 A2 A4 A5 A0 A3]
time 8293ms: Time slice expired; preempting process A1 with 1568ms remaining [Q A6 A2 A4 A5 A0 A3]
time 8299ms: Process A6 started using the CPU for remaining 631ms of 759ms burst [Q A2 A4 A5 A0 A3 A1]
time 8427ms: Time slice expired; preempting process A6 with 503ms remaining [Q A2 A4 A5 A0 A3 A1]
time 8433ms: Process A2 started using the CPU for remaining 112ms of 1008ms burst [Q A4 A5 A0 A3 A1 A6]
time 8545ms: Process A2 terminated [Q A4 A5 A0 A3 A1 A6]
time 8551ms: Process A4 started using the CPU for remaining 1444ms of 1572ms burst [Q A5 A0 A3 A1 A6]
time 8679ms: Time slice expired; preempting process A4 with 1316ms remaining [Q A5 A0 A3 A1 A6]
time 8685ms: Process A5 started using the CPU for remaining 1020ms of 2428ms burst [Q A0 A3 A1 A6 A4]
time 8813ms: Time slice expired; preempting process A5 with 892ms remaining [Q A0 A3 A1 A6 A4]
time 8819ms: Process A0 started using the CPU for remaining 1528ms of 2552ms burst [Q A3 A1 A6 A4 A5]
time 8947ms: Time slice expired; preempting process A0 with 1400ms remaining [Q A3 A1 A6 A4 A5]
time 8953ms: Process A3 started using the CPU for remaining 3508ms of 3764ms burst [Q A1 A6 A4 A5 A0]
time 9081ms: Time slice expired; preempting process A3 with 3380ms remaining [Q A1 A6 A4 A5 A0]
time 9087ms: Process A1 started using the CPU for remaining 1568ms of 2720ms burst [Q A6 A4 A5 A0 A3]
time 9215ms: Time slice expired; preempting process A1 with 1440ms remaining [Q A6 A4 A5 A0 A3]
time 9221ms: Process A6 started using the CPU for remaining 503ms of 759ms burst [Q A4 A5 A0 A3 A1]
time 9349ms: Time slice expired; preempting process A6 with 375ms remaining [Q A4 A5 A0 A3 A1]
time 9355ms: Process A4 started using the CPU for remaining 1316ms of 1572ms burst [Q A5 A0 A3 A1 A6]
time 9394ms: Process A7 completed I/O; added to ready queue [Q A5 A0 A3 A1 A6 A7]
time 9483ms: Time slice expired; preempting process A4 with 1188ms remaining [Q A5 A0 A3 A1 A6 A7]
time 9489ms: Process A5 started using the CPU for remaining 892ms of 2428ms burst [Q A0 A3 A1 A6 A7 A4]
time 9617ms: Time slice expired; preempting process A5 with 764ms remaining [Q A0 A3 A1 A6 A7 A4]
time 9623ms: Process A0 started using the CPU for remaining 1400ms of 2552ms burst [Q A3 A1 A6 A7 A4 A5]
time 9751ms: Time slice expired; preempting process A0 with 1272ms remaining [Q A3 A1 A6 A7 A4 A5]
time 9757ms: Process A3 started using the CPU for remaining 3380ms of 3764ms burst [Q A1 A6 A7 A4 A5 A0]
time 9885ms: Time slice expired; preempting process A3 with 3252ms remaining [Q A1 A6 A7 A4 A5 A0]
time 9891ms: Process A1 started using the CPU for remaining 1440ms of 2720ms burst [Q A6 A7 A4 A5 A0 A3]
time 10019ms: Time slice expired; preempting process A1 with 1312ms remaining [Q A6 A7 A4 A5 A0 A3]
time 10025ms: Process A6 started using the CPU for remaining 375ms of 759ms burst [Q A7 A4 A5 A0 A3 A1]
time 10153ms: Time slice expired; preempting process A6 with 247ms remaining [Q A7 A4 A5 A0 A3 A1]
time 10159ms: Process A7 started using the CPU for 604ms burst [Q A4 A5 A0 A3 A1 A6]
time 10287ms: Time slice expired; preempting process A7 with 476ms remaining [Q A4 A5 A0 A3 A1 A6]
time 10293ms: Process A4 started using the CPU for remaining 1188ms of 1572ms burst [Q A5 A0 A3 A1 A6 A7]
time 10421ms: Time slice expired; preempting process A4 with 1060ms remaining [Q A5 A0 A3 A1 A6 A7]
time 10427ms: Process A5 started using the CPU for remaining 764ms of 2428ms burst [Q A0 A3 A1 A6 A7 A4]
time 10555ms: Time slice expired; preempting process A5 with 636ms remaining [Q A0 A3 A1 A6 A7 A4]
time 10561ms: Process A0 started using the CPU for remaining 1272ms of 2552ms burst [Q A3 A1 A6 A7 A4 A5]
time 10689ms: Time slice expired; preempting process A0 with 1144ms remaining [Q A3 A1 A6 A7 A4 A5]
time 10695ms: Process A3 started using the CPU for remaining 3252ms of 3764ms burst [Q A1 A6 A7 A4 A5 A0]
time 10823ms: Time slice expired; preempting process A3 with 3124ms remaining [Q A1 A6 A7 A4 A5 A0]
time 10829ms: Process A1 started using the CPU for remaining 1312ms of 2720ms burst [Q A6 A7 A4 A5 A0 A3]
time 10957ms: Time slice expired; preempting process A1 with 1184ms remaining [Q A6 A7 A4 A5 A0 A3]
time 10963ms: Process A6 started using the CPU for remaining 247ms of 759ms burst [Q A7 A4 A5 A0 A3 A1]
time 11091ms: Time slice expired; preempting process A6 with 119ms remaining [Q A7 A4 A5 A0 A3 A1]
time 11097ms: Process A7 started using the CPU for remaining 476ms of 604ms burst [Q A4 A5 A0 A3 A1 A6]
time 11225ms: Time slice expired; preempting process A7 with 348ms remaining [Q A4 A5 A0 A3 A1 A6]
time 11231ms: Process A4 started using the CPU for remaining 1060ms of 1572ms burst [Q A5 A0 A3 A1 A6 A7]
time 11359ms: Time slice expired; preempting process A4 with 932ms remaining [Q A5 A0 A3 A1 A6 A7]
time 11365ms: Process A5 started using the CPU for remaining 636ms of 2428ms burst [Q A0 A3 A1 A6 A7 A4]
time 11493ms: Time slice expired; preempting process A5 with 508ms remaining [Q A0 A3 A1 A6 A7 A4]
time 11499ms: Process A0 started using the CPU for remaining 1144ms of 2552ms burst [Q A3 A1 A6 A7 A4 A5]
time 11627ms: Time slice expired; preempting process A0 with 1016ms remaining [Q A3 A1 A6 A7 A4 A5]
time 11633ms: Process A3 started using the CPU for remaining 3124ms of 3764ms burst [Q A1 A6 A7 A4 A5 A0]
time 11761ms: Time slice expired; preempting process A3 with 2996ms remaining [Q A1 A6 A7 A4 A5 A0]
time 11767ms: Process A1 started using the CPU for remaining 1184ms of 2720ms burst [Q A6 A7 A4 A5 A0 A3]
time 11895ms: Time slice expired; preempting process A1 with 1056ms remaining [Q A6 A7 A4 A5 A0 A3]
time 11901ms: Process A6 started using the CPU for remaining 119ms of 759ms burst [Q A7 A4 A5 A0 A3 A1]
time 12020ms: Process A6 completed a CPU burst; 4 bursts to go [Q A7 A4 A5 A0 A3 A1]
time 12020ms: Process A6 switching out of CPU; blocking on I/O until time 16671ms [Q A7 A4 A5 A0 A3 A1]
time 12026ms: Process A7 started using the CPU for remaining 348ms of 604ms burst [Q A4 A5 A0 A3 A1]
time 12154ms: Time slice expired; preempting process A7 with 220ms remaining [Q A4 A5 A0 A3 A1]
time 12160ms: Process A4 started using the CPU for remaining 932ms of 1572ms burst [Q A5 A0 A3 A1 A7]
time 12288ms: Time slice expired; preempting process A4 with 804ms remaining [Q A5 A0 A3 A1 A7]
time 12294ms: Process A5 started using the CPU for remaining 508ms of 2428ms burst [Q A0 A3 A1 A7 A4]
time 12422ms: Time slice expired; preempting process A5 with 380ms remaining [Q A0 A3 A1 A7 A4]
time 12428ms: Process A0 started using the CPU for remaining 1016ms of 2552ms burst [Q A3 A1 A7 A4 A5]
time 12556ms: Time slice expired; preempting process A0 with 888ms remaining [Q A3 A1 A7 A4 A5]
time 12562ms: Process A3 started using the CPU for remaining 2996ms of 3764ms burst [Q A1 A7 A4 A5 A0]
time 12690ms: Time slice expired; preempting process A3 with 2868ms remaining [Q A1 A7 A4 A5 A0]
time 12696ms: Process A1 started using the CPU for remaining 1056ms of 2720ms burst [Q A7 A4 A5 A0 A3]
time 12824ms: Time slice expired; preempting process A1 with 928ms remaining [Q A7 A4 A5 A0 A3]
time 12830ms: Process A7 started using the CPU for remaining 220ms of 604ms burst [Q A4 A5 A0 A3 A1]
time 12958ms: Time slice expired; preempting process A7 with 92ms remaining [Q A4 A5 A0 A3 A1]
time 12964ms: Process A4 started using the CPU for remaining 804ms of 1572ms burst [Q A5 A0 A3 A1 A7]
time 13092ms: Time slice expired; preempting process A4 with 676ms remaining [Q A5 A0 A3 A1 A7]
time 13098ms: Process A5 started using the CPU for remaining 380ms of 2428ms burst [Q A0 A3 A1 A7 A4]
time 13226ms: Time slice expired; preempting process A5 with 252ms remaining [Q A0 A3 A1 A7 A4]
time 13232ms: Process A0 started using the CPU for remaining 888ms of 2552ms burst [Q A3 A1 A7 A4 A5]
time 13360ms: Time slice expired; preempting process A0 with 760ms remaining [Q A3 A1 A7 A4 A5]
time 13366ms: Process A3 started using the CPU for remaining 2868ms of 3764ms burst [Q A1 A7 A4 A5 A0]
time 13494ms: Time slice expired; preempting process A3 with 2740ms remaining [Q A1 A7 A4 A5 A0]
time 13500ms: Process A1 started using the CPU for remaining 928ms of 2720ms burst [Q A7 A4 A5 A0 A3]
time 13628ms: Time slice expired; preempting process A1 with 800ms remaining [Q A7 A4 A5 A0 A3]
time 13634ms: Process A7 started using the CPU for remaining 92ms of 604ms burst [Q A4 A5 A0 A3 A1]
time 13726ms: Process A7 completed a CPU burst; 20 bursts to go [Q A4 A5 A0 A3 A1]
time 13726ms: Process A7 switching out of CPU; blocking on I/O until time 16337ms [Q A4 A5 A0 A3 A1]
time 13732ms: Process A4 started using the CPU for remaining 676ms of 1572ms burst [Q A5 A0 A3 A1]
time 13860ms: Time slice expired; preempting process A4 with 548ms remaining [Q A5 A0 A3 A1]
time 13866ms: Process A5 started using the CPU for remaining 252ms of 2428ms burst [Q A0 A3 A1 A4]
time 13994ms: Time slice expired; preempting process A5 with 124ms remaining [Q A0 A3 A1 A4]
time 14000ms: Process A0 started using the CPU for remaining 760ms of 2552ms burst [Q A3 A1 A4 A5]
time 14128ms: Time slice expired; preempting process A0 with 632ms remaining [Q A3 A1 A4 A5]
time 14134ms: Process A3 started using the CPU for remaining 2740ms of 3764ms burst [Q A1 A4 A5 A0]
time 14262ms: Time slice expired; preempting process A3 with 2612ms remaining [Q A1 A4 A5 A0]
time 14268ms: Process A1 started using the CPU for remaining 800ms of 2720ms burst [Q A4 A5 A0 A3]
time 14396ms: Time slice expired; preempting process A1 with 672ms remaining [Q A4 A5 A0 A3]
time 14402ms: Process A4 started using the CPU for remaining 548ms of 1572ms burst [Q A5 A0 A3 A1]
time 14530ms: Time slice expired; preempting process A4 with 420ms remaining [Q A5 A0 A3 A1]
time 14536ms: Process A5 started using the CPU for remaining 124ms of 2428ms burst [Q A0 A3 A1 A4]
time 14660ms: Process A5 completed a CPU burst; 10 bursts to go [Q A0 A3 A1 A4]
time 14660ms: Process A5 switching out of CPU; blocking on I/O until time 15227ms [Q A0 A3 A1 A4]
time 14666ms: Process A0 started using the CPU for remaining 632ms of 2552ms burst [Q A3 A1 A4]
time 14794ms: Time slice expired; preempting process A0 with 504ms remaining [Q A3 A1 A4]
time 14800ms: Process A3 started using the CPU for remaining 2612ms of 3764ms burst [Q A1 A4 A0]
time 14928ms: Time slice expired; preempting process A3 with 2484ms remaining [Q A1 A4 A0]
time 14934ms: Process A1 started using the CPU for remaining 672ms of 2720ms burst [Q A4 A0 A3]
time 15062ms: Time slice expired; preempting process A1 with 544ms remaining [Q A4 A0 A3]
time 15068ms: Process A4 started using the CPU for remaining 420ms of 1572ms burst [Q A0 A3 A1]
time 15196ms: Time slice expired; preempting process A4 with 292ms remaining [Q A0 A3 A1]
time 15202ms: Process A0 started using the CPU for remaining 504ms of 2552ms burst [Q A3 A1 A4]
time 15227ms: Process A5 completed I/O; added to ready queue [Q A3 A1 A4 A5]
time 15330ms: Time slice expired; preempting process A0 with 376ms remaining [Q A3 A1 A4 A5]
time 15336ms: Process A3 started using the CPU for remaining 2484ms of 3764ms burst [Q A1 A4 A5 A0]
time 15464ms: Time slice expired; preempting process A3 with 2356ms remaining [Q A1 A4 A5 A0]
time 15470ms: Process A1 started using the CPU for remaining 544ms of 2720ms burst [Q A4 A5 A0 A3]
time 15598ms: Time slice expired; preempting process A1 with 416ms remaining [Q A4 A5 A0 A3]
time 15604ms: Process A4 started using the CPU for remaining 292ms of 1572ms burst [Q A5 A0 A3 A1]
time 15732ms: Time slice expired; preempting process A4 with 164ms remaining [Q A5 A0 A3 A1]
time 15738ms: Process A5 started using the CPU for 1096ms burst [Q A0 A3 A1 A4]
time 15866ms: Time slice expired; preempting process A5 with 968ms remaining [Q A0 A3 A1 A4]
time 15872ms: Process A0 started using the CPU for remaining 376ms of 2552ms burst [Q A3 A1 A4 A5]
time 16000ms: Time slice expired; preempting process A0 with 248ms remaining [Q A3 A1 A4 A5]
time 16006ms: Process A3 started using the CPU for remaining 2356ms of 3764ms burst [Q A1 A4 A5 A0]
time 16134ms: Time slice expired; preempting process A3 with 2228ms remaining [Q A1 A4 A5 A0]
time 16140ms: Process A1 started using the CPU for remaining 416ms of 2720ms burst [Q A4 A5 A0 A3]
time 16268ms: Time slice expired; preempting process A1 with 288ms remaining [Q A4 A5 A0 A3]
time 16274ms: Process A4 started using the CPU for remaining 164ms of 1572ms burst [Q A5 A0 A3 A1]
time 16337ms: Process A7 completed I/O; added to ready queue [Q A5 A0 A3 A1 A7]
time 16402ms: Time slice expired; preempting process A4 with 36ms remaining [Q A5 A0 A3 A1 A7]
time 16408ms: Process A5 started using the CPU for remaining 968ms of 1096ms burst [Q A0 A3 A1 A7 A4]
time 16536ms: Time slice expired; preempting process A5 with 840ms remaining [Q A0 A3 A1 A7 A4]
time 16542ms: Process A0 started using the CPU for remaining 248ms of 2552ms burst [Q A3 A1 A7 A4 A5]
time 16670ms: Time slice expired; preempting process A0 with 120ms remaining [Q A3 A1 A7 A4 A5]
time 16671ms: Process A6 completed I/O; added to ready queue [Q A3 A1 A7 A4 A5 A6]
time 16676ms: Process A3 started using the CPU for remaining 2228ms of 3764ms burst [Q A1 A7 A4 A5 A6 A0]
time 16804ms: Time slice expired; preempting process A3 with 2100ms remaining [Q A1 A7 A4 A5 A6 A0]
time 16810ms: Process A1 started using the CPU for remaining 288ms of 2720ms burst [Q A7 A4 A5 A6 A0 A3]
time 16938ms: Time slice expired; preempting process A1 with 160ms remaining [Q A7 A4 A5 A6 A0 A3]
time 16944ms: Process A7 started using the CPU for 811ms burst [Q A4 A5 A6 A0 A3 A1]
time 17072ms: Time slice expired; preempting process A7 with 683ms remaining [Q A4 A5 A6 A0 A3 A1]
time 17078ms: Process A4 started using the CPU for remaining 36ms of 1572ms burst [Q A5 A6 A0 A3 A1 A7]
time 17114ms: Process A4 completed a CPU burst; 16 bursts to go [Q A5 A6 A0 A3 A1 A7]
time 17114ms: Process A4 switching out of CPU; blocking on I/O until time 17612ms [Q A5 A6 A0 A3 A1 A7]
time 17120ms: Process A5 started using the CPU for remaining 840ms of 1096ms burst [Q A6 A0 A3 A1 A7]
time 17248ms: Time slice expired; preempting process A5 with 712ms remaining [Q A6 A0 A3 A1 A7]
time 17254ms: Process A6 started using the CPU for 569ms burst [Q A0 A3 A1 A7 A5]
time 17382ms: Time slice expired; preempting process A6 with 441ms remaining [Q A0 A3 A1 A7 A5]
time 17388ms: Process A0 started using the CPU for remaining 120ms of 2552ms burst [Q A3 A1 A7 A5 A6]
time 17508ms: Process A0 completed a CPU burst; 5 bursts to go [Q A3 A1 A7 A5 A6]
time 17508ms: Process A0 switching out of CPU; blocking on I/O until time 18530ms [Q A3 A1 A7 A5 A6]
time 17514ms: Process A3 started using the CPU for remaining 2100ms of 3764ms burst [Q A1 A7 A5 A6]
time 17612ms: Process A4 completed I/O; added to ready queue [Q A1 A7 A5 A6 A4]
time 17642ms: Time slice expired; preempting process A3 with 1972ms remaining [Q A1 A7 A5 A6 A4]
time 17648ms: Process A1 started using the CPU for remaining 160ms of 2720ms burst [Q A7 A5 A6 A4 A3]
time 17776ms: Time slice expired; preempting process A1 with 32ms remaining [Q A7 A5 A6 A4 A3]
time 17782ms: Process A7 started using the CPU for remaining 683ms of 811ms burst [Q A5 A6 A4 A3 A1]
time 17910ms: Time slice expired; preempting process A7 with 555ms remaining [Q A5 A6 A4 A3 A1]
time 17916ms: Process A5 started using the CPU for remaining 712ms of 1096ms burst [Q A6 A4 A3 A1 A7]
time 18044ms: Time slice expired; preempting process A5 with 584ms remaining [Q A6 A4 A3 A1 A7]
time 18050ms: Process A6 started using the CPU for remaining 441ms of 569ms burst [Q A4 A3 A1 A7 A5]
time 18178ms: Time slice expired; preempting process A6 with 313ms remaining [Q A4 A3 A1 A7 A5]
time 18184ms: Process A4 started using the CPU for 3332ms burst [Q A3 A1 A7 A5 A6]
time 18312ms: Time slice expired; preempting process A4 with 3204ms remaining [Q A3 A1 A7 A5 A6]
time 18318ms: Process A3 started using the CPU for remaining 1972ms of 3764ms burst [Q A1 A7 A5 A6 A4]
time 18446ms: Time slice expired; preempting process A3 with 1844ms remaining [Q A1 A7 A5 A6 A4]
time 18452ms: Process A1 started using the CPU for remaining 32ms of 2720ms burst [Q A7 A5 A6 A4 A3]
time 18484ms: Process A1 completed a CPU burst; 9 bursts to go [Q A7 A5 A6 A4 A3]
time 18484ms: Process A1 switching out of CPU; blocking on I/O until time 19054ms [Q A7 A5 A6 A4 A3]
time 18490ms: Process A7 started using the CPU for remaining 555ms of 811ms burst [Q A5 A6 A4 A3]
time 18530ms: Process A0 completed I/O; added to ready queue [Q A5 A6 A4 A3 A0]
time 18618ms: Time slice expired; preempting process A7 with 427ms remaining [Q A5 A6 A4 A3 A0]
time 18624ms: Process A5 started using the CPU for remaining 584ms of 1096ms burst [Q A6 A4 A3 A0 A7]
time 18752ms: Time slice expired; preempting process A5 with 456ms remaining [Q A6 A4 A3 A0 A7]
time 18758ms: Process A6 started using the CPU for remaining 313ms of 569ms burst [Q A4 A3 A0 A7 A5]
time 18886ms: Time slice expired; preempting process A6 with 185ms remaining [Q A4 A3 A0 A7 A5]
time 18892ms: Process A4 started using the CPU for remaining 3204ms of 3332ms burst [Q A3 A0 A7 A5 A6]
time 19020ms: Time slice expired; preempting process A4 with 3076ms remaining [Q A3 A0 A7 A5 A6]
time 19026ms: Process A3 started using the CPU for remaining 1844ms of 3764ms burst [Q A0 A7 A5 A6 A4]
time 19054ms: Process A1 completed I/O; added to ready queue [Q A0 A7 A5 A6 A4 A1]
time 19154ms: Time slice expired; preempting process A3 with 1716ms remaining [Q A0 A7 A5 A6 A4 A1]
time 19160ms: Process A0 started using the CPU for 1648ms burst [Q A7 A5 A6 A4 A1 A3]
time 19288ms: Time slice expired; preempting process A0 with 1520ms remaining [Q A7 A5 A6 A4 A1 A3]
time 19294ms: Process A7 started using the CPU for remaining 427ms of 811ms burst [Q A5 A6 A4 A1 A3 A0]
time 19422ms: Time slice expired; preempting process A7 with 299ms remaining [Q A5 A6 A4 A1 A3 A0]
time 19428ms: Process A5 started using the CPU for remaining 456ms of 1096ms burst [Q A6 A4 A1 A3 A0 A7]
time 19556ms: Time slice expired; preempting process A5 with 328ms remaining [Q A6 A4 A1 A3 A0 A7]
time 19562ms: Process A6 started using the CPU for remaining 185ms of 569ms burst [Q A4 A1 A3 A0 A7 A5]
time 19690ms: Time slice expired; preempting process A6 with 57ms remaining [Q A4 A1 A3 A0 A7 A5]
time 19696ms: Process A4 started using the CPU for remaining 3076ms of 3332ms burst [Q A1 A3 A0 A7 A5 A6]
time 19824ms: Time slice expired; preempting process A4 with 2948ms remaining [Q A1 A3 A0 A7 A5 A6]
time 19830ms: Process A1 started using the CPU for 924ms burst [Q A3 A0 A7 A5 A6 A4]
time 19958ms: Time slice expired; preempting process A1 with 796ms remaining [Q A3 A0 A7 A5 A6 A4]
time 19964ms: Process A3 started using the CPU for remaining 1716ms of 3764ms burst [Q A0 A7 A5 A6 A4 A1]
time 20092ms: Time slice expired; preempting process A3 with 1588ms remaining [Q A0 A7 A5 A6 A4 A1]
time 20098ms: Process A0 started using the CPU for remaining 1520ms of 1648ms burst [Q A7 A5 A6 A4 A1 A3]
time 20226ms: Time slice expired; preempting process A0 with 1392ms remaining [Q A7 A5 A6 A4 A1 A3]
time 20232ms: Process A7 started using the CPU for remaining 299ms of 811ms burst [Q A5 A6 A4 A1 A3 A0]
time 20360ms: Time slice expired; preempting process A7 with 171ms remaining [Q A5 A6 A4 A1 A3 A0]
time 20366ms: Process A5 started using the CPU for remaining 328ms of 1096ms burst [Q A6 A4 A1 A3 A0 A7]
time 20494ms: Time slice expired; preempting process A5 with 200ms remaining [Q A6 A4 A1 A3 A0 A7]
time 20500ms: Process A6 started using the CPU for remaining 57ms of 569ms burst [Q A4 A1 A3 A0 A7 A5]
time 20557ms: Process A6 completed a CPU burst; 3 bursts to go [Q A4 A1 A3 A0 A7 A5]
time 20557ms: Process A6 switching out of CPU; blocking on I/O until time 24968ms [Q A4 A1 A3 A0 A7 A5]
time 20563ms: Process A4 started using the CPU for remaining 2948ms of 3332ms burst [Q A1 A3 A0 A7 A5]
time 20691ms: Time slice expired; preempting process A4 with 2820ms remaining [Q A1 A3 A0 A7 A5]
time 20697ms: Process A1 started using the CPU for remaining 796ms of 924ms burst [Q A3 A0 A7 A5 A4]
time 20825ms: Time slice expired; preempting process A1 with 668ms remaining [Q A3 A0 A7 A5 A4]
time 20831ms: Process A3 started using the CPU for remaining 1588ms of 3764ms burst [Q A0 A7 A5 A4 A1]
time 20959ms: Time slice expired; preempting process A3 with 1460ms remaining [Q A0 A7 A5 A4 A1]
time 20965ms: Process A0 started using the CPU for remaining 1392ms of 1648ms burst [Q A7 A5 A4 A1 A3]
time 21093ms: Time slice expired; preempting process A0 with 1264ms remaining [Q A7 A5 A4 A1 A3]
time 21099ms: Process A7 started using the CPU for remaining 171ms of 811ms burst [Q A5 A4 A1 A3 A0]
time 21227ms: Time slice expired; preempting process A7 with 43ms remaining [Q A5 A4 A1 A3 A0]
time 21233ms: Process A5 started using the CPU for remaining 200ms of 1096ms burst [Q A4 A1 A3 A0 A7]
time 21361ms: Time slice expired; preempting process A5 with 72ms remaining [Q A4 A1 A3 A0 A7]
time 21367ms: Process A4 started using the CPU for remaining 2820ms of 3332ms burst [Q A1 A3 A0 A7 A5]
time 21495ms: Time slice expired; preempting process A4 with 2692ms remaining [Q A1 A3 A0 A7 A5]
time 21501ms: Process A1 started using the CPU for remaining 668ms of 924ms burst [Q A3 A0 A7 A5 A4]
time 21629ms: Time slice expired; preempting process A1 with 540ms remaining [Q A3 A0 A7 A5 A4]
time 21635ms: Process A3 started using the CPU for remaining 1460ms of 3764ms burst [Q A0 A7 A5 A4 A1]
time 21763ms: Time slice expired; preempting process A3 with 1332ms remaining [Q A0 A7 A5 A4 A1]
time 21769ms: Process A0 started using the CPU for remaining 1264ms of 1648ms burst [Q A7 A5 A4 A1 A3]
time 21897ms: Time slice expired; preempting process A0 with 1136ms remaining [Q A7 A5 A4 A1 A3]
time 21903ms: Process A7 started using the CPU for remaining 43ms of 811ms burst [Q A5 A4 A1 A3 A0]
time 21946ms: Process A7 completed a CPU burst; 19 bursts to go [Q A5 A4 A1 A3 A0]
time 21946ms: Process A7 switching out of CPU; blocking on I/O until time 23005ms [Q A5 A4 A1 A3 A0]
time 21952ms: Process A5 started using the CPU for remaining 72ms of 1096ms burst [Q A4 A1 A3 A0]
time 22024ms: Process A5 completed a CPU burst; 9 bursts to go [Q A4 A1 A3 A0]
time 22024ms: Process A5 switching out of CPU; blocking on I/O until time 22801ms [Q A4 A1 A3 A0]
time 22030ms: Process A4 started using the CPU for remaining 2692ms of 3332ms burst [Q A1 A3 A0]
time 22158ms: Time slice expired; preempting process A4 with 2564ms remaining [Q A1 A3 A0]
time 22164ms: Process A1 started using the CPU for remaining 540ms of 924ms burst [Q A3 A0 A4]
time 22292ms: Time slice expired; preempting process A1 with 412ms remaining [Q A3 A0 A4]
time 22298ms: Process A3 started using the CPU for remaining 1332ms of 3764ms burst [Q A0 A4 A1]
time 22426ms: Time slice expired; preempting process A3 with 1204ms remaining [Q A0 A4 A1]
time 22432ms: Process A0 started using the CPU for remaining 1136ms of 1648ms burst [Q A4 A1 A3]
time 22560ms: Time slice expired; preempting process A0 with 1008ms remaining [Q A4 A1 A3]
time 22566ms: Process A4 started using the CPU for remaining 2564ms of 3332ms burst [Q A1 A3 A0]
time 22694ms: Time slice expired; preempting process A4 with 2436ms remaining [Q A1 A3 A0]
time 22700ms: Process A1 started using the CPU for remaining 412ms of 924ms burst [Q A3 A0 A4]
time 22801ms: Process A5 completed I/O; added to ready queue [Q A3 A0 A4 A5]
time 22828ms: Time slice expired; preempting process A1 with 284ms remaining [Q A3 A0 A4 A5]
time 22834ms: Process A3 started using the CPU for remaining 1204ms of 3764ms burst [Q A0 A4 A5 A1]
time 22962ms: Time slice expired; preempting process A3 with 1076ms remaining [Q A0 A4 A5 A1]
time 22968ms: Process A0 started using the CPU for remaining 1008ms of 1648ms burst [Q A4 A5 A1 A3]
time 23005ms: Process A7 completed I/O; added to ready queue [Q A4 A5 A1 A3 A7]
time 23096ms: Time slice expired; preempting process A0 with 880ms remaining [Q A4 A5 A1 A3 A7]
time 23102ms: Process A4 started using the CPU for remaining 2436ms of 3332ms burst [Q A5 A1 A3 A7 A0]
time 23230ms: Time slice expired; preempting process A4 with 2308ms remaining [Q A5 A1 A3 A7 A0]
time 23236ms: Process A5 started using the CPU for 2652ms burst [Q A1 A3 A7 A0 A4]
time 23364ms: Time slice expired; preempting process A5 with 2524ms remaining [Q A1 A3 A7 A0 A4]
time 23370ms: Process A1 started using the CPU for remaining 284ms of 924ms burst [Q A3 A7 A0 A4 A5]
time 23498ms: Time slice expired; preempting process A1 with 156ms remaining [Q A3 A7 A0 A4 A5]
time 23504ms: Process A3 started using the CPU for remaining 1076ms of 3764ms burst [Q A7 A0 A4 A5 A1]
time 23632ms: Time slice expired; preempting process A3 with 948ms remaining [Q A7 A0 A4 A5 A1]
time 23638ms: Process A7 started using the CPU for 962ms burst [Q A0 A4 A5 A1 A3]
time 23766ms: Time slice expired; preempting process A7 with 834ms remaining [Q A0 A4 A5 A1 A3]
time 23772ms: Process A0 started using the CPU for remaining 880ms of 1648ms burst [Q A4 A5 A1 A3 A7]
time 23900ms: Time slice expired; preempting process A0 with 752ms remaining [Q A4 A5 A1 A3 A7]
time 23906ms: Process A4 started using the CPU for remaining 2308ms of 3332ms burst [Q A5 A1 A3 A7 A0]
time 24034ms: Time slice expired; preempting process A4 with 2180ms remaining [Q A5 A1 A3 A7 A0]
time 24040ms: Process A5 started using the CPU for remaining 2524ms of 2652ms burst [Q A1 A3 A7 A0 A4]
time 24168ms: Time slice expired; preempting process A5 with 2396ms remaining [Q A1 A3 A7 A0 A4]
time 24174ms: Process A1 started using the CPU for remaining 156ms of 924ms burst [Q A3 A7 A0 A4 A5]
time 24302ms: Time slice expired; preempting process A1 with 28ms remaining [Q A3 A7 A0 A4 A5]
time 24308ms: Process A3 started using the CPU for remaining 948ms of 3764ms burst [Q A7 A0 A4 A5 A1]
time 24436ms: Time slice expired; preempting process A3 with 820ms remaining [Q A7 A0 A4 A5 A1]
time 24442ms: Process A7 started using the CPU for remaining 834ms of 962ms burst [Q A0 A4 A5 A1 A3]
time 24570ms: Time slice expired; preempting process A7 with 706ms remaining [Q A0 A4 A5 A1 A3]
time 24576ms: Process A0 started using the CPU for remaining 752ms of 1648ms burst [Q A4 A5 A1 A3 A7]
time 24704ms: Time slice expired; preempting process A0 with 624ms remaining [Q A4 A5 A1 A3 A7]
time 24710ms: Process A4 started using the CPU for remaining 2180ms of 3332ms burst [Q A5 A1 A3 A7 A0]
time 24838ms: Time slice expired; preempting process A4 with 2052ms remaining [Q A5 A1 A3 A7 A0]
time 24844ms: Process A5 started using the CPU for remaining 2396ms of 2652ms burst [Q A1 A3 A7 A0 A4]
time 24968ms: Process A6 completed I/O; added to ready queue [Q A1 A3 A7 A0 A4 A6]
time 24972ms: Time slice expired; preempting process A5 with 2268ms remaining [Q A1 A3 A7 A0 A4 A6]
time 24978ms: Process A1 started using the CPU for remaining 28ms of 924ms burst [Q A3 A7 A0 A4 A6 A5]
time 25006ms: Process A1 completed a CPU burst; 8 bursts to go [Q A3 A7 A0 A4 A6 A5]
time 25006ms: Process A1 switching out of CPU; blocking on I/O until time 25289ms [Q A3 A7 A0 A4 A6 A5]
time 25012ms: Process A3 started using the CPU for remaining 820ms of 3764ms burst [Q A7 A0 A4 A6 A5]
time 25140ms: Time slice expired; preempting process A3 with 692ms remaining [Q A7 A0 A4 A6 A5]
time 25146ms: Process A7 started using the CPU for remaining 706ms of 962ms burst [Q A0 A4 A6 A5 A3]
time 25274ms: Time slice expired; preempting process A7 with 578ms remaining [Q A0 A4 A6 A5 A3]
time 25280ms: Process A0 started using the CPU for remaining 624ms of 1648ms burst [Q A4 A6 A5 A3 A7]
time 25289ms: Process A1 completed I/O; added to ready queue [Q A4 A6 A5 A3 A7 A1]
time 25408ms: Time slice expired; preempting process A0 with 496ms remaining [Q A4 A6 A5 A3 A7 A1]
time 25414ms: Process A4 started using the CPU for remaining 2052ms of 3332ms burst [Q A6 A5 A3 A7 A1 A0]
time 25542ms: Time slice expired; preempting process A4 with 1924ms remaining [Q A6 A5 A3 A7 A1 A0]
time 25548ms: Process A6 started using the CPU for 960ms burst [Q A5 A3 A7 A1 A0 A4]
time 25676ms: Time slice expired; preempting process A6 with 832ms remaining [Q A5 A3 A7 A1 A0 A4]
time 25682ms: Process A5 started using the CPU for remaining 2268ms of 2652ms burst [Q A3 A7 A1 A0 A4 A6]
time 25810ms: Time slice expired; preempting process A5 with 2140ms remaining [Q A3 A7 A1 A0 A4 A6]
time 25816ms: Process A3 started using the CPU for remaining 692ms of 3764ms burst [Q A7 A1 A0 A4 A6 A5]
time 25944ms: Time slice expired; preempting process A3 with 564ms remaining [Q A7 A1 A0 A4 A6 A5]
time 25950ms: Process A7 started using the CPU for remaining 578ms of 962ms burst [Q A1 A0 A4 A6 A5 A3]
time 26078ms: Time slice expired; preempting process A7 with 450ms remaining [Q A1 A0 A4 A6 A5 A3]
time 26084ms: Process A1 started using the CPU for 476ms burst [Q A0 A4 A6 A5 A3 A7]
time 26212ms: Time slice expired; preempting process A1 with 348ms remaining [Q A0 A4 A6 A5 A3 A7]
time 26218ms: Process A0 started using the CPU for remaining 496ms of 1648ms burst [Q A4 A6 A5 A3 A7 A1]
time 26346ms: Time slice expired; preempting process A0 with 368ms remaining [Q A4 A6 A5 A3 A7 A1]
time 26352ms: Process A4 started using the CPU for remaining 1924ms of 3332ms burst [Q A6 A5 A3 A7 A1 A0]
time 26480ms: Time slice expired; preempting process A4 with 1796ms remaining [Q A6 A5 A3 A7 A1 A0]
time 26486ms: Process A6 started using the CPU for remaining 832ms of 960ms burst [Q A5 A3 A7 A1 A0 A4]
time 26614ms: Time slice expired; preempting process A6 with 704ms remaining [Q A5 A3 A7 A1 A0 A4]
time 26620ms: Process A5 started using the CPU for remaining 2140ms of 2652ms burst [Q A3 A7 A1 A0 A4 A6]
time 26748ms: Time slice expired; preempting process A5 with 2012ms remaining [Q A3 A7 A1 A0 A4 A6]
time 26754ms: Process A3 started using the CPU for remaining 564ms of 3764ms burst [Q A7 A1 A0 A4 A6 A5]
time 26882ms: Time slice expired; preempting process A3 with 436ms remaining [Q A7 A1 A0 A4 A6 A5]
time 26888ms: Process A7 started using the CPU for remaining 450ms of 962ms burst [Q A1 A0 A4 A6 A5 A3]
time 27016ms: Time slice expired; preempting process A7 with 322ms remaining [Q A1 A0 A4 A6 A5 A3]
time 27022ms: Process A1 started using the CPU for remaining 348ms of 476ms burst [Q A0 A4 A6 A5 A3 A7]
time 27150ms: Time slice expired; preempting process A1 with 220ms remaining [Q A0 A4 A6 A5 A3 A7]
time 27156ms: Process A0 started using the CPU for remaining 368ms of 1648ms burst [Q A4 A6 A5 A3 A7 A1]
time 27284ms: Time slice expired; preempting process A0 with 240ms remaining [Q A4 A6 A5 A3 A7 A1]
time 27290ms: Process A4 started using the CPU for remaining 1796ms of 3332ms burst [Q A6 A5 A3 A7 A1 A0]
time 27418ms: Time slice expired; preempting process A4 with 1668ms remaining [Q A6 A5 A3 A7 A1 A0]
time 27424ms: Process A6 started using the CPU for remaining 704ms of 960ms burst [Q A5 A3 A7 A1 A0 A4]
time 27552ms: Time slice expired; preempting process A6 with 576ms remaining [Q A5 A3 A7 A1 A0 A4]
time 27558ms: Process A5 started using the CPU for remaining 2012ms of 2652ms burst [Q A3 A7 A1 A0 A4 A6]
time 27686ms: Time slice expired; preempting process A5 with 1884ms remaining [Q A3 A7 A1 A0 A4 A6]
time 27692ms: Process A3 started using the CPU for remaining 436ms of 3764ms burst [Q A7 A1 A0 A4 A6 A5]
time 27820ms: Time slice expired; preempting process A3 with 308ms remaining [Q A7 A1 A0 A4 A6 A5]
time 27826ms: Process A7 started using the CPU for remaining 322ms of 962ms burst [Q A1 A0 A4 A6 A5 A3]
time 27954ms: Time slice expired; preempting process A7 with 194ms remaining [Q A1 A0 A4 A6 A5 A3]
time 27960ms: Process A1 started using the CPU for remaining 220ms of 476ms burst [Q A0 A4 A6 A5 A3 A7]
time 28088ms: Time slice expired; preempting process A1 with 92ms remaining [Q A0 A4 A6 A5 A3 A7]
time 28094ms: Process A0 started using the CPU for remaining 240ms of 1648ms burst [Q A4 A6 A5 A3 A7 A1]
time 28222ms: Time slice expired; preempting process A0 with 112ms remaining [Q A4 A6 A5 A3 A7 A1]
time 28228ms: Process A4 started using the CPU for remaining 1668ms of 3332ms burst [Q A6 A5 A3 A7 A1 A0]
time 28356ms: Time slice expired; preempting process A4 with 1540ms remaining [Q A6 A5 A3 A7 A1 A0]
time 28362ms: Process A6 started using the CPU for remaining 576ms of 960ms burst [Q A5 A3 A7 A1 A0 A4]
time 28490ms: Time slice expired; preempting process A6 with 448ms remaining [Q A5 A3 A7 A1 A0 A4]
time 28496ms: Process A5 started using the CPU for remaining 1884ms of 2652ms burst [Q A3 A7 A1 A0 A4 A6]
time 28624ms: Time slice expired; preempting process A5 with 1756ms remaining [Q A3 A7 A1 A0 A4 A6]
time 28630ms: Process A3 started using the CPU for remaining 308ms of 3764ms burst [Q A7 A1 A0 A4 A6 A5]
time 28758ms: Time slice expired; preempting process A3 with 180ms remaining [Q A7 A1 A0 A4 A6 A5]
time 28764ms: Process A7 started using the CPU for remaining 194ms of 962ms burst [Q A1 A0 A4 A6 A5 A3]
time 28892ms: Time slice expired; preempting process A7 with 66ms remaining [Q A1 A0 A4 A6 A5 A3]
time 28898ms: Process A1 started using the CPU for remaining 92ms of 476ms burst [Q A0 A4 A6 A5 A3 A7]
time 28990ms: Process A1 completed a CPU burst; 7 bursts to go [Q A0 A4 A6 A5 A3 A7]
time 28990ms: Process A1 switching out of CPU; blocking on I/O until time 29017ms [Q A0 A4 A6 A5 A3 A7]
time 28996ms: Process A0 started using the CPU for remaining 112ms of 1648ms burst [Q A4 A6 A5 A3 A7]
time 29017ms: Process A1 completed I/O; added to ready queue [Q A4 A6 A5 A3 A7 A1]
time 29108ms: Process A0 completed a CPU burst; 4 bursts to go [Q A4 A6 A5 A3 A7 A1]
time 29108ms: Process A0 switching out of CPU; blocking on I/O until time 29483ms [Q A4 A6 A5 A3 A7 A1]
time 29114ms: Process A4 started using the CPU for remaining 1540ms of 3332ms burst [Q A6 A5 A3 A7 A1]
time 29242ms: Time slice expired; preempting process A4 with 1412ms remaining [Q A6 A5 A3 A7 A1]
time 29248ms: Process A6 started using the CPU for remaining 448ms of 960ms burst [Q A5 A3 A7 A1 A4]
time 29376ms: Time slice expired; preempting process A6 with 320ms remaining [Q A5 A3 A7 A1 A4]
time 29382ms: Process A5 started using the CPU for remaining 1756ms of 2652ms burst [Q A3 A7 A1 A4 A6]
time 29483ms: Process A0 completed I/O; added to ready queue [Q A3 A7 A1 A4 A6 A0]
time 29510ms: Time slice expired; preempting process A5 with 1628ms remaining [Q A3 A7 A1 A4 A6 A0]
time 29516ms: Process A3 started using the CPU for remaining 180ms of 3764ms burst [Q A7 A1 A4 A6 A0 A5]
time 29644ms: Time slice expired; preempting process A3 with 52ms remaining [Q A7 A1 A4 A6 A0 A5]
time 29650ms: Process A7 started using the CPU for remaining 66ms of 962ms burst [Q A1 A4 A6 A0 A5 A3]
time 29716ms: Process A7 completed a CPU burst; 18 bursts to go [Q A1 A4 A6 A0 A5 A3]
time 29716ms: Process A7 switching out of CPU; blocking on I/O until time 29775ms [Q A1 A4 A6 A0 A5 A3]
time 29722ms: Process A1 started using the CPU for 752ms burst [Q A4 A6 A0 A5 A3]
time 29775ms: Process A7 completed I/O; added to ready queue [Q A4 A6 A0 A5 A3 A7]
time 29850ms: Time slice expired; preempting process A1 with 624ms remaining [Q A4 A6 A0 A5 A3 A7]
time 29856ms: Process A4 started using the CPU for remaining 1412ms of 3332ms burst [Q A6 A0 A5 A3 A7 A1]
time 29984ms: Time slice expired; preempting process A4 with 1284ms remaining [Q A6 A0 A5 A3 A7 A1]
time 29990ms: Process A6 started using the CPU for remaining 320ms of 960ms burst [Q A0 A5 A3 A7 A1 A4]
time 30118ms: Time slice expired; preempting process A6 with 192ms remaining [Q A0 A5 A3 A7 A1 A4]
time 30124ms: Process A0 started using the CPU for 952ms burst [Q A5 A3 A7 A1 A4 A6]
time 30252ms: Time slice expired; preempting process A0 with 824ms remaining [Q A5 A3 A7 A1 A4 A6]
time 30258ms: Process A5 started using the CPU for remaining 1628ms of 2652ms burst [Q A3 A7 A1 A4 A6 A0]
time 30386ms: Time slice expired; preempting process A5 with 1500ms remaining [Q A3 A7 A1 A4 A6 A0]
time 30392ms: Process A3 started using the CPU for remaining 52ms of 3764ms burst [Q A7 A1 A4 A6 A0 A5]
time 30444ms: Process A3 completed a CPU burst; 4 bursts to go [Q A7 A1 A4 A6 A0 A5]
time 30444ms: Process A3 switching out of CPU; blocking on I/O until time 30811ms [Q A7 A1 A4 A6 A0 A5]
time 30450ms: Process A7 started using the CPU for 93ms burst [Q A1 A4 A6 A0 A5]
time 30543ms: Process A7 completed a CPU burst; 17 bursts to go [Q A1 A4 A6 A0 A5]
time 30543ms: Process A7 switching out of CPU; blocking on I/O until time 33050ms [Q A1 A4 A6 A0 A5]
time 30549ms: Process A1 started using the CPU for remaining 624ms of 752ms burst [Q A4 A6 A0 A5]
time 30677ms: Time slice expired; preempting process A1 with 496ms remaining [Q A4 A6 A0 A5]
time 30683ms: Process A4 started using the CPU for remaining 1284ms of 3332ms burst [Q A6 A0 A5 A1]
time 30811ms: Time slice expired; preempting process A4 with 1156ms remaining [Q A6 A0 A5 A1]
time 30811ms: Process A3 completed I/O; added to ready queue [Q A6 A0 A5 A1 A3]
time 30817ms: Process A6 started using the CPU for remaining 192ms of 960ms burst [Q A0 A5 A1 A3 A4]
time 30945ms: Time slice expired; preempting process A6 with 64ms remaining [Q A0 A5 A1 A3 A4]
time 30951ms: Process A0 started using the CPU for remaining 824ms of 952ms burst [Q A5 A1 A3 A4 A6]
time 31079ms: Time slice expired; preempting process A0 with 696ms remaining [Q A5 A1 A3 A4 A6]
time 31085ms: Process A5 started using the CPU for remaining 1500ms of 2652ms burst [Q A1 A3 A4 A6 A0]
time 31213ms: Time slice expired; preempting process A5 with 1372ms remaining [Q A1 A3 A4 A6 A0]
time 31219ms: Process A1 started using the CPU for remaining 496ms of 752ms burst [Q A3 A4 A6 A0 A5]
time 31347ms: Time slice expired; preempting process A1 with 368ms remaining [Q A3 A4 A6 A0 A5]
time 31353ms: Process A3 started using the CPU for 364ms burst [Q A4 A6 A0 A5 A1]
time 31481ms: Time slice expired; preempting process A3 with 236ms remaining [Q A4 A6 A0 A5 A1]
time 31487ms: Process A4 started using the CPU for remaining 1156ms of 3332ms burst [Q A6 A0 A5 A1 A3]
time 31615ms: Time slice expired; preempting process A4 with 1028ms remaining [Q A6 A0 A5 A1 A3]
time 31621ms: Process A6 started using the CPU for remaining 64ms of 960ms burst [Q A0 A5 A1 A3 A4]
time 31685ms: Process A6 completed a CPU burst; 2 bursts to go [Q A0 A5 A1 A3 A4]
time 31685ms: Process A6 switching out of CPU; blocking on I/O until time 36272ms [Q A0 A5 A1 A3 A4]
time 31691ms: Process A0 started using the CPU for remaining 696ms of 952ms burst [Q A5 A1 A3 A4]
time 31819ms: Time slice expired; preempting process A0 with 568ms remaining [Q A5 A1 A3 A4]
time 31825ms: Process A5 started using the CPU for remaining 1372ms of 2652ms burst [Q A1 A3 A4 A0]
time 31953ms: Time slice expired; preempting process A5 with 1244ms remaining [Q A1 A3 A4 A0]
time 31959ms: Process A1 started using the CPU for remaining 368ms of 752ms burst [Q A3 A4 A0 A5]
time 32087ms: Time slice expired; preempting process A1 with 240ms remaining [Q A3 A4 A0 A5]
time 32093ms: Process A3 started using the CPU for remaining 236ms of 364ms burst [Q A4 A0 A5 A1]
time 32221ms: Time slice expired; preempting process A3 with 108ms remaining [Q A4 A0 A5 A1]
time 32227ms: Process A4 started using the CPU for remaining 1028ms of 3332ms burst [Q A0 A5 A1 A3]
time 32355ms: Time slice expired; preempting process A4 with 900ms remaining [Q A0 A5 A1 A3]
time 32361ms: Process A0 started using the CPU for remaining 568ms of 952ms burst [Q A5 A1 A3 A4]
time 32489ms: Time slice expired; preempting process A0 with 440ms remaining [Q A5 A1 A3 A4]
time 32495ms: Process A5 started using the CPU for remaining 1244ms of 2652ms burst [Q A1 A3 A4 A0]
time 32623ms: Time slice expired; preempting process A5 with 1116ms remaining [Q A1 A3 A4 A0]
time 32629ms: Process A1 started using the CPU for remaining 240ms of 752ms burst [Q A3 A4 A0 A5]
time 32757ms: Time slice expired; preempting process A1 with 112ms remaining [Q A3 A4 A0 A5]
time 32763ms: Process A3 started using the CPU for remaining 108ms of 364ms burst [Q A4 A0 A5 A1]
time 32871ms: Process A3 completed a CPU burst; 3 bursts to go [Q A4 A0 A5 A1]
time 32871ms: Process A3 switching out of CPU; blocking on I/O until time 32899ms [Q A4 A0 A5 A1]
time 32877ms: Process A4 started using the CPU for remaining 900ms of 3332ms burst [Q A0 A5 A1]
time 32899ms: Process A3 completed I/O; added to ready queue [Q A0 A5 A1 A3]
time 33005ms: Time slice expired; preempting process A4 with 772ms remaining [Q A0 A5 A1 A3]
time 33011ms: Process A0 started using the CPU for remaining 440ms of 952ms burst [Q A5 A1 A3 A4]
time 33050ms: Process A7 completed I/O; added to ready queue [Q A5 A1 A3 A4 A7]
time 33139ms: Time slice expired; preempting process A0 with 312ms remaining [Q A5 A1 A3 A4 A7]
time 33145ms: Process A5 started using the CPU for remaining 1116ms of 2652ms burst [Q A1 A3 A4 A7 A0]
time 33273ms: Time slice expired; preempting process A5 with 988ms remaining [Q A1 A3 A4 A7 A0]
time 33279ms: Process A1 started using the CPU for remaining 112ms of 752ms burst [Q A3 A4 A7 A0 A5]
time 33391ms: Process A1 completed a CPU burst; 6 bursts to go [Q A3 A4 A7 A0 A5]
time 33391ms: Process A1 switching out of CPU; blocking on I/O until time 33791ms [Q A3 A4 A7 A0 A5]
time 33397ms: Process A3 started using the CPU for 2520ms burst [Q A4 A7 A0 A5]
time 33525ms: Time slice expired; preempting process A3 with 2392ms remaining [Q A4 A7 A0 A5]
time 33531ms: Process A4 started using the CPU for remaining 772ms of 3332ms burst [Q A7 A0 A5 A3]
time 33659ms: Time slice expired; preempting process A4 with 644ms remaining [Q A7 A0 A5 A3]
time 33665ms: Process A7 started using the CPU for 195ms burst [Q A0 A5 A3 A4]
time 33791ms: Process A1 completed I/O; added to ready queue [Q A0 A5 A3 A4 A1]
time 33793ms: Time slice expired; preempting process A7 with 67ms remaining [Q A0 A5 A3 A4 A1]
time 33799ms: Process A0 started using the CPU for remaining 312ms of 952ms burst [Q A5 A3 A4 A1 A7]
time 33927ms: Time slice expired; preempting process A0 with 184ms remaining [Q A5 A3 A4 A1 A7]
time 33933ms: Process A5 started using the CPU for remaining 988ms of 2652ms burst [Q A3 A4 A1 A7 A0]
time 34061ms: Time slice expired; preempting process A5 with 860ms remaining [Q A3 A4 A1 A7 A0]
time 34067ms: Process A3 started using the CPU for remaining 2392ms of 2520ms burst [Q A4 A1 A7 A0 A5]
time 34195ms: Time slice expired; preempting process A3 with 2264ms remaining [Q A4 A1 A7 A0 A5]
time 34201ms: Process A4 started using the CPU for remaining 644ms of 3332ms burst [Q A1 A7 A0 A5 A3]
time 34329ms: Time slice expired; preempting process A4 with 516ms remaining [Q A1 A7 A0 A5 A3]
time 34335ms: Process A1 started using the CPU for 3896ms burst [Q A7 A0 A5 A3 A4]
time 34463ms: Time slice expired; preempting process A1 with 3768ms remaining [Q A7 A0 A5 A3 A4]
time 34469ms: Process A7 started using the CPU for remaining 67ms of 195ms burst [Q A0 A5 A3 A4 A1]
time 34536ms: Process A7 completed a CPU burst; 16 bursts to go [Q A0 A5 A3 A4 A1]
time 34536ms: Process A7 switching out of CPU; blocking on I/O until time 35411ms [Q A0 A5 A3 A4 A1]
time 34542ms: Process A0 started using the CPU for remaining 184ms of 952ms burst [Q A5 A3 A4 A1]
time 34670ms: Time slice expired; preempting process A0 with 56ms remaining [Q A5 A3 A4 A1]
time 34676ms: Process A5 started using the CPU for remaining 860ms of 2652ms burst [Q A3 A4 A1 A0]
time 34804ms: Time slice expired; preempting process A5 with 732ms remaining [Q A3 A4 A1 A0]
time 34810ms: Process A3 started using the CPU for remaining 2264ms of 2520ms burst [Q A4 A1 A0 A5]
time 34938ms: Time slice expired; preempting process A3 with 2136ms remaining [Q A4 A1 A0 A5]
time 34944ms: Process A4 started using the CPU for remaining 516ms of 3332ms burst [Q A1 A0 A5 A3]
time 35072ms: Time slice expired; preempting process A4 with 388ms remaining [Q A1 A0 A5 A3]
time 35078ms: Process A1 started using the CPU for remaining 3768ms of 3896ms burst [Q A0 A5 A3 A4]
time 35206ms: Time slice expired; preempting process A1 with 3640ms remaining [Q A0 A5 A3 A4]
time 35212ms: Process A0 started using the CPU for remaining 56ms of 952ms burst [Q A5 A3 A4 A1]
time 35268ms: Process A0 completed a CPU burst; 3 bursts to go [Q A5 A3 A4 A1]
time 35268ms: Process A0 switching out of CPU; blocking on I/O until time 35388ms [Q A5 A3 A4 A1]
time 35274ms: Process A5 started using the CPU for remaining 732ms of 2652ms burst [Q A3 A4 A1]
time 35388ms: Process A0 completed I/O; added to ready queue [Q A3 A4 A1 A0]
time 35402ms: Time slice expired; preempting process A5 with 604ms remaining [Q A3 A4 A1 A0]
time 35408ms: Process A3 started using the CPU for remaining 2136ms of 2520ms burst [Q A4 A1 A0 A5]
time 35411ms: Process A7 completed I/O; added to ready queue [Q A4 A1 A0 A5 A7]
time 35536ms: Time slice expired; preempting process A3 with 2008ms remaining [Q A4 A1 A0 A5 A7]
time 35542ms: Process A4 started using the CPU for remaining 388ms of 3332ms burst [Q A1 A0 A5 A7 A3]
time 35670ms: Time slice expired; preempting process A4 with 260ms remaining [Q A1 A0 A5 A7 A3]
time 35676ms: Process A1 started using the CPU for remaining 3640ms of 3896ms burst [Q A0 A5 A7 A3 A4]
time 35804ms: Time slice expired; preempting process A1 with 3512ms remaining [Q A0 A5 A7 A3 A4]
time 35810ms: Process A0 started using the CPU for 908ms burst [Q A5 A7 A3 A4 A1]
time 35938ms: Time slice expired; preempting process A0 with 780ms remaining [Q A5 A7 A3 A4 A1]
time 35944ms: Process A5 started using the CPU for remaining 604ms of 2652ms burst [Q A7 A3 A4 A1 A0]
time 36072ms: Time slice expired; preempting process A5 with 476ms remaining [Q A7 A3 A4 A1 A0]
time 36078ms: Process A7 started using the CPU for 131ms burst [Q A3 A4 A1 A0 A5]
time 36206ms: Time slice expired; preempting process A7 with 3ms remaining [Q A3 A4 A1 A0 A5]
time 36212ms: Process A3 started using the CPU for remaining 2008ms of 2520ms burst [Q A4 A1 A0 A5 A7]
time 36272ms: Process A6 completed I/O; added to ready queue [Q A4 A1 A0 A5 A7 A6]
time 36340ms: Time slice expired; preempting process A3 with 1880ms remaining [Q A4 A1 A0 A5 A7 A6]
time 36346ms: Process A4 started using the CPU for remaining 260ms of 3332ms burst [Q A1 A0 A5 A7 A6 A3]
time 36474ms: Time slice expired; preempting process A4 with 132ms remaining [Q A1 A0 A5 A7 A6 A3]
time 36480ms: Process A1 started using the CPU for remaining 3512ms of 3896ms burst [Q A0 A5 A7 A6 A3 A4]
time 36608ms: Time slice expired; preempting process A1 with 3384ms remaining [Q A0 A5 A7 A6 A3 A4]
time 36614ms: Process A0 started using the CPU for remaining 780ms of 908ms burst [Q A5 A7 A6 A3 A4 A1]
time 36742ms: Time slice expired; preempting process A0 with 652ms remaining [Q A5 A7 A6 A3 A4 A1]
time 36748ms: Process A5 started using the CPU for remaining 476ms of 2652ms burst [Q A7 A6 A3 A4 A1 A0]
time 36876ms: Time slice expired; preempting process A5 with 348ms remaining [Q A7 A6 A3 A4 A1 A0]
time 36882ms: Process A7 started using the CPU for remaining 3ms of 131ms burst [Q A6 A3 A4 A1 A0 A5]
time 36885ms: Process A7 completed a CPU burst; 15 bursts to go [Q A6 A3 A4 A1 A0 A5]
time 36885ms: Process A7 switching out of CPU; blocking on I/O until time 38272ms [Q A6 A3 A4 A1 A0 A5]
time 36891ms: Process A6 started using the CPU for 977ms burst [Q A3 A4 A1 A0 A5]
time 37019ms: Time slice expired; preempting process A6 with 849ms remaining [Q A3 A4 A1 A0 A5]
time 37025ms: Process A3 started using the CPU for remaining 1880ms of 2520ms burst [Q A4 A1 A0 A5 A6]
time 37153ms: Time slice expired; preempting process A3 with 1752ms remaining [Q A4 A1 A0 A5 A6]
time 37159ms: Process A4 started using the CPU for remaining 132ms of 3332ms burst [Q A1 A0 A5 A6 A3]
time 37287ms: Time slice expired; preempting process A4 with 4ms remaining [Q A1 A0 A5 A6 A3]
time 37293ms: Process A1 started using the CPU for remaining 3384ms of 3896ms burst [Q A0 A5 A6 A3 A4]
time 37421ms: Time slice expired; preempting process A1 with 3256ms remaining [Q A0 A5 A6 A3 A4]
time 37427ms: Process A0 started using the CPU for remaining 652ms of 908ms burst [Q A5 A6 A3 A4 A1]
time 37555ms: Time slice expired; preempting process A0 with 524ms remaining [Q A5 A6 A3 A4 A1]
time 37561ms: Process A5 started using the CPU for remaining 348ms of 2652ms burst [Q A6 A3 A4 A1 A0]
time 37689ms: Time slice expired; preempting process A5 with 220ms remaining [Q A6 A3 A4 A1 A0]
time 37695ms: Process A6 started using the CPU for remaining 849ms of 977ms burst [Q A3 A4 A1 A0 A5]
time 37823ms: Time slice expired; preempting process A6 with 721ms remaining [Q A3 A4 A1 A0 A5]
time 37829ms: Process A3 started using the CPU for remaining 1752ms of 2520ms burst [Q A4 A1 A0 A5 A6]
time 37957ms: Time slice expired; preempting process A3 with 1624ms remaining [Q A4 A1 A0 A5 A6]
time 37963ms: Process A4 started using the CPU for remaining 4ms of 3332ms burst [Q A1 A0 A5 A6 A3]
time 37967ms: Process A4 completed a CPU burst; 15 bursts to go [Q A1 A0 A5 A6 A3]
time 37967ms: Process A4 switching out of CPU; blocking on I/O until time 38027ms [Q A1 A0 A5 A6 A3]
time 37973ms: Process A1 started using the CPU for remaining 3256ms of 3896ms burst [Q A0 A5 A6 A3]
time 38027ms: Process A4 completed I/O; added to ready queue [Q A0 A5 A6 A3 A4]
time 38101ms: Time slice expired; preempting process A1 with 3128ms remaining [Q A0 A5 A6 A3 A4]
time 38107ms: Process A0 started using the CPU for remaining 524ms of 908ms burst [Q A5 A6 A3 A4 A1]
time 38235ms: Time slice expired; preempting process A0 with 396ms remaining [Q A5 A6 A3 A4 A1]
time 38241ms: Process A5 started using the CPU for remaining 220ms of 2652ms burst [Q A6 A3 A4 A1 A0]
time 38272ms: Process A7 completed I/O; added to ready queue [Q A6 A3 A4 A1 A0 A7]
time 38369ms: Time slice expired; preempting process A5 with 92ms remaining [Q A6 A3 A4 A1 A0 A7]
time 38375ms: Process A6 started using the CPU for remaining 721ms of 977ms burst [Q A3 A4 A1 A0 A7 A5]
time 38503ms: Time slice expired; preempting process A6 with 593ms remaining [Q A3 A4 A1 A0 A7 A5]
time 38509ms: Process A3 started using the CPU for remaining 1624ms of 2520ms burst [Q A4 A1 A0 A7 A5 A6]
time 38637ms: Time slice expired; preempting process A3 with 1496ms remaining [Q A4 A1 A0 A7 A5 A6]
time 38643ms: Process A4 started using the CPU for 1460ms burst [Q A1 A0 A7 A5 A6 A3]
time 38771ms: Time slice expired; preempting process A4 with 1332ms remaining [Q A1 A0 A7 A5 A6 A3]
time 38777ms: Process A1 started using the CPU for remaining 3128ms of 3896ms burst [Q A0 A7 A5 A6 A3 A4]
time 38905ms: Time slice expired; preempting process A1 with 3000ms remaining [Q A0 A7 A5 A6 A3 A4]
time 38911ms: Process A0 started using the CPU for remaining 396ms of 908ms burst [Q A7 A5 A6 A3 A4 A1]
time 39039ms: Time slice expired; preempting process A0 with 268ms remaining [Q A7 A5 A6 A3 A4 A1]
time 39045ms: Process A7 started using the CPU for 211ms burst [Q A5 A6 A3 A4 A1 A0]
time 39173ms: Time slice expired; preempting process A7 with 83ms remaining [Q A5 A6 A3 A4 A1 A0]
time 39179ms: Process A5 started using the CPU for remaining 92ms of 2652ms burst [Q A6 A3 A4 A1 A0 A7]
time 39271ms: Process A5 completed a CPU burst; 8 bursts to go [Q A6 A3 A4 A1 A0 A7]
time 39271ms: Process A5 switching out of CPU; blocking on I/O until time 39472ms [Q A6 A3 A4 A1 A0 A7]
time 39277ms: Process A6 started using the CPU for remaining 593ms of 977ms burst [Q A3 A4 A1 A0 A7]
time 39405ms: Time slice expired; preempting process A6 with 465ms remaining [Q A3 A4 A1 A0 A7]
time 39411ms: Process A3 started using the CPU for remaining 1496ms of 2520ms burst [Q A4 A1 A0 A7 A6]
time 39472ms: Process A5 completed I/O; added to ready queue [Q A4 A1 A0 A7 A6 A5]
time 39539ms: Time slice expired; preempting process A3 with 1368ms remaining [Q A4 A1 A0 A7 A6 A5]
time 39545ms: Process A4 started using the CPU for remaining 1332ms of 1460ms burst [Q A1 A0 A7 A6 A5 A3]
time 39673ms: Time slice expired; preempting process A4 with 1204ms remaining [Q A1 A0 A7 A6 A5 A3]
time 39679ms: Process A1 started using the CPU for remaining 3000ms of 3896ms burst [Q A0 A7 A6 A5 A3 A4]
time 39807ms: Time slice expired; preempting process A1 with 2872ms remaining [Q A0 A7 A6 A5 A3 A4]
time 39813ms: Process A0 started using the CPU for remaining 268ms of 908ms burst [Q A7 A6 A5 A3 A4 A1]
time 39941ms: Time slice expired; preempting process A0 with 140ms remaining [Q A7 A6 A5 A3 A4 A1]
time 39947ms: Process A7 started using the CPU for remaining 83ms of 211ms burst [Q A6 A5 A3 A4 A1 A0]
time 40030ms: Process A7 completed a CPU burst; 14 bursts to go [Q A6 A5 A3 A4 A1 A0]
time 40030ms: Process A7 switching out of CPU; blocking on I/O until time 44273ms [Q A6 A5 A3 A4 A1 A0]
time 40036ms: Process A6 started using the CPU for remaining 465ms of 977ms burst [Q A5 A3 A4 A1 A0]
time 40164ms: Time slice expired; preempting process A6 with 337ms remaining [Q A5 A3 A4 A1 A0]
time 40170ms: Process A5 started using the CPU for 1060ms burst [Q A3 A4 A1 A0 A6]
time 40298ms: Time slice expired; preempting process A5 with 932ms remaining [Q A3 A4 A1 A0 A6]
time 40304ms: Process A3 started using the CPU for remaining 1368ms of 2520ms burst [Q A4 A1 A0 A6 A5]
time 40432ms: Time slice expired; preempting process A3 with 1240ms remaining [Q A4 A1 A0 A6 A5]
time 40438ms: Process A4 started using the CPU for remaining 1204ms of 1460ms burst [Q A1 A0 A6 A5 A3]
time 40566ms: Time slice expired; preempting process A4 with 1076ms remaining [Q A1 A0 A6 A5 A3]
time 40572ms: Process A1 started using the CPU for remaining 2872ms of 3896ms burst [Q A0 A6 A5 A3 A4]
time 40700ms: Time slice expired; preempting process A1 with 2744ms remaining [Q A0 A6 A5 A3 A4]
time 40706ms: Process A0 started using the CPU for remaining 140ms of 908ms burst [Q A6 A5 A3 A4 A1]
time 40834ms: Time slice expired; preempting process A0 with 12ms remaining [Q A6 A5 A3 A4 A1]
time 40840ms: Process A6 started using the CPU for remaining 337ms of 977ms burst [Q A5 A3 A4 A1 A0]
time 40968ms: Time slice expired; preempting process A6 with 209ms remaining [Q A5 A3 A4 A1 A0]
time 40974ms: Process A5 started using the CPU for remaining 932ms of 1060ms burst [Q A3 A4 A1 A0 A6]
time 41102ms: Time slice expired; preempting process A5 with 804ms remaining [Q A3 A4 A1 A0 A6]
time 41108ms: Process A3 started using the CPU for remaining 1240ms of 2520ms burst [Q A4 A1 A0 A6 A5]
time 41236ms: Time slice expired; preempting process A3 with 1112ms remaining [Q A4 A1 A0 A6 A5]
time 41242ms: Process A4 started using the CPU for remaining 1076ms of 1460ms burst [Q A1 A0 A6 A5 A3]
time 41370ms: Time slice expired; preempting process A4 with 948ms remaining [Q A1 A0 A6 A5 A3]
time 41376ms: Process A1 started using the CPU for remaining 2744ms of 3896ms burst [Q A0 A6 A5 A3 A4]
time 41504ms: Time slice expired; preempting process A1 with 2616ms remaining [Q A0 A6 A5 A3 A4]
time 41510ms: Process A0 started using the CPU for remaining 12ms of 908ms burst [Q A6 A5 A3 A4 A1]
time 41522ms: Process A0 completed a CPU burst; 2 bursts to go [Q A6 A5 A3 A4 A1]
time 41522ms: Process A0 switching out of CPU; blocking on I/O until time 42123ms [Q A6 A5 A3 A4 A1]
time 41528ms: Process A6 started using the CPU for remaining 209ms of 977ms burst [Q A5 A3 A4 A1]
time 41656ms: Time slice expired; preempting process A6 with 81ms remaining [Q A5 A3 A4 A1]
time 41662ms: Process A5 started using the CPU for remaining 804ms of 1060ms burst [Q A3 A4 A1 A6]
time 41790ms: Time slice expired; preempting process A5 with 676ms remaining [Q A3 A4 A1 A6]
time 41796ms: Process A3 started using the CPU for remaining 1112ms of 2520ms burst [Q A4 A1 A6 A5]
time 41924ms: Time slice expired; preempting process A3 with 984ms remaining [Q A4 A1 A6 A5]
time 41930ms: Process A4 started using the CPU for remaining 948ms of 1460ms burst [Q A1 A6 A5 A3]
time 42058ms: Time slice expired; preempting process A4 with 820ms remaining [Q A1 A6 A5 A3]
time 42064ms: Process A1 started using the CPU for remaining 2616ms of 3896ms burst [Q A6 A5 A3 A4]
time 42123ms: Process A0 completed I/O; added to ready queue [Q A6 A5 A3 A4 A0]
time 42192ms: Time slice expired; preempting process A1 with 2488ms remaining [Q A6 A5 A3 A4 A0]
time 42198ms: Process A6 started using the CPU for remaining 81ms of 977ms burst [Q A5 A3 A4 A0 A1]
time 42279ms: Process A6 completed a CPU burst; 1 burst to go [Q A5 A3 A4 A0 A1]
time 42279ms: Process A6 switching out of CPU; blocking on I/O until time 43970ms [Q A5 A3 A4 A0 A1]
time 42285ms: Process A5 started using the CPU for remaining 676ms of 1060ms burst [Q A3 A4 A0 A1]
time 42413ms: Time slice expired; preempting process A5 with 548ms remaining [Q A3 A4 A0 A1]
time 42419ms: Process A3 started using the CPU for remaining 984ms of 2520ms burst [Q A4 A0 A1 A5]
time 42547ms: Time slice expired; preempting process A3 with 856ms remaining [Q A4 A0 A1 A5]
time 42553ms: Process A4 started using the CPU for remaining 820ms of 1460ms burst [Q A0 A1 A5 A3]
time 42681ms: Time slice expired; preempting process A4 with 692ms remaining [Q A0 A1 A5 A3]
time 42687ms: Process A0 started using the CPU for 516ms burst [Q A1 A5 A3 A4]
time 42815ms: Time slice expired; preempting process A0 with 388ms remaining [Q A1 A5 A3 A4]
time 42821ms: Process A1 started using the CPU for remaining 2488ms of 3896ms burst [Q A5 A3 A4 A0]
time 42949ms: Time slice expired; preempting process A1 with 2360ms remaining [Q A5 A3 A4 A0]
time 42955ms: Process A5 started using the CPU for remaining 548ms of 1060ms burst [Q A3 A4 A0 A1]
time 43083ms: Time slice expired; preempting process A5 with 420ms remaining [Q A3 A4 A0 A1]
time 43089ms: Process A3 started using the CPU for remaining 856ms of 2520ms burst [Q A4 A0 A1 A5]
time 43217ms: Time slice expired; preempting process A3 with 728ms remaining [Q A4 A0 A1 A5]
time 43223ms: Process A4 started using the CPU for remaining 692ms of 1460ms burst [Q A0 A1 A5 A3]
time 43351ms: Time slice expired; preempting process A4 with 564ms remaining [Q A0 A1 A5 A3]
time 43357ms: Process A0 started using the CPU for remaining 388ms of 516ms burst [Q A1 A5 A3 A4]
time 43485ms: Time slice expired; preempting process A0 with 260ms remaining [Q A1 A5 A3 A4]
time 43491ms: Process A1 started using the CPU for remaining 2360ms of 3896ms burst [Q A5 A3 A4 A0]
time 43619ms: Time slice expired; preempting process A1 with 2232ms remaining [Q A5 A3 A4 A0]
time 43625ms: Process A5 started using the CPU for remaining 420ms of 1060ms burst [Q A3 A4 A0 A1]
time 43753ms: Time slice expired; preempting process A5 with 292ms remaining [Q A3 A4 A0 A1]
time 43759ms: Process A3 started using the CPU for remaining 728ms of 2520ms burst [Q A4 A0 A1 A5]
time 43887ms: Time slice expired; preempting process A3 with 600ms remaining [Q A4 A0 A1 A5]
time 43893ms: Process A4 started using the CPU for remaining 564ms of 1460ms burst [Q A0 A1 A5 A3]
time 43970ms: Process A6 completed I/O; added to ready queue [Q A0 A1 A5 A3 A6]
time 44021ms: Time slice expired; preempting process A4 with 436ms remaining [Q A0 A1 A5 A3 A6]
time 44027ms: Process A0 started using the CPU for remaining 260ms of 516ms burst [Q A1 A5 A3 A6 A4]
time 44155ms: Time slice expired; preempting process A0 with 132ms remaining [Q A1 A5 A3 A6 A4]
time 44161ms: Process A1 started using the CPU for remaining 2232ms of 3896ms burst [Q A5 A3 A6 A4 A0]
time 44273ms: Process A7 completed I/O; added to ready queue [Q A5 A3 A6 A4 A0 A7]
time 44289ms: Time slice expired; preempting process A1 with 2104ms remaining [Q A5 A3 A6 A4 A0 A7]
time 44295ms: Process A5 started using the CPU for remaining 292ms of 1060ms burst [Q A3 A6 A4 A0 A7 A1]
time 44423ms: Time slice expired; preempting process A5 with 164ms remaining [Q A3 A6 A4 A0 A7 A1]
time 44429ms: Process A3 started using the CPU for remaining 600ms of 2520ms burst [Q A6 A4 A0 A7 A1 A5]
time 44557ms: Time slice expired; preempting process A3 with 472ms remaining [Q A6 A4 A0 A7 A1 A5]
time 44563ms: Process A6 started using the CPU for 959ms burst [Q A4 A0 A7 A1 A5 A3]
time 44691ms: Time slice expired; preempting process A6 with 831ms remaining [Q A4 A0 A7 A1 A5 A3]
time 44697ms: Process A4 started using the CPU for remaining 436ms of 1460ms burst [Q A0 A7 A1 A5 A3 A6]
time 44825ms: Time slice expired; preempting process A4 with 308ms remaining [Q A0 A7 A1 A5 A3 A6]
time 44831ms: Process A0 started using the CPU for remaining 132ms of 516ms burst [Q A7 A1 A5 A3 A6 A4]
time 44959ms: Time slice expired; preempting process A0 with 4ms remaining [Q A7 A1 A5 A3 A6 A4]
time 44965ms: Process A7 started using the CPU for 248ms burst [Q A1 A5 A3 A6 A4 A0]
time 45093ms: Time slice expired; preempting process A7 with 120ms remaining [Q A1 A5 A3 A6 A4 A0]
time 45099ms: Process A1 started using the CPU for remaining 2104ms of 3896ms burst [Q A5 A3 A6 A4 A0 A7]
time 45227ms: Time slice expired; preempting process A1 with 1976ms remaining [Q A5 A3 A6 A4 A0 A7]
time 45233ms: Process A5 started using the CPU for remaining 164ms of 1060ms burst [Q A3 A6 A4 A0 A7 A1]
time 45361ms: Time slice expired; preempting process A5 with 36ms remaining [Q A3 A6 A4 A0 A7 A1]
time 45367ms: Process A3 started using the CPU for remaining 472ms of 2520ms burst [Q A6 A4 A0 A7 A1 A5]
time 45495ms: Time slice expired; preempting process A3 with 344ms remaining [Q A6 A4 A0 A7 A1 A5]
time 45501ms: Process A6 started using the CPU for remaining 831ms of 959ms burst [Q A4 A0 A7 A1 A5 A3]
time 45629ms: Time slice expired; preempting process A6 with 703ms remaining [Q A4 A0 A7 A1 A5 A3]
time 45635ms: Process A4 started using the CPU for remaining 308ms of 1460ms burst [Q A0 A7 A1 A5 A3 A6]
time 45763ms: Time slice expired; preempting process A4 with 180ms remaining [Q A0 A7 A1 A5 A3 A6]
time 45769ms: Process A0 started using the CPU for remaining 4ms of 516ms burst [Q A7 A1 A5 A3 A6 A4]
time 45773ms: Process A0 completed a CPU burst; 1 burst to go [Q A7 A1 A5 A3 A6 A4]
time 45773ms: Process A0 switching out of CPU; blocking on I/O until time 46158ms [Q A7 A1 A5 A3 A6 A4]
time 45779ms: Process A7 started using the CPU for remaining 120ms of 248ms burst [Q A1 A5 A3 A6 A4]
time 45899ms: Process A7 completed a CPU burst; 13 bursts to go [Q A1 A5 A3 A6 A4]
time 45899ms: Process A7 switching out of CPU; blocking on I/O until time 52166ms [Q A1 A5 A3 A6 A4]
time 45905ms: Process A1 started using the CPU for remaining 1976ms of 3896ms burst [Q A5 A3 A6 A4]
time 46033ms: Time slice expired; preempting process A1 with 1848ms remaining [Q A5 A3 A6 A4]
time 46039ms: Process A5 started using the CPU for remaining 36ms of 1060ms burst [Q A3 A6 A4 A1]
time 46075ms: Process A5 completed a CPU burst; 7 bursts to go [Q A3 A6 A4 A1]
time 46075ms: Process A5 switching out of CPU; blocking on I/O until time 47085ms [Q A3 A6 A4 A1]
time 46081ms: Process A3 started using the CPU for remaining 344ms of 2520ms burst [Q A6 A4 A1]
time 46158ms: Process A0 completed I/O; added to ready queue [Q A6 A4 A1 A0]
time 46209ms: Time slice expired; preempting process A3 with 216ms remaining [Q A6 A4 A1 A0]
time 46215ms: Process A6 started using the CPU for remaining 703ms of 959ms burst [Q A4 A1 A0 A3]
time 46343ms: Time slice expired; preempting process A6 with 575ms remaining [Q A4 A1 A0 A3]
time 46349ms: Process A4 started using the CPU for remaining 180ms of 1460ms burst [Q A1 A0 A3 A6]
time 46477ms: Time slice expired; preempting process A4 with 52ms remaining [Q A1 A0 A3 A6]
time 46483ms: Process A1 started using the CPU for remaining 1848ms of 3896ms burst [Q A0 A3 A6 A4]
time 46611ms: Time slice expired; preempting process A1 with 1720ms remaining [Q A0 A3 A6 A4]
time 46617ms: Process A0 started using the CPU for 2560ms burst [Q A3 A6 A4 A1]
time 46745ms: Time slice expired; preempting process A0 with 2432ms remaining [Q A3 A6 A4 A1]
time 46751ms: Process A3 started using the CPU for remaining 216ms of 2520ms burst [Q A6 A4 A1 A0]
time 46879ms: Time slice expired; preempting process A3 with 88ms remaining [Q A6 A4 A1 A0]
time 46885ms: Process A6 started using the CPU for remaining 575ms of 959ms burst [Q A4 A1 A0 A3]
time 47013ms: Time slice expired; preempting process A6 with 447ms remaining [Q A4 A1 A0 A3]
time 47019ms: Process A4 started using the CPU for remaining 52ms of 1460ms burst [Q A1 A0 A3 A6]
time 47071ms: Process A4 completed a CPU burst; 14 bursts to go [Q A1 A0 A3 A6]
time 47071ms: Process A4 switching out of CPU; blocking on I/O until time 47632ms [Q A1 A0 A3 A6]
time 47077ms: Process A1 started using the CPU for remaining 1720ms of 3896ms burst [Q A0 A3 A6]
time 47085ms: Process A5 completed I/O; added to ready queue [Q A0 A3 A6 A5]
time 47205ms: Time slice expired; preempting process A1 with 1592ms remaining [Q A0 A3 A6 A5]
time 47211ms: Process A0 started using the CPU for remaining 2432ms of 2560ms burst [Q A3 A6 A5 A1]
time 47339ms: Time slice expired; preempting process A0 with 2304ms remaining [Q A3 A6 A5 A1]
time 47345ms: Process A3 started using the CPU for remaining 88ms of 2520ms burst [Q A6 A5 A1 A0]
time 47433ms: Process A3 completed a CPU burst; 2 bursts to go [Q A6 A5 A1 A0]
time 47433ms: Process A3 switching out of CPU; blocking on I/O until time 48180ms [Q A6 A5 A1 A0]
time 47439ms: Process A6 started using the CPU for remaining 447ms of 959ms burst [Q A5 A1 A0]
time 47567ms: Time slice expired; preempting process A6 with 319ms remaining [Q A5 A1 A0]
time 47573ms: Process A5 started using the CPU for 480ms burst [Q A1 A0 A6]
time 47632ms: Process A4 completed I/O; added to ready queue [Q A1 A0 A6 A4]
time 47701ms: Time slice expired; preempting process A5 with 352ms remaining [Q A1 A0 A6 A4]
time 47707ms: Process A1 started using the CPU for remaining 1592ms of 3896ms burst [Q A0 A6 A4 A5]
time 47835ms: Time slice expired; preempting process A1 with 1464ms remaining [Q A0 A6 A4 A5]
time 47841ms: Process A0 started using the CPU for remaining 2304ms of 2560ms burst [Q A6 A4 A5 A1]
time 47969ms: Time slice expired; preempting process A0 with 2176ms remaining [Q A6 A4 A5 A1]
time 47975ms: Process A6 started using the CPU for remaining 319ms of 959ms burst [Q A4 A5 A1 A0]
time 48103ms: Time slice expired; preempting process A6 with 191ms remaining [Q A4 A5 A1 A0]
time 48109ms: Process A4 started using the CPU for 68ms burst [Q A5 A1 A0 A6]
time 48177ms: Process A4 completed a CPU burst; 13 bursts to go [Q A5 A1 A0 A6]
time 48177ms: Process A4 switching out of CPU; blocking on I/O until time 48707ms [Q A5 A1 A0 A6]
time 48180ms: Process A3 completed I/O; added to ready queue [Q A5 A1 A0 A6 A3]
time 48183ms: Process A5 started using the CPU for remaining 352ms of 480ms burst [Q A1 A0 A6 A3]
time 48311ms: Time slice expired; preempting process A5 with 224ms remaining [Q A1 A0 A6 A3]
time 48317ms: Process A1 started using the CPU for remaining 1464ms of 3896ms burst [Q A0 A6 A3 A5]
time 48445ms: Time slice expired; preempting process A1 with 1336ms remaining [Q A0 A6 A3 A5]
time 48451ms: Process A0 started using the CPU for remaining 2176ms of 2560ms burst [Q A6 A3 A5 A1]
time 48579ms: Time slice expired; preempting process A0 with 2048ms remaining [Q A6 A3 A5 A1]
time 48585ms: Process A6 started using the CPU for remaining 191ms of 959ms burst [Q A3 A5 A1 A0]
time 48707ms: Process A4 completed I/O; added to ready queue [Q A3 A5 A1 A0 A4]
time 48713ms: Time slice expired; preempting process A6 with 63ms remaining [Q A3 A5 A1 A0 A4]
time 48719ms: Process A3 started using the CPU for 364ms burst [Q A5 A1 A0 A4 A6]
time 48847ms: Time slice expired; preempting process A3 with 236ms remaining [Q A5 A1 A0 A4 A6]
time 48853ms: Process A5 started using the CPU for remaining 224ms of 480ms burst [Q A1 A0 A4 A6 A3]
time 48981ms: Time slice expired; preempting process A5 with 96ms remaining [Q A1 A0 A4 A6 A3]
time 48987ms: Process A1 started using the CPU for remaining 1336ms of 3896ms burst [Q A0 A4 A6 A3 A5]
time 49115ms: Time slice expired; preempting process A1 with 1208ms remaining [Q A0 A4 A6 A3 A5]
time 49121ms: Process A0 started using the CPU for remaining 2048ms of 2560ms burst [Q A4 A6 A3 A5 A1]
time 49249ms: Time slice expired; preempting process A0 with 1920ms remaining [Q A4 A6 A3 A5 A1]
time 49255ms: Process A4 started using the CPU for 1292ms burst [Q A6 A3 A5 A1 A0]
time 49383ms: Time slice expired; preempting process A4 with 1164ms remaining [Q A6 A3 A5 A1 A0]
time 49389ms: Process A6 started using the CPU for remaining 63ms of 959ms burst [Q A3 A5 A1 A0 A4]
time 49452ms: Process A6 terminated [Q A3 A5 A1 A0 A4]
time 49458ms: Process A3 started using the CPU for remaining 236ms of 364ms burst [Q A5 A1 A0 A4]
time 49586ms: Time slice expired; preempting process A3 with 108ms remaining [Q A5 A1 A0 A4]
time 49592ms: Process A5 started using the CPU for remaining 96ms of 480ms burst [Q A1 A0 A4 A3]
time 49688ms: Process A5 completed a CPU burst; 6 bursts to go [Q A1 A0 A4 A3]
time 49688ms: Process A5 switching out of CPU; blocking on I/O until time 49958ms [Q A1 A0 A4 A3]
time 49694ms: Process A1 started using the CPU for remaining 1208ms of 3896ms burst [Q A0 A4 A3]
time 49822ms: Time slice expired; preempting process A1 with 1080ms remaining [Q A0 A4 A3]
time 49828ms: Process A0 started using the CPU for remaining 1920ms of 2560ms burst [Q A4 A3 A1]
time 49956ms: Time slice expired; preempting process A0 with 1792ms remaining [Q A4 A3 A1]
time 49958ms: Process A5 completed I/O; added to ready queue [Q A4 A3 A1 A5]
time 49962ms: Process A4 started using the CPU for remaining 1164ms of 1292ms burst [Q A3 A1 A5 A0]
time 50090ms: Time slice expired; preempting process A4 with 1036ms remaining [Q A3 A1 A5 A0]
time 50096ms: Process A3 started using the CPU for remaining 108ms of 364ms burst [Q A1 A5 A0 A4]
time 50204ms: Process A3 completed a CPU burst; 1 burst to go [Q A1 A5 A0 A4]
time 50204ms: Process A3 switching out of CPU; blocking on I/O until time 50603ms [Q A1 A5 A0 A4]
time 50210ms: Process A1 started using the CPU for remaining 1080ms of 3896ms burst [Q A5 A0 A4]
time 50338ms: Time slice expired; preempting process A1 with 952ms remaining [Q A5 A0 A4]
time 50344ms: Process A5 started using the CPU for 3124ms burst [Q A0 A4 A1]
time 50472ms: Time slice expired; preempting process A5 with 2996ms remaining [Q A0 A4 A1]
time 50478ms: Process A0 started using the CPU for remaining 1792ms of 2560ms burst [Q A4 A1 A5]
time 50603ms: Process A3 completed I/O; added to ready queue [Q A4 A1 A5 A3]
time 50606ms: Time slice expired; preempting process A0 with 1664ms remaining [Q A4 A1 A5 A3]
time 50612ms: Process A4 started using the CPU for remaining 1036ms of 1292ms burst [Q A1 A5 A3 A0]
time 50740ms: Time slice expired; preempting process A4 with 908ms remaining [Q A1 A5 A3 A0]
time 50746ms: Process A1 started using the CPU for remaining 952ms of 3896ms burst [Q A5 A3 A0 A4]
time 50874ms: Time slice expired; preempting process A1 with 824ms remaining [Q A5 A3 A0 A4]
time 50880ms: Process A5 started using the CPU for remaining 2996ms of 3124ms burst [Q A3 A0 A4 A1]
time 51008ms: Time slice expired; preempting process A5 with 2868ms remaining [Q A3 A0 A4 A1]
time 51014ms: Process A3 started using the CPU for 3988ms burst [Q A0 A4 A1 A5]
time 51142ms: Time slice expired; preempting process A3 with 3860ms remaining [Q A0 A4 A1 A5]
time 51148ms: Process A0 started using the CPU for remaining 1664ms of 2560ms burst [Q A4 A1 A5 A3]
time 51276ms: Time slice expired; preempting process A0 with 1536ms remaining [Q A4 A1 A5 A3]
time 51282ms: Process A4 started using the CPU for remaining 908ms of 1292ms burst [Q A1 A5 A3 A0]
time 51410ms: Time slice expired; preempting process A4 with 780ms remaining [Q A1 A5 A3 A0]
time 51416ms: Process A1 started using the CPU for remaining 824ms of 3896ms burst [Q A5 A3 A0 A4]
time 51544ms: Time slice expired; preempting process A1 with 696ms remaining [Q A5 A3 A0 A4]
time 51550ms: Process A5 started using the CPU for remaining 2868ms of 3124ms burst [Q A3 A0 A4 A1]
time 51678ms: Time slice expired; preempting process A5 with 2740ms remaining [Q A3 A0 A4 A1]
time 51684ms: Process A3 started using the CPU for remaining 3860ms of 3988ms burst [Q A0 A4 A1 A5]
time 51812ms: Time slice expired; preempting process A3 with 3732ms remaining [Q A0 A4 A1 A5]
time 51818ms: Process A0 started using the CPU for remaining 1536ms of 2560ms burst [Q A4 A1 A5 A3]
time 51946ms: Time slice expired; preempting process A0 with 1408ms remaining [Q A4 A1 A5 A3]
time 51952ms: Process A4 started using the CPU for remaining 780ms of 1292ms burst [Q A1 A5 A3 A0]
time 52080ms: Time slice expired; preempting process A4 with 652ms remaining [Q A1 A5 A3 A0]
time 52086ms: Process A1 started using the CPU for remaining 696ms of 3896ms burst [Q A5 A3 A0 A4]
time 52166ms: Process A7 completed I/O; added to ready queue [Q A5 A3 A0 A4 A7]
time 52214ms: Time slice expired; preempting process A1 with 568ms remaining [Q A5 A3 A0 A4 A7]
time 52220ms: Process A5 started using the CPU for remaining 2740ms of 3124ms burst [Q A3 A0 A4 A7 A1]
time 52348ms: Time slice expired; preempting process A5 with 2612ms remaining [Q A3 A0 A4 A7 A1]
time 52354ms: Process A3 started using the CPU for remaining 3732ms of 3988ms burst [Q A0 A4 A7 A1 A5]
time 52482ms: Time slice expired; preempting process A3 with 3604ms remaining [Q A0 A4 A7 A1 A5]
time 52488ms: Process A0 started using the CPU for remaining 1408ms of 2560ms burst [Q A4 A7 A1 A5 A3]
time 52616ms: Time slice expired; preempting process A0 with 1280ms remaining [Q A4 A7 A1 A5 A3]
time 52622ms: Process A4 started using the CPU for remaining 652ms of 1292ms burst [Q A7 A1 A5 A3 A0]
time 52750ms: Time slice expired; preempting process A4 with 524ms remaining [Q A7 A1 A5 A3 A0]
time 52756ms: Process A7 started using the CPU for 904ms burst [Q A1 A5 A3 A0 A4]
time 52884ms: Time slice expired; preempting process A7 with 776ms remaining [Q A1 A5 A3 A0 A4]
time 52890ms: Process A1 started using the CPU for remaining 568ms of 3896ms burst [Q A5 A3 A0 A4 A7]
time 53018ms: Time slice expired; preempting process A1 with 440ms remaining [Q A5 A3 A0 A4 A7]
time 53024ms: Process A5 started using the CPU for remaining 2612ms of 3124ms burst [Q A3 A0 A4 A7 A1]
time 53152ms: Time slice expired; preempting process A5 with 2484ms remaining [Q A3 A0 A4 A7 A1]
time 53158ms: Process A3 started using the CPU for remaining 3604ms of 3988ms burst [Q A0 A4 A7 A1 A5]
time 53286ms: Time slice expired; preempting process A3 with 3476ms remaining [Q A0 A4 A7 A1 A5]
time 53292ms: Process A0 started using the CPU for remaining 1280ms of 2560ms burst [Q A4 A7 A1 A5 A3]
time 53420ms: Time slice expired; preempting process A0 with 1152ms remaining [Q A4 A7 A1 A5 A3]
time 53426ms: Process A4 started using the CPU for remaining 524ms of 1292ms burst [Q A7 A1 A5 A3 A0]
time 53554ms: Time slice expired; preempting process A4 with 396ms remaining [Q A7 A1 A5 A3 A0]
time 53560ms: Process A7 started using the CPU for remaining 776ms of 904ms burst [Q A1 A5 A3 A0 A4]
time 53688ms: Time slice expired; preempting process A7 with 648ms remaining [Q A1 A5 A3 A0 A4]
time 53694ms: Process A1 started using the CPU for remaining 440ms of 3896ms burst [Q A5 A3 A0 A4 A7]
time 53822ms: Time slice expired; preempting process A1 with 312ms remaining [Q A5 A3 A0 A4 A7]
time 53828ms: Process A5 started using the CPU for remaining 2484ms of 3124ms burst [Q A3 A0 A4 A7 A1]
time 53956ms: Time slice expired; preempting process A5 with 2356ms remaining [Q A3 A0 A4 A7 A1]
time 53962ms: Process A3 started using the CPU for remaining 3476ms of 3988ms burst [Q A0 A4 A7 A1 A5]
time 54090ms: Time slice expired; preempting process A3 with 3348ms remaining [Q A0 A4 A7 A1 A5]
time 54096ms: Process A0 started using the CPU for remaining 1152ms of 2560ms burst [Q A4 A7 A1 A5 A3]
time 54224ms: Time slice expired; preempting process A0 with 1024ms remaining [Q A4 A7 A1 A5 A3]
time 54230ms: Process A4 started using the CPU for remaining 396ms of 1292ms burst [Q A7 A1 A5 A3 A0]
time 54358ms: Time slice expired; preempting process A4 with 268ms remaining [Q A7 A1 A5 A3 A0]
time 54364ms: Process A7 started using the CPU for remaining 648ms of 904ms burst [Q A1 A5 A3 A0 A4]
time 54492ms: Time slice expired; preempting process A7 with 520ms remaining [Q A1 A5 A3 A0 A4]
time 54498ms: Process A1 started using the CPU for remaining 312ms of 3896ms burst [Q A5 A3 A0 A4 A7]
time 54626ms: Time slice expired; preempting process A1 with 184ms remaining [Q A5 A3 A0 A4 A7]
time 54632ms: Process A5 started using the CPU for remaining 2356ms of 3124ms burst [Q A3 A0 A4 A7 A1]
time 54760ms: Time slice expired; preempting process A5 with 2228ms remaining [Q A3 A0 A4 A7 A1]
time 54766ms: Process A3 started using the CPU for remaining 3348ms of 3988ms burst [Q A0 A4 A7 A1 A5]
time 54894ms: Time slice expired; preempting process A3 with 3220ms remaining [Q A0 A4 A7 A1 A5]
time 54900ms: Process A0 started using the CPU for remaining 1024ms of 2560ms burst [Q A4 A7 A1 A5 A3]
time 55028ms: Time slice expired; preempting process A0 with 896ms remaining [Q A4 A7 A1 A5 A3]
time 55034ms: Process A4 started using the CPU for remaining 268ms of 1292ms burst [Q A7 A1 A5 A3 A0]
time 55162ms: Time slice expired; preempting process A4 with 140ms remaining [Q A7 A1 A5 A3 A0]
time 55168ms: Process A7 started using the CPU for remaining 520ms of 904ms burst [Q A1 A5 A3 A0 A4]
time 55296ms: Time slice expired; preempting process A7 with 392ms remaining [Q A1 A5 A3 A0 A4]
time 55302ms: Process A1 started using the CPU for remaining 184ms of 3896ms burst [Q A5 A3 A0 A4 A7]
time 55430ms: Time slice expired; preempting process A1 with 56ms remaining [Q A5 A3 A0 A4 A7]
time 55436ms: Process A5 started using the CPU for remaining 2228ms of 3124ms burst [Q A3 A0 A4 A7 A1]
time 55564ms: Time slice expired; preempting process A5 with 2100ms remaining [Q A3 A0 A4 A7 A1]
time 55570ms: Process A3 started using the CPU for remaining 3220ms of 3988ms burst [Q A0 A4 A7 A1 A5]
time 55698ms: Time slice expired; preempting process A3 with 3092ms remaining [Q A0 A4 A7 A1 A5]
time 55704ms: Process A0 started using the CPU for remaining 896ms of 2560ms burst [Q A4 A7 A1 A5 A3]
time 55832ms: Time slice expired; preempting process A0 with 768ms remaining [Q A4 A7 A1 A5 A3]
time 55838ms: Process A4 started using the CPU for remaining 140ms of 1292ms burst [Q A7 A1 A5 A3 A0]
time 55966ms: Time slice expired; preempting process A4 with 12ms remaining [Q A7 A1 A5 A3 A0]
time 55972ms: Process A7 started using the CPU for remaining 392ms of 904ms burst [Q A1 A5 A3 A0 A4]
time 56100ms: Time slice expired; preempting process A7 with 264ms remaining [Q A1 A5 A3 A0 A4]
time 56106ms: Process A1 started using the CPU for remaining 56ms of 3896ms burst [Q A5 A3 A0 A4 A7]
time 56162ms: Process A1 completed a CPU burst; 5 bursts to go [Q A5 A3 A0 A4 A7]
time 56162ms: Process A1 switching out of CPU; blocking on I/O until time 57060ms [Q A5 A3 A0 A4 A7]
time 56168ms: Process A5 started using the CPU for remaining 2100ms of 3124ms burst [Q A3 A0 A4 A7]
time 56296ms: Time slice expired; preempting process A5 with 1972ms remaining [Q A3 A0 A4 A7]
time 56302ms: Process A3 started using the CPU for remaining 3092ms of 3988ms burst [Q A0 A4 A7 A5]
time 56430ms: Time slice expired; preempting process A3 with 2964ms remaining [Q A0 A4 A7 A5]
time 56436ms: Process A0 started using the CPU for remaining 768ms of 2560ms burst [Q A4 A7 A5 A3]
time 56564ms: Time slice expired; preempting process A0 with 640ms remaining [Q A4 A7 A5 A3]
time 56570ms: Process A4 started using the CPU for remaining 12ms of 1292ms burst [Q A7 A5 A3 A0]
time 56582ms: Process A4 completed a CPU burst; 12 bursts to go [Q A7 A5 A3 A0]
time 56582ms: Process A4 switching out of CPU; blocking on I/O until time 57053ms [Q A7 A5 A3 A0]
time 56588ms: Process A7 started using the CPU for remaining 264ms of 904ms burst [Q A5 A3 A0]
time 56716ms: Time slice expired; preempting process A7 with 136ms remaining [Q A5 A3 A0]
time 56722ms: Process A5 started using the CPU for remaining 1972ms of 3124ms burst [Q A3 A0 A7]
time 56850ms: Time slice expired; preempting process A5 with 1844ms remaining [Q A3 A0 A7]
time 56856ms: Process A3 started using the CPU for remaining 2964ms of 3988ms burst [Q A0 A7 A5]
time 56984ms: Time slice expired; preempting process A3 with 2836ms remaining [Q A0 A7 A5]
time 56990ms: Process A0 started using the CPU for remaining 640ms of 2560ms burst [Q A7 A5 A3]
time 57053ms: Process A4 completed I/O; added to ready queue [Q A7 A5 A3 A4]
time 57060ms: Process A1 completed I/O; added to ready queue [Q A7 A5 A3 A4 A1]
time 57118ms: Time slice expired; preempting process A0 with 512ms remaining [Q A7 A5 A3 A4 A1]
time 57124ms: Process A7 started using the CPU for remaining 136ms of 904ms burst [Q A5 A3 A4 A1 A0]
time 57252ms: Time slice expired; preempting process A7 with 8ms remaining [Q A5 A3 A4 A1 A0]
time 57258ms: Process A5 started using the CPU for remaining 1844ms of 3124ms burst [Q A3 A4 A1 A0 A7]
time 57386ms: Time slice expired; preempting process A5 with 1716ms remaining [Q A3 A4 A1 A0 A7]
time 57392ms: Process A3 started using the CPU for remaining 2836ms of 3988ms burst [Q A4 A1 A0 A7 A5]
time 57520ms: Time slice expired; preempting process A3 with 2708ms remaining [Q A4 A1 A0 A7 A5]
time 57526ms: Process A4 started using the CPU for 628ms burst [Q A1 A0 A7 A5 A3]
time 57654ms: Time slice expired; preempting process A4 with 500ms remaining [Q A1 A0 A7 A5 A3]
time 57660ms: Process A1 started using the CPU for 1884ms burst [Q A0 A7 A5 A3 A4]
time 57788ms: Time slice expired; preempting process A1 with 1756ms remaining [Q A0 A7 A5 A3 A4]
time 57794ms: Process A0 started using the CPU for remaining 512ms of 2560ms burst [Q A7 A5 A3 A4 A1]
time 57922ms: Time slice expired; preempting process A0 with 384ms remaining [Q A7 A5 A3 A4 A1]
time 57928ms: Process A7 started using the CPU for remaining 8ms of 904ms burst [Q A5 A3 A4 A1 A0]
time 57936ms: Process A7 completed a CPU burst; 12 bursts to go [Q A5 A3 A4 A1 A0]
time 57936ms: Process A7 switching out of CPU; blocking on I/O until time 61683ms [Q A5 A3 A4 A1 A0]
time 57942ms: Process A5 started using the CPU for remaining 1716ms of 3124ms burst [Q A3 A4 A1 A0]
time 58070ms: Time slice expired; preempting process A5 with 1588ms remaining [Q A3 A4 A1 A0]
time 58076ms: Process A3 started using the CPU for remaining 2708ms of 3988ms burst [Q A4 A1 A0 A5]
time 58204ms: Time slice expired; preempting process A3 with 2580ms remaining [Q A4 A1 A0 A5]
time 58210ms: Process A4 started using the CPU for remaining 500ms of 628ms burst [Q A1 A0 A5 A3]
time 58338ms: Time slice expired; preempting process A4 with 372ms remaining [Q A1 A0 A5 A3]
time 58344ms: Process A1 started using the CPU for remaining 1756ms of 1884ms burst [Q A0 A5 A3 A4]
time 58472ms: Time slice expired; preempting process A1 with 1628ms remaining [Q A0 A5 A3 A4]
time 58478ms: Process A0 started using the CPU for remaining 384ms of 2560ms burst [Q A5 A3 A4 A1]
time 58606ms: Time slice expired; preempting process A0 with 256ms remaining [Q A5 A3 A4 A1]
time 58612ms: Process A5 started using the CPU for remaining 1588ms of 3124ms burst [Q A3 A4 A1 A0]
time 58740ms: Time slice expired; preempting process A5 with 1460ms remaining [Q A3 A4 A1 A0]
time 58746ms: Process A3 started using the CPU for remaining 2580ms of 3988ms burst [Q A4 A1 A0 A5]
time 58874ms: Time slice expired; preempting process A3 with 2452ms remaining [Q A4 A1 A0 A5]
time 58880ms: Process A4 started using the CPU for remaining 372ms of 628ms burst [Q A1 A0 A5 A3]
time 59008ms: Time slice expired; preempting process A4 with 244ms remaining [Q A1 A0 A5 A3]
time 59014ms: Process A1 started using the CPU for remaining 1628ms of 1884ms burst [Q A0 A5 A3 A4]
time 59142ms: Time slice expired; preempting process A1 with 1500ms remaining [Q A0 A5 A3 A4]
time 59148ms: Process A0 started using the CPU for remaining 256ms of 2560ms burst [Q A5 A3 A4 A1]
time 59276ms: Time slice expired; preempting process A0 with 128ms remaining [Q A5 A3 A4 A1]
time 59282ms: Process A5 started using the CPU for remaining 1460ms of 3124ms burst [Q A3 A4 A1 A0]
time 59410ms: Time slice expired; preempting process A5 with 1332ms remaining [Q A3 A4 A1 A0]
time 59416ms: Process A3 started using the CPU for remaining 2452ms of 3988ms burst [Q A4 A1 A0 A5]
time 59544ms: Time slice expired; preempting process A3 with 2324ms remaining [Q A4 A1 A0 A5]
time 59550ms: Process A4 started using the CPU for remaining 244ms of 628ms burst [Q A1 A0 A5 A3]
time 59678ms: Time slice expired; preempting process A4 with 116ms remaining [Q A1 A0 A5 A3]
time 59684ms: Process A1 started using the CPU for remaining 1500ms of 1884ms burst [Q A0 A5 A3 A4]
time 59812ms: Time slice expired; preempting process A1 with 1372ms remaining [Q A0 A5 A3 A4]
time 59818ms: Process A0 started using the CPU for remaining 128ms of 2560ms burst [Q A5 A3 A4 A1]
time 59946ms: Process A0 terminated [Q A5 A3 A4 A1]
time 59952ms: Process A5 started using the CPU for remaining 1332ms of 3124ms burst [Q A3 A4 A1]
time 60080ms: Time slice expired; preempting process A5 with 1204ms remaining [Q A3 A4 A1]
time 60086ms: Process A3 started using the CPU for remaining 2324ms of 3988ms burst [Q A4 A1 A5]
